2025-05-22 19:08:53,440 - error_handler - INFO - Error handler initialized
2025-05-22 19:08:53,440 - session_manager - INFO - No existing configuration found, using defaults
2025-05-22 19:08:53,440 - session_manager - INFO - Session manager initialized with config: session.json
2025-05-22 19:08:53,440 - session_manager - INFO - Backup directory: session_backups
2025-05-22 19:08:53,466 - __main__ - INFO - Application state restored
2025-05-22 19:08:53,466 - __main__ - INFO - Backend systems initialized
2025-05-22 19:08:53,466 - __main__ - INFO - Analytics Runner application initialized successfully
2025-05-22 19:09:24,449 - __main__ - INFO - Loading data source: audit_workpapers_2025Q2.xlsx
2025-05-22 19:09:26,370 - __main__ - INFO - Starting validation process
2025-05-22 19:09:28,363 - __main__ - INFO - Validation process completed
2025-05-22 19:09:32,701 - __main__ - INFO - Application closing
2025-05-22 19:09:32,729 - error_handler - CRITICAL - TypeError: Object of type QByteArray is not JSON serializable
2025-05-22 19:09:34,469 - __main__ - ERROR - ERROR: Object of type QByteArray is not JSON serializable
2025-05-22 20:31:20,087 - error_handler - INFO - Error handler initialized
2025-05-22 20:31:20,088 - session_manager - WARNING - Error loading configuration: Expecting value: line 2 column 22 (char 23)
2025-05-22 20:31:20,088 - session_manager - INFO - Attempting to restore from backup...
2025-05-22 20:31:20,089 - session_manager - INFO - Configuration restored from backup: session_backups\session_backup1.json
2025-05-22 20:31:20,089 - session_manager - INFO - Session manager initialized with config: session.json
2025-05-22 20:31:20,089 - session_manager - INFO - Backup directory: session_backups
2025-05-22 20:31:20,177 - __main__ - INFO - Application state restored
2025-05-22 20:31:20,177 - __main__ - INFO - Backend systems initialized
2025-05-22 20:31:20,177 - __main__ - INFO - Analytics Runner application initialized successfully
2025-05-22 20:31:49,476 - data_source_panel - INFO - File selected: audit_workpapers_2025Q2.xlsx
2025-05-22 20:31:49,823 - progress_widget - INFO - Progress operation started
2025-05-22 20:31:49,824 - __main__ - INFO - Data source changed: audit_workpapers_2025Q2.xlsx
2025-05-22 20:31:49,825 - file_selector_widget - INFO - File selected: audit_workpapers_2025Q2.xlsx
2025-05-22 20:31:49,826 - __main__ - INFO - Data source validation: File validation passed
2025-05-22 20:31:52,535 - data_integration.connectors.excel_connector - ERROR - Error loading Excel file C:/Users/luria/PycharmProjects/AuditQAStudio2/test_data/audit_workpapers_2025Q2.xlsx: Error executing read_excel: Worksheet named 'Loading sheets...' not found - Details: {"function": "read_excel", "args": "('C:/Users/luria/PycharmProjects/AuditQAStudio2/test_data/audit_workpapers_2025Q2.xlsx',)", "kwargs": {"sheet_name": "Loading sheets...", "header": 0, "nrows": 10, "na_values": ["#N/A", "#N/A N/A", "#NA", "-NA", "#NULL!", "#NUM!", "#DIV/0!", "#VALUE!", "#REF!", "#NAME?", "#DIV/0", "#NUM", "#REF", "#VALUE"], "engine": "openpyxl", "parse_dates": true}}
2025-05-22 20:31:52,535 - data_integration.errors.error_handler - ERROR - Failed to load data from ExcelConnector: Error executing read_excel: Worksheet named 'Loading sheets...' not found - Details: {"function": "read_excel", "args": "('C:/Users/luria/PycharmProjects/AuditQAStudio2/test_data/audit_workpapers_2025Q2.xlsx',)", "kwargs": {"sheet_name": "Loading sheets...", "header": 0, "nrows": 10, "na_values": ["#N/A", "#N/A N/A", "#NA", "-NA", "#NULL!", "#NUM!", "#DIV/0!", "#VALUE!", "#REF!", "#NAME?", "#DIV/0", "#NUM", "#REF", "#VALUE"], "engine": "openpyxl", "parse_dates": true}} - Details: {"source_name": "ExcelConnector", "params": {"sheet_name": "Loading sheets...", "header": 0, "nrows": 10, "na_values": ["#N/A", "#N/A N/A", "#NA", "-NA", "#NULL!", "#NUM!", "#DIV/0!", "#VALUE!", "#REF!", "#NAME?", "#DIV/0", "#NUM", "#REF", "#VALUE"], "engine": "openpyxl", "parse_dates": true}}
Traceback (most recent call last):
  File "C:\Users\luria\PycharmProjects\QAStudiov3\data_integration\errors\error_handler.py", line 328, in safe_dataframe_operation
    return func(*args, **kwargs)
           ^^^^^^^^^^^^^^^^^^^^^
  File "C:\Users\luria\PycharmProjects\QAStudiov3\.venv\Lib\site-packages\pandas\io\excel\_base.py", line 508, in read_excel
    data = io.parse(
           ^^^^^^^^^
  File "C:\Users\luria\PycharmProjects\QAStudiov3\.venv\Lib\site-packages\pandas\io\excel\_base.py", line 1616, in parse
    return self._reader.parse(
           ^^^^^^^^^^^^^^^^^^^
  File "C:\Users\luria\PycharmProjects\QAStudiov3\.venv\Lib\site-packages\pandas\io\excel\_base.py", line 773, in parse
    sheet = self.get_sheet_by_name(asheetname)
            ^^^^^^^^^^^^^^^^^^^^^^^^^^^^^^^^^^
  File "C:\Users\luria\PycharmProjects\QAStudiov3\.venv\Lib\site-packages\pandas\io\excel\_openpyxl.py", line 582, in get_sheet_by_name
    self.raise_if_bad_sheet_by_name(name)
  File "C:\Users\luria\PycharmProjects\QAStudiov3\.venv\Lib\site-packages\pandas\io\excel\_base.py", line 624, in raise_if_bad_sheet_by_name
    raise ValueError(f"Worksheet named '{name}' not found")
ValueError: Worksheet named 'Loading sheets...' not found

During handling of the above exception, another exception occurred:

Traceback (most recent call last):
  File "C:\Users\luria\PycharmProjects\QAStudiov3\data_integration\connectors\excel_connector.py", line 195, in get_data
    df = retry_operation(
         ^^^^^^^^^^^^^^^^
  File "C:\Users\luria\PycharmProjects\QAStudiov3\data_integration\errors\error_handler.py", line 379, in retry_operation
    return func(*args, **kwargs)
           ^^^^^^^^^^^^^^^^^^^^^
  File "C:\Users\luria\PycharmProjects\QAStudiov3\data_integration\connectors\excel_connector.py", line 183, in load_excel
    return safe_dataframe_operation(
           ^^^^^^^^^^^^^^^^^^^^^^^^^
  File "C:\Users\luria\PycharmProjects\QAStudiov3\data_integration\errors\error_handler.py", line 344, in safe_dataframe_operation
    raise DataIntegrationError(error_msg, details)
data_integration.errors.error_handler.DataIntegrationError: Error executing read_excel: Worksheet named 'Loading sheets...' not found - Details: {"function": "read_excel", "args": "('C:/Users/luria/PycharmProjects/AuditQAStudio2/test_data/audit_workpapers_2025Q2.xlsx',)", "kwargs": {"sheet_name": "Loading sheets...", "header": 0, "nrows": 10, "na_values": ["#N/A", "#N/A N/A", "#NA", "-NA", "#NULL!", "#NUM!", "#DIV/0!", "#VALUE!", "#REF!", "#NAME?", "#DIV/0", "#NUM", "#REF", "#VALUE"], "engine": "openpyxl", "parse_dates": true}}
2025-05-22 20:31:52,564 - data_integration.io.importer - ERROR - Error previewing file C:/Users/luria/PycharmProjects/AuditQAStudio2/test_data/audit_workpapers_2025Q2.xlsx: Failed to load data from ExcelConnector: Error executing read_excel: Worksheet named 'Loading sheets...' not found - Details: {"function": "read_excel", "args": "('C:/Users/luria/PycharmProjects/AuditQAStudio2/test_data/audit_workpapers_2025Q2.xlsx',)", "kwargs": {"sheet_name": "Loading sheets...", "header": 0, "nrows": 10, "na_values": ["#N/A", "#N/A N/A", "#NA", "-NA", "#NULL!", "#NUM!", "#DIV/0!", "#VALUE!", "#REF!", "#NAME?", "#DIV/0", "#NUM", "#REF", "#VALUE"], "engine": "openpyxl", "parse_dates": true}} - Details: {"source_name": "ExcelConnector", "params": {"sheet_name": "Loading sheets...", "header": 0, "nrows": 10, "na_values": ["#N/A", "#N/A N/A", "#NA", "-NA", "#NULL!", "#NUM!", "#DIV/0!", "#VALUE!", "#REF!", "#NAME?", "#DIV/0", "#NUM", "#REF", "#VALUE"], "engine": "openpyxl", "parse_dates": true}}
2025-05-22 20:31:52,564 - data_source_panel - ERROR - Error loading file preview: Failed to load data from ExcelConnector: Error executing read_excel: Worksheet named 'Loading sheets...' not found - Details: {"function": "read_excel", "args": "('C:/Users/luria/PycharmProjects/AuditQAStudio2/test_data/audit_workpapers_2025Q2.xlsx',)", "kwargs": {"sheet_name": "Loading sheets...", "header": 0, "nrows": 10, "na_values": ["#N/A", "#N/A N/A", "#NA", "-NA", "#NULL!", "#NUM!", "#DIV/0!", "#VALUE!", "#REF!", "#NAME?", "#DIV/0", "#NUM", "#REF", "#VALUE"], "engine": "openpyxl", "parse_dates": true}} - Details: {"source_name": "ExcelConnector", "params": {"sheet_name": "Loading sheets...", "header": 0, "nrows": 10, "na_values": ["#N/A", "#N/A N/A", "#NA", "-NA", "#NULL!", "#NUM!", "#DIV/0!", "#VALUE!", "#REF!", "#NAME?", "#DIV/0", "#NUM", "#REF", "#VALUE"], "engine": "openpyxl", "parse_dates": true}}
2025-05-22 20:31:52,570 - progress_widget - INFO - Progress operation started
2025-05-22 20:31:52,573 - progress_widget - INFO - Progress operation started
2025-05-22 20:31:52,573 - progress_widget - INFO - Progress operation completed: Error: Error loading file preview: Failed to load data from ExcelConnector: Error executing read_excel: Worksheet named 'Loading sheets...' not found - Details: {"function": "read_excel", "args": "('C:/Users/luria/PycharmProjects/AuditQAStudio2/test_data/audit_workpapers_2025Q2.xlsx',)", "kwargs": {"sheet_name": "Loading sheets...", "header": 0, "nrows": 10, "na_values": ["#N/A", "#N/A N/A", "#NA", "-NA", "#NULL!", "#NUM!", "#DIV/0!", "#VALUE!", "#REF!", "#NAME?", "#DIV/0", "#NUM", "#REF", "#VALUE"], "engine": "openpyxl", "parse_dates": true}} - Details: {"source_name": "ExcelConnector", "params": {"sheet_name": "Loading sheets...", "header": 0, "nrows": 10, "na_values": ["#N/A", "#N/A N/A", "#NA", "-NA", "#NULL!", "#NUM!", "#DIV/0!", "#VALUE!", "#REF!", "#NAME?", "#DIV/0", "#NUM", "#REF", "#VALUE"], "engine": "openpyxl", "parse_dates": true}}
2025-05-22 20:31:52,576 - data_source_panel - ERROR - Preview error: Error loading file preview: Failed to load data from ExcelConnector: Error executing read_excel: Worksheet named 'Loading sheets...' not found - Details: {"function": "read_excel", "args": "('C:/Users/luria/PycharmProjects/AuditQAStudio2/test_data/audit_workpapers_2025Q2.xlsx',)", "kwargs": {"sheet_name": "Loading sheets...", "header": 0, "nrows": 10, "na_values": ["#N/A", "#N/A N/A", "#NA", "-NA", "#NULL!", "#NUM!", "#DIV/0!", "#VALUE!", "#REF!", "#NAME?", "#DIV/0", "#NUM", "#REF", "#VALUE"], "engine": "openpyxl", "parse_dates": true}} - Details: {"source_name": "ExcelConnector", "params": {"sheet_name": "Loading sheets...", "header": 0, "nrows": 10, "na_values": ["#N/A", "#N/A N/A", "#NA", "-NA", "#NULL!", "#NUM!", "#DIV/0!", "#VALUE!", "#REF!", "#NAME?", "#DIV/0", "#NUM", "#REF", "#VALUE"], "engine": "openpyxl", "parse_dates": true}}
2025-05-22 20:31:52,665 - __main__ - INFO - Data preview loaded: 10 rows, 11 columns
2025-05-22 20:31:52,665 - data_source_panel - INFO - Preview loaded: 10 rows, 11 columns
2025-05-22 20:32:04,643 - progress_widget - INFO - Progress operation started
2025-05-22 20:32:04,666 - progress_widget - INFO - Progress operation completed: Preview loaded successfully
2025-05-22 20:32:04,666 - __main__ - INFO - Data preview loaded: 10 rows, 11 columns
2025-05-22 20:32:04,666 - data_source_panel - INFO - Preview loaded: 10 rows, 11 columns
2025-05-22 20:34:32,521 - progress_widget - INFO - Progress operation started
2025-05-22 20:34:32,592 - data_integration.connectors.excel_connector - ERROR - Error loading Excel file C:/Users/luria/PycharmProjects/AuditQAStudio2/test_data/audit_workpapers_2025Q2.xlsx: Error executing read_excel: Worksheet named 'Loading sheets...' not found - Details: {"function": "read_excel", "args": "('C:/Users/luria/PycharmProjects/AuditQAStudio2/test_data/audit_workpapers_2025Q2.xlsx',)", "kwargs": {"sheet_name": "Loading sheets...", "header": 0, "nrows": 10, "na_values": ["#N/A", "#N/A N/A", "#NA", "-NA", "#NULL!", "#NUM!", "#DIV/0!", "#VALUE!", "#REF!", "#NAME?", "#DIV/0", "#NUM", "#REF", "#VALUE"], "engine": "openpyxl", "parse_dates": true}}
2025-05-22 20:34:32,592 - data_integration.errors.error_handler - ERROR - Failed to load data from ExcelConnector: Error executing read_excel: Worksheet named 'Loading sheets...' not found - Details: {"function": "read_excel", "args": "('C:/Users/luria/PycharmProjects/AuditQAStudio2/test_data/audit_workpapers_2025Q2.xlsx',)", "kwargs": {"sheet_name": "Loading sheets...", "header": 0, "nrows": 10, "na_values": ["#N/A", "#N/A N/A", "#NA", "-NA", "#NULL!", "#NUM!", "#DIV/0!", "#VALUE!", "#REF!", "#NAME?", "#DIV/0", "#NUM", "#REF", "#VALUE"], "engine": "openpyxl", "parse_dates": true}} - Details: {"source_name": "ExcelConnector", "params": {"sheet_name": "Loading sheets...", "header": 0, "nrows": 10, "na_values": ["#N/A", "#N/A N/A", "#NA", "-NA", "#NULL!", "#NUM!", "#DIV/0!", "#VALUE!", "#REF!", "#NAME?", "#DIV/0", "#NUM", "#REF", "#VALUE"], "engine": "openpyxl", "parse_dates": true}}
Traceback (most recent call last):
  File "C:\Users\luria\PycharmProjects\QAStudiov3\data_integration\errors\error_handler.py", line 328, in safe_dataframe_operation
    return func(*args, **kwargs)
           ^^^^^^^^^^^^^^^^^^^^^
  File "C:\Users\luria\PycharmProjects\QAStudiov3\.venv\Lib\site-packages\pandas\io\excel\_base.py", line 508, in read_excel
    data = io.parse(
           ^^^^^^^^^
  File "C:\Users\luria\PycharmProjects\QAStudiov3\.venv\Lib\site-packages\pandas\io\excel\_base.py", line 1616, in parse
    return self._reader.parse(
           ^^^^^^^^^^^^^^^^^^^
  File "C:\Users\luria\PycharmProjects\QAStudiov3\.venv\Lib\site-packages\pandas\io\excel\_base.py", line 773, in parse
    sheet = self.get_sheet_by_name(asheetname)
            ^^^^^^^^^^^^^^^^^^^^^^^^^^^^^^^^^^
  File "C:\Users\luria\PycharmProjects\QAStudiov3\.venv\Lib\site-packages\pandas\io\excel\_openpyxl.py", line 582, in get_sheet_by_name
    self.raise_if_bad_sheet_by_name(name)
  File "C:\Users\luria\PycharmProjects\QAStudiov3\.venv\Lib\site-packages\pandas\io\excel\_base.py", line 624, in raise_if_bad_sheet_by_name
    raise ValueError(f"Worksheet named '{name}' not found")
ValueError: Worksheet named 'Loading sheets...' not found

During handling of the above exception, another exception occurred:

Traceback (most recent call last):
  File "C:\Users\luria\PycharmProjects\QAStudiov3\data_integration\connectors\excel_connector.py", line 195, in get_data
    df = retry_operation(
         ^^^^^^^^^^^^^^^^
  File "C:\Users\luria\PycharmProjects\QAStudiov3\data_integration\errors\error_handler.py", line 379, in retry_operation
    return func(*args, **kwargs)
           ^^^^^^^^^^^^^^^^^^^^^
  File "C:\Users\luria\PycharmProjects\QAStudiov3\data_integration\connectors\excel_connector.py", line 183, in load_excel
    return safe_dataframe_operation(
           ^^^^^^^^^^^^^^^^^^^^^^^^^
  File "C:\Users\luria\PycharmProjects\QAStudiov3\data_integration\errors\error_handler.py", line 344, in safe_dataframe_operation
    raise DataIntegrationError(error_msg, details)
data_integration.errors.error_handler.DataIntegrationError: Error executing read_excel: Worksheet named 'Loading sheets...' not found - Details: {"function": "read_excel", "args": "('C:/Users/luria/PycharmProjects/AuditQAStudio2/test_data/audit_workpapers_2025Q2.xlsx',)", "kwargs": {"sheet_name": "Loading sheets...", "header": 0, "nrows": 10, "na_values": ["#N/A", "#N/A N/A", "#NA", "-NA", "#NULL!", "#NUM!", "#DIV/0!", "#VALUE!", "#REF!", "#NAME?", "#DIV/0", "#NUM", "#REF", "#VALUE"], "engine": "openpyxl", "parse_dates": true}}
2025-05-22 20:34:32,596 - data_integration.io.importer - ERROR - Error previewing file C:/Users/luria/PycharmProjects/AuditQAStudio2/test_data/audit_workpapers_2025Q2.xlsx: Failed to load data from ExcelConnector: Error executing read_excel: Worksheet named 'Loading sheets...' not found - Details: {"function": "read_excel", "args": "('C:/Users/luria/PycharmProjects/AuditQAStudio2/test_data/audit_workpapers_2025Q2.xlsx',)", "kwargs": {"sheet_name": "Loading sheets...", "header": 0, "nrows": 10, "na_values": ["#N/A", "#N/A N/A", "#NA", "-NA", "#NULL!", "#NUM!", "#DIV/0!", "#VALUE!", "#REF!", "#NAME?", "#DIV/0", "#NUM", "#REF", "#VALUE"], "engine": "openpyxl", "parse_dates": true}} - Details: {"source_name": "ExcelConnector", "params": {"sheet_name": "Loading sheets...", "header": 0, "nrows": 10, "na_values": ["#N/A", "#N/A N/A", "#NA", "-NA", "#NULL!", "#NUM!", "#DIV/0!", "#VALUE!", "#REF!", "#NAME?", "#DIV/0", "#NUM", "#REF", "#VALUE"], "engine": "openpyxl", "parse_dates": true}}
2025-05-22 20:34:32,596 - data_source_panel - ERROR - Error loading file preview: Failed to load data from ExcelConnector: Error executing read_excel: Worksheet named 'Loading sheets...' not found - Details: {"function": "read_excel", "args": "('C:/Users/luria/PycharmProjects/AuditQAStudio2/test_data/audit_workpapers_2025Q2.xlsx',)", "kwargs": {"sheet_name": "Loading sheets...", "header": 0, "nrows": 10, "na_values": ["#N/A", "#N/A N/A", "#NA", "-NA", "#NULL!", "#NUM!", "#DIV/0!", "#VALUE!", "#REF!", "#NAME?", "#DIV/0", "#NUM", "#REF", "#VALUE"], "engine": "openpyxl", "parse_dates": true}} - Details: {"source_name": "ExcelConnector", "params": {"sheet_name": "Loading sheets...", "header": 0, "nrows": 10, "na_values": ["#N/A", "#N/A N/A", "#NA", "-NA", "#NULL!", "#NUM!", "#DIV/0!", "#VALUE!", "#REF!", "#NAME?", "#DIV/0", "#NUM", "#REF", "#VALUE"], "engine": "openpyxl", "parse_dates": true}}
2025-05-22 20:34:32,602 - progress_widget - INFO - Progress operation started
2025-05-22 20:34:32,605 - progress_widget - INFO - Progress operation started
2025-05-22 20:34:32,607 - progress_widget - INFO - Progress operation completed: Error: Error loading file preview: Failed to load data from ExcelConnector: Error executing read_excel: Worksheet named 'Loading sheets...' not found - Details: {"function": "read_excel", "args": "('C:/Users/luria/PycharmProjects/AuditQAStudio2/test_data/audit_workpapers_2025Q2.xlsx',)", "kwargs": {"sheet_name": "Loading sheets...", "header": 0, "nrows": 10, "na_values": ["#N/A", "#N/A N/A", "#NA", "-NA", "#NULL!", "#NUM!", "#DIV/0!", "#VALUE!", "#REF!", "#NAME?", "#DIV/0", "#NUM", "#REF", "#VALUE"], "engine": "openpyxl", "parse_dates": true}} - Details: {"source_name": "ExcelConnector", "params": {"sheet_name": "Loading sheets...", "header": 0, "nrows": 10, "na_values": ["#N/A", "#N/A N/A", "#NA", "-NA", "#NULL!", "#NUM!", "#DIV/0!", "#VALUE!", "#REF!", "#NAME?", "#DIV/0", "#NUM", "#REF", "#VALUE"], "engine": "openpyxl", "parse_dates": true}}
2025-05-22 20:34:32,613 - data_source_panel - ERROR - Preview error: Error loading file preview: Failed to load data from ExcelConnector: Error executing read_excel: Worksheet named 'Loading sheets...' not found - Details: {"function": "read_excel", "args": "('C:/Users/luria/PycharmProjects/AuditQAStudio2/test_data/audit_workpapers_2025Q2.xlsx',)", "kwargs": {"sheet_name": "Loading sheets...", "header": 0, "nrows": 10, "na_values": ["#N/A", "#N/A N/A", "#NA", "-NA", "#NULL!", "#NUM!", "#DIV/0!", "#VALUE!", "#REF!", "#NAME?", "#DIV/0", "#NUM", "#REF", "#VALUE"], "engine": "openpyxl", "parse_dates": true}} - Details: {"source_name": "ExcelConnector", "params": {"sheet_name": "Loading sheets...", "header": 0, "nrows": 10, "na_values": ["#N/A", "#N/A N/A", "#NA", "-NA", "#NULL!", "#NUM!", "#DIV/0!", "#VALUE!", "#REF!", "#NAME?", "#DIV/0", "#NUM", "#REF", "#VALUE"], "engine": "openpyxl", "parse_dates": true}}
2025-05-22 20:34:32,654 - __main__ - INFO - Data preview loaded: 10 rows, 11 columns
2025-05-22 20:34:32,656 - data_source_panel - INFO - Preview loaded: 10 rows, 11 columns
2025-05-22 20:34:34,302 - progress_widget - INFO - Progress operation started
2025-05-22 20:34:34,324 - progress_widget - INFO - Progress operation completed: Preview loaded successfully
2025-05-22 20:34:34,325 - __main__ - INFO - Data preview loaded: 10 rows, 11 columns
2025-05-22 20:34:34,325 - data_source_panel - INFO - Preview loaded: 10 rows, 11 columns
2025-05-22 20:40:35,139 - __main__ - INFO - Application closing
2025-05-22 20:40:35,150 - error_handler - CRITICAL - TypeError: Object of type QByteArray is not JSON serializable
2025-05-22 20:40:36,738 - __main__ - ERROR - ERROR: Object of type QByteArray is not JSON serializable
2025-05-22 20:41:31,548 - error_handler - INFO - Error handler initialized
2025-05-22 20:41:31,549 - session_manager - WARNING - Error loading configuration: Expecting value: line 2 column 22 (char 23)
2025-05-22 20:41:31,549 - session_manager - INFO - Attempting to restore from backup...
2025-05-22 20:41:31,549 - session_manager - INFO - Configuration restored from backup: session_backups\session_backup1.json
2025-05-22 20:41:31,549 - session_manager - INFO - Session manager initialized with config: session.json
2025-05-22 20:41:31,550 - session_manager - INFO - Backup directory: session_backups
2025-05-22 20:41:31,599 - __main__ - INFO - Application state restored
2025-05-22 20:41:31,599 - __main__ - INFO - Backend systems initialized
2025-05-22 20:41:31,599 - __main__ - INFO - Analytics Runner application initialized successfully
2025-05-22 20:42:41,546 - __main__ - INFO - Data source changed: audit_workpapers_2025Q2.xlsx
2025-05-22 20:42:41,546 - __main__ - INFO - Data source validation: File appears valid
2025-05-22 20:42:42,286 - data_integration.connectors.excel_connector - ERROR - Error loading Excel file C:\Users\luria\PycharmProjects\AuditQAStudio2\test_data\audit_workpapers_2025Q2.xlsx: Error executing read_excel: Worksheet named 'Loading...' not found - Details: {"function": "read_excel", "args": "('C:\\\\Users\\\\luria\\\\PycharmProjects\\\\AuditQAStudio2\\\\test_data\\\\audit_workpapers_2025Q2.xlsx',)", "kwargs": {"sheet_name": "Loading...", "header": 0, "nrows": 50, "na_values": ["#N/A", "#N/A N/A", "#NA", "-NA", "#NULL!", "#NUM!", "#DIV/0!", "#VALUE!", "#REF!", "#NAME?", "#DIV/0", "#NUM", "#REF", "#VALUE"], "engine": "openpyxl", "parse_dates": true}}
2025-05-22 20:42:42,286 - data_integration.errors.error_handler - ERROR - Failed to load data from ExcelConnector: Error executing read_excel: Worksheet named 'Loading...' not found - Details: {"function": "read_excel", "args": "('C:\\\\Users\\\\luria\\\\PycharmProjects\\\\AuditQAStudio2\\\\test_data\\\\audit_workpapers_2025Q2.xlsx',)", "kwargs": {"sheet_name": "Loading...", "header": 0, "nrows": 50, "na_values": ["#N/A", "#N/A N/A", "#NA", "-NA", "#NULL!", "#NUM!", "#DIV/0!", "#VALUE!", "#REF!", "#NAME?", "#DIV/0", "#NUM", "#REF", "#VALUE"], "engine": "openpyxl", "parse_dates": true}} - Details: {"source_name": "ExcelConnector", "params": {"sheet_name": "Loading...", "header": 0, "nrows": 50, "na_values": ["#N/A", "#N/A N/A", "#NA", "-NA", "#NULL!", "#NUM!", "#DIV/0!", "#VALUE!", "#REF!", "#NAME?", "#DIV/0", "#NUM", "#REF", "#VALUE"], "engine": "openpyxl", "parse_dates": true}}
Traceback (most recent call last):
  File "C:\Users\luria\PycharmProjects\QAStudiov3\data_integration\errors\error_handler.py", line 328, in safe_dataframe_operation
    return func(*args, **kwargs)
           ^^^^^^^^^^^^^^^^^^^^^
  File "C:\Users\luria\PycharmProjects\QAStudiov3\.venv\Lib\site-packages\pandas\io\excel\_base.py", line 508, in read_excel
    data = io.parse(
           ^^^^^^^^^
  File "C:\Users\luria\PycharmProjects\QAStudiov3\.venv\Lib\site-packages\pandas\io\excel\_base.py", line 1616, in parse
    return self._reader.parse(
           ^^^^^^^^^^^^^^^^^^^
  File "C:\Users\luria\PycharmProjects\QAStudiov3\.venv\Lib\site-packages\pandas\io\excel\_base.py", line 773, in parse
    sheet = self.get_sheet_by_name(asheetname)
            ^^^^^^^^^^^^^^^^^^^^^^^^^^^^^^^^^^
  File "C:\Users\luria\PycharmProjects\QAStudiov3\.venv\Lib\site-packages\pandas\io\excel\_openpyxl.py", line 582, in get_sheet_by_name
    self.raise_if_bad_sheet_by_name(name)
  File "C:\Users\luria\PycharmProjects\QAStudiov3\.venv\Lib\site-packages\pandas\io\excel\_base.py", line 624, in raise_if_bad_sheet_by_name
    raise ValueError(f"Worksheet named '{name}' not found")
ValueError: Worksheet named 'Loading...' not found

During handling of the above exception, another exception occurred:

Traceback (most recent call last):
  File "C:\Users\luria\PycharmProjects\QAStudiov3\data_integration\connectors\excel_connector.py", line 195, in get_data
    df = retry_operation(
         ^^^^^^^^^^^^^^^^
  File "C:\Users\luria\PycharmProjects\QAStudiov3\data_integration\errors\error_handler.py", line 379, in retry_operation
    return func(*args, **kwargs)
           ^^^^^^^^^^^^^^^^^^^^^
  File "C:\Users\luria\PycharmProjects\QAStudiov3\data_integration\connectors\excel_connector.py", line 183, in load_excel
    return safe_dataframe_operation(
           ^^^^^^^^^^^^^^^^^^^^^^^^^
  File "C:\Users\luria\PycharmProjects\QAStudiov3\data_integration\errors\error_handler.py", line 344, in safe_dataframe_operation
    raise DataIntegrationError(error_msg, details)
data_integration.errors.error_handler.DataIntegrationError: Error executing read_excel: Worksheet named 'Loading...' not found - Details: {"function": "read_excel", "args": "('C:\\\\Users\\\\luria\\\\PycharmProjects\\\\AuditQAStudio2\\\\test_data\\\\audit_workpapers_2025Q2.xlsx',)", "kwargs": {"sheet_name": "Loading...", "header": 0, "nrows": 50, "na_values": ["#N/A", "#N/A N/A", "#NA", "-NA", "#NULL!", "#NUM!", "#DIV/0!", "#VALUE!", "#REF!", "#NAME?", "#DIV/0", "#NUM", "#REF", "#VALUE"], "engine": "openpyxl", "parse_dates": true}}
2025-05-22 20:42:42,289 - data_integration.io.importer - ERROR - Error previewing file C:\Users\luria\PycharmProjects\AuditQAStudio2\test_data\audit_workpapers_2025Q2.xlsx: Failed to load data from ExcelConnector: Error executing read_excel: Worksheet named 'Loading...' not found - Details: {"function": "read_excel", "args": "('C:\\\\Users\\\\luria\\\\PycharmProjects\\\\AuditQAStudio2\\\\test_data\\\\audit_workpapers_2025Q2.xlsx',)", "kwargs": {"sheet_name": "Loading...", "header": 0, "nrows": 50, "na_values": ["#N/A", "#N/A N/A", "#NA", "-NA", "#NULL!", "#NUM!", "#DIV/0!", "#VALUE!", "#REF!", "#NAME?", "#DIV/0", "#NUM", "#REF", "#VALUE"], "engine": "openpyxl", "parse_dates": true}} - Details: {"source_name": "ExcelConnector", "params": {"sheet_name": "Loading...", "header": 0, "nrows": 50, "na_values": ["#N/A", "#N/A N/A", "#NA", "-NA", "#NULL!", "#NUM!", "#DIV/0!", "#VALUE!", "#REF!", "#NAME?", "#DIV/0", "#NUM", "#REF", "#VALUE"], "engine": "openpyxl", "parse_dates": true}}
2025-05-22 20:42:42,289 - data_source_panel - ERROR - Error loading file preview: Failed to load data from ExcelConnector: Error executing read_excel: Worksheet named 'Loading...' not found - Details: {"function": "read_excel", "args": "('C:\\\\Users\\\\luria\\\\PycharmProjects\\\\AuditQAStudio2\\\\test_data\\\\audit_workpapers_2025Q2.xlsx',)", "kwargs": {"sheet_name": "Loading...", "header": 0, "nrows": 50, "na_values": ["#N/A", "#N/A N/A", "#NA", "-NA", "#NULL!", "#NUM!", "#DIV/0!", "#VALUE!", "#REF!", "#NAME?", "#DIV/0", "#NUM", "#REF", "#VALUE"], "engine": "openpyxl", "parse_dates": true}} - Details: {"source_name": "ExcelConnector", "params": {"sheet_name": "Loading...", "header": 0, "nrows": 50, "na_values": ["#N/A", "#N/A N/A", "#NA", "-NA", "#NULL!", "#NUM!", "#DIV/0!", "#VALUE!", "#REF!", "#NAME?", "#DIV/0", "#NUM", "#REF", "#VALUE"], "engine": "openpyxl", "parse_dates": true}}
2025-05-22 20:42:42,294 - data_source_panel - ERROR - Preview error: Error loading file preview: Failed to load data from ExcelConnector: Error executing read_excel: Worksheet named 'Loading...' not found - Details: {"function": "read_excel", "args": "('C:\\\\Users\\\\luria\\\\PycharmProjects\\\\AuditQAStudio2\\\\test_data\\\\audit_workpapers_2025Q2.xlsx',)", "kwargs": {"sheet_name": "Loading...", "header": 0, "nrows": 50, "na_values": ["#N/A", "#N/A N/A", "#NA", "-NA", "#NULL!", "#NUM!", "#DIV/0!", "#VALUE!", "#REF!", "#NAME?", "#DIV/0", "#NUM", "#REF", "#VALUE"], "engine": "openpyxl", "parse_dates": true}} - Details: {"source_name": "ExcelConnector", "params": {"sheet_name": "Loading...", "header": 0, "nrows": 50, "na_values": ["#N/A", "#N/A N/A", "#NA", "-NA", "#NULL!", "#NUM!", "#DIV/0!", "#VALUE!", "#REF!", "#NAME?", "#DIV/0", "#NUM", "#REF", "#VALUE"], "engine": "openpyxl", "parse_dates": true}}
2025-05-22 20:42:42,319 - __main__ - INFO - Data preview loaded: 30 rows, 11 columns
2025-05-22 20:42:42,321 - data_source_panel - INFO - Preview loaded: 30 rows, 11 columns
2025-05-22 20:52:33,979 - __main__ - INFO - Data source changed: 
2025-05-22 20:52:37,501 - __main__ - INFO - Data source changed: audit_workpapers_2025Q2.xlsx
2025-05-22 20:52:37,502 - __main__ - INFO - Data source validation: File appears valid
2025-05-22 20:52:37,513 - data_integration.connectors.excel_connector - ERROR - Error loading Excel file C:\Users\luria\PycharmProjects\AuditQAStudio2\test_data\audit_workpapers_2025Q2.xlsx: Error executing read_excel: Worksheet named 'Loading...' not found - Details: {"function": "read_excel", "args": "('C:\\\\Users\\\\luria\\\\PycharmProjects\\\\AuditQAStudio2\\\\test_data\\\\audit_workpapers_2025Q2.xlsx',)", "kwargs": {"sheet_name": "Loading...", "header": 0, "nrows": 50, "na_values": ["#N/A", "#N/A N/A", "#NA", "-NA", "#NULL!", "#NUM!", "#DIV/0!", "#VALUE!", "#REF!", "#NAME?", "#DIV/0", "#NUM", "#REF", "#VALUE"], "engine": "openpyxl", "parse_dates": true}}
2025-05-22 20:52:37,513 - data_integration.errors.error_handler - ERROR - Failed to load data from ExcelConnector: Error executing read_excel: Worksheet named 'Loading...' not found - Details: {"function": "read_excel", "args": "('C:\\\\Users\\\\luria\\\\PycharmProjects\\\\AuditQAStudio2\\\\test_data\\\\audit_workpapers_2025Q2.xlsx',)", "kwargs": {"sheet_name": "Loading...", "header": 0, "nrows": 50, "na_values": ["#N/A", "#N/A N/A", "#NA", "-NA", "#NULL!", "#NUM!", "#DIV/0!", "#VALUE!", "#REF!", "#NAME?", "#DIV/0", "#NUM", "#REF", "#VALUE"], "engine": "openpyxl", "parse_dates": true}} - Details: {"source_name": "ExcelConnector", "params": {"sheet_name": "Loading...", "header": 0, "nrows": 50, "na_values": ["#N/A", "#N/A N/A", "#NA", "-NA", "#NULL!", "#NUM!", "#DIV/0!", "#VALUE!", "#REF!", "#NAME?", "#DIV/0", "#NUM", "#REF", "#VALUE"], "engine": "openpyxl", "parse_dates": true}}
Traceback (most recent call last):
  File "C:\Users\luria\PycharmProjects\QAStudiov3\data_integration\errors\error_handler.py", line 328, in safe_dataframe_operation
    return func(*args, **kwargs)
           ^^^^^^^^^^^^^^^^^^^^^
  File "C:\Users\luria\PycharmProjects\QAStudiov3\.venv\Lib\site-packages\pandas\io\excel\_base.py", line 508, in read_excel
    data = io.parse(
           ^^^^^^^^^
  File "C:\Users\luria\PycharmProjects\QAStudiov3\.venv\Lib\site-packages\pandas\io\excel\_base.py", line 1616, in parse
    return self._reader.parse(
           ^^^^^^^^^^^^^^^^^^^
  File "C:\Users\luria\PycharmProjects\QAStudiov3\.venv\Lib\site-packages\pandas\io\excel\_base.py", line 773, in parse
    sheet = self.get_sheet_by_name(asheetname)
            ^^^^^^^^^^^^^^^^^^^^^^^^^^^^^^^^^^
  File "C:\Users\luria\PycharmProjects\QAStudiov3\.venv\Lib\site-packages\pandas\io\excel\_openpyxl.py", line 582, in get_sheet_by_name
    self.raise_if_bad_sheet_by_name(name)
  File "C:\Users\luria\PycharmProjects\QAStudiov3\.venv\Lib\site-packages\pandas\io\excel\_base.py", line 624, in raise_if_bad_sheet_by_name
    raise ValueError(f"Worksheet named '{name}' not found")
ValueError: Worksheet named 'Loading...' not found

During handling of the above exception, another exception occurred:

Traceback (most recent call last):
  File "C:\Users\luria\PycharmProjects\QAStudiov3\data_integration\connectors\excel_connector.py", line 195, in get_data
    df = retry_operation(
         ^^^^^^^^^^^^^^^^
  File "C:\Users\luria\PycharmProjects\QAStudiov3\data_integration\errors\error_handler.py", line 379, in retry_operation
    return func(*args, **kwargs)
           ^^^^^^^^^^^^^^^^^^^^^
  File "C:\Users\luria\PycharmProjects\QAStudiov3\data_integration\connectors\excel_connector.py", line 183, in load_excel
    return safe_dataframe_operation(
           ^^^^^^^^^^^^^^^^^^^^^^^^^
  File "C:\Users\luria\PycharmProjects\QAStudiov3\data_integration\errors\error_handler.py", line 344, in safe_dataframe_operation
    raise DataIntegrationError(error_msg, details)
data_integration.errors.error_handler.DataIntegrationError: Error executing read_excel: Worksheet named 'Loading...' not found - Details: {"function": "read_excel", "args": "('C:\\\\Users\\\\luria\\\\PycharmProjects\\\\AuditQAStudio2\\\\test_data\\\\audit_workpapers_2025Q2.xlsx',)", "kwargs": {"sheet_name": "Loading...", "header": 0, "nrows": 50, "na_values": ["#N/A", "#N/A N/A", "#NA", "-NA", "#NULL!", "#NUM!", "#DIV/0!", "#VALUE!", "#REF!", "#NAME?", "#DIV/0", "#NUM", "#REF", "#VALUE"], "engine": "openpyxl", "parse_dates": true}}
2025-05-22 20:52:37,514 - data_integration.io.importer - ERROR - Error previewing file C:\Users\luria\PycharmProjects\AuditQAStudio2\test_data\audit_workpapers_2025Q2.xlsx: Failed to load data from ExcelConnector: Error executing read_excel: Worksheet named 'Loading...' not found - Details: {"function": "read_excel", "args": "('C:\\\\Users\\\\luria\\\\PycharmProjects\\\\AuditQAStudio2\\\\test_data\\\\audit_workpapers_2025Q2.xlsx',)", "kwargs": {"sheet_name": "Loading...", "header": 0, "nrows": 50, "na_values": ["#N/A", "#N/A N/A", "#NA", "-NA", "#NULL!", "#NUM!", "#DIV/0!", "#VALUE!", "#REF!", "#NAME?", "#DIV/0", "#NUM", "#REF", "#VALUE"], "engine": "openpyxl", "parse_dates": true}} - Details: {"source_name": "ExcelConnector", "params": {"sheet_name": "Loading...", "header": 0, "nrows": 50, "na_values": ["#N/A", "#N/A N/A", "#NA", "-NA", "#NULL!", "#NUM!", "#DIV/0!", "#VALUE!", "#REF!", "#NAME?", "#DIV/0", "#NUM", "#REF", "#VALUE"], "engine": "openpyxl", "parse_dates": true}}
2025-05-22 20:52:37,514 - data_source_panel - ERROR - Error loading file preview: Failed to load data from ExcelConnector: Error executing read_excel: Worksheet named 'Loading...' not found - Details: {"function": "read_excel", "args": "('C:\\\\Users\\\\luria\\\\PycharmProjects\\\\AuditQAStudio2\\\\test_data\\\\audit_workpapers_2025Q2.xlsx',)", "kwargs": {"sheet_name": "Loading...", "header": 0, "nrows": 50, "na_values": ["#N/A", "#N/A N/A", "#NA", "-NA", "#NULL!", "#NUM!", "#DIV/0!", "#VALUE!", "#REF!", "#NAME?", "#DIV/0", "#NUM", "#REF", "#VALUE"], "engine": "openpyxl", "parse_dates": true}} - Details: {"source_name": "ExcelConnector", "params": {"sheet_name": "Loading...", "header": 0, "nrows": 50, "na_values": ["#N/A", "#N/A N/A", "#NA", "-NA", "#NULL!", "#NUM!", "#DIV/0!", "#VALUE!", "#REF!", "#NAME?", "#DIV/0", "#NUM", "#REF", "#VALUE"], "engine": "openpyxl", "parse_dates": true}}
2025-05-22 20:52:37,520 - data_source_panel - ERROR - Preview error: Error loading file preview: Failed to load data from ExcelConnector: Error executing read_excel: Worksheet named 'Loading...' not found - Details: {"function": "read_excel", "args": "('C:\\\\Users\\\\luria\\\\PycharmProjects\\\\AuditQAStudio2\\\\test_data\\\\audit_workpapers_2025Q2.xlsx',)", "kwargs": {"sheet_name": "Loading...", "header": 0, "nrows": 50, "na_values": ["#N/A", "#N/A N/A", "#NA", "-NA", "#NULL!", "#NUM!", "#DIV/0!", "#VALUE!", "#REF!", "#NAME?", "#DIV/0", "#NUM", "#REF", "#VALUE"], "engine": "openpyxl", "parse_dates": true}} - Details: {"source_name": "ExcelConnector", "params": {"sheet_name": "Loading...", "header": 0, "nrows": 50, "na_values": ["#N/A", "#N/A N/A", "#NA", "-NA", "#NULL!", "#NUM!", "#DIV/0!", "#VALUE!", "#REF!", "#NAME?", "#DIV/0", "#NUM", "#REF", "#VALUE"], "engine": "openpyxl", "parse_dates": true}}
2025-05-22 20:52:37,540 - __main__ - INFO - Data preview loaded: 30 rows, 11 columns
2025-05-22 20:52:37,540 - data_source_panel - INFO - Preview loaded: 30 rows, 11 columns
2025-05-22 20:52:39,678 - __main__ - INFO - Data preview loaded: 30 rows, 11 columns
2025-05-22 20:52:39,678 - data_source_panel - INFO - Preview loaded: 30 rows, 11 columns
2025-05-22 20:53:59,870 - __main__ - INFO - Application closing
2025-05-22 20:53:59,876 - error_handler - CRITICAL - TypeError: Object of type QByteArray is not JSON serializable
2025-05-22 20:54:05,928 - __main__ - ERROR - ERROR: Object of type QByteArray is not JSON serializable
2025-05-22 20:54:14,713 - error_handler - INFO - Error handler initialized
2025-05-22 20:54:14,713 - session_manager - WARNING - Error loading configuration: Expecting value: line 2 column 22 (char 23)
2025-05-22 20:54:14,713 - session_manager - INFO - Attempting to restore from backup...
2025-05-22 20:54:14,714 - session_manager - INFO - Configuration restored from backup: session_backups\session_backup1.json
2025-05-22 20:54:14,714 - session_manager - INFO - Session manager initialized with config: session.json
2025-05-22 20:54:14,714 - session_manager - INFO - Backup directory: session_backups
2025-05-22 20:54:14,756 - __main__ - INFO - Application state restored
2025-05-22 20:54:14,756 - __main__ - INFO - Backend systems initialized
2025-05-22 20:54:14,756 - __main__ - INFO - Analytics Runner application initialized successfully
2025-05-22 20:54:19,690 - __main__ - INFO - Data source changed: audit_workpapers_2025Q2.xlsx
2025-05-22 20:54:19,691 - __main__ - INFO - Data source validation: File appears valid
2025-05-22 20:54:20,190 - data_integration.connectors.excel_connector - ERROR - Error loading Excel file C:\Users\luria\PycharmProjects\AuditQAStudio2\test_data\audit_workpapers_2025Q2.xlsx: Error executing read_excel: Worksheet named 'Loading...' not found - Details: {"function": "read_excel", "args": "('C:\\\\Users\\\\luria\\\\PycharmProjects\\\\AuditQAStudio2\\\\test_data\\\\audit_workpapers_2025Q2.xlsx',)", "kwargs": {"sheet_name": "Loading...", "header": 0, "nrows": 50, "na_values": ["#N/A", "#N/A N/A", "#NA", "-NA", "#NULL!", "#NUM!", "#DIV/0!", "#VALUE!", "#REF!", "#NAME?", "#DIV/0", "#NUM", "#REF", "#VALUE"], "engine": "openpyxl", "parse_dates": true}}
2025-05-22 20:54:20,190 - data_integration.errors.error_handler - ERROR - Failed to load data from ExcelConnector: Error executing read_excel: Worksheet named 'Loading...' not found - Details: {"function": "read_excel", "args": "('C:\\\\Users\\\\luria\\\\PycharmProjects\\\\AuditQAStudio2\\\\test_data\\\\audit_workpapers_2025Q2.xlsx',)", "kwargs": {"sheet_name": "Loading...", "header": 0, "nrows": 50, "na_values": ["#N/A", "#N/A N/A", "#NA", "-NA", "#NULL!", "#NUM!", "#DIV/0!", "#VALUE!", "#REF!", "#NAME?", "#DIV/0", "#NUM", "#REF", "#VALUE"], "engine": "openpyxl", "parse_dates": true}} - Details: {"source_name": "ExcelConnector", "params": {"sheet_name": "Loading...", "header": 0, "nrows": 50, "na_values": ["#N/A", "#N/A N/A", "#NA", "-NA", "#NULL!", "#NUM!", "#DIV/0!", "#VALUE!", "#REF!", "#NAME?", "#DIV/0", "#NUM", "#REF", "#VALUE"], "engine": "openpyxl", "parse_dates": true}}
Traceback (most recent call last):
  File "C:\Users\luria\PycharmProjects\QAStudiov3\data_integration\errors\error_handler.py", line 328, in safe_dataframe_operation
    return func(*args, **kwargs)
           ^^^^^^^^^^^^^^^^^^^^^
  File "C:\Users\luria\PycharmProjects\QAStudiov3\.venv\Lib\site-packages\pandas\io\excel\_base.py", line 508, in read_excel
    data = io.parse(
           ^^^^^^^^^
  File "C:\Users\luria\PycharmProjects\QAStudiov3\.venv\Lib\site-packages\pandas\io\excel\_base.py", line 1616, in parse
    return self._reader.parse(
           ^^^^^^^^^^^^^^^^^^^
  File "C:\Users\luria\PycharmProjects\QAStudiov3\.venv\Lib\site-packages\pandas\io\excel\_base.py", line 773, in parse
    sheet = self.get_sheet_by_name(asheetname)
            ^^^^^^^^^^^^^^^^^^^^^^^^^^^^^^^^^^
  File "C:\Users\luria\PycharmProjects\QAStudiov3\.venv\Lib\site-packages\pandas\io\excel\_openpyxl.py", line 582, in get_sheet_by_name
    self.raise_if_bad_sheet_by_name(name)
  File "C:\Users\luria\PycharmProjects\QAStudiov3\.venv\Lib\site-packages\pandas\io\excel\_base.py", line 624, in raise_if_bad_sheet_by_name
    raise ValueError(f"Worksheet named '{name}' not found")
ValueError: Worksheet named 'Loading...' not found

During handling of the above exception, another exception occurred:

Traceback (most recent call last):
  File "C:\Users\luria\PycharmProjects\QAStudiov3\data_integration\connectors\excel_connector.py", line 195, in get_data
    df = retry_operation(
         ^^^^^^^^^^^^^^^^
  File "C:\Users\luria\PycharmProjects\QAStudiov3\data_integration\errors\error_handler.py", line 379, in retry_operation
    return func(*args, **kwargs)
           ^^^^^^^^^^^^^^^^^^^^^
  File "C:\Users\luria\PycharmProjects\QAStudiov3\data_integration\connectors\excel_connector.py", line 183, in load_excel
    return safe_dataframe_operation(
           ^^^^^^^^^^^^^^^^^^^^^^^^^
  File "C:\Users\luria\PycharmProjects\QAStudiov3\data_integration\errors\error_handler.py", line 344, in safe_dataframe_operation
    raise DataIntegrationError(error_msg, details)
data_integration.errors.error_handler.DataIntegrationError: Error executing read_excel: Worksheet named 'Loading...' not found - Details: {"function": "read_excel", "args": "('C:\\\\Users\\\\luria\\\\PycharmProjects\\\\AuditQAStudio2\\\\test_data\\\\audit_workpapers_2025Q2.xlsx',)", "kwargs": {"sheet_name": "Loading...", "header": 0, "nrows": 50, "na_values": ["#N/A", "#N/A N/A", "#NA", "-NA", "#NULL!", "#NUM!", "#DIV/0!", "#VALUE!", "#REF!", "#NAME?", "#DIV/0", "#NUM", "#REF", "#VALUE"], "engine": "openpyxl", "parse_dates": true}}
2025-05-22 20:54:20,193 - data_integration.io.importer - ERROR - Error previewing file C:\Users\luria\PycharmProjects\AuditQAStudio2\test_data\audit_workpapers_2025Q2.xlsx: Failed to load data from ExcelConnector: Error executing read_excel: Worksheet named 'Loading...' not found - Details: {"function": "read_excel", "args": "('C:\\\\Users\\\\luria\\\\PycharmProjects\\\\AuditQAStudio2\\\\test_data\\\\audit_workpapers_2025Q2.xlsx',)", "kwargs": {"sheet_name": "Loading...", "header": 0, "nrows": 50, "na_values": ["#N/A", "#N/A N/A", "#NA", "-NA", "#NULL!", "#NUM!", "#DIV/0!", "#VALUE!", "#REF!", "#NAME?", "#DIV/0", "#NUM", "#REF", "#VALUE"], "engine": "openpyxl", "parse_dates": true}} - Details: {"source_name": "ExcelConnector", "params": {"sheet_name": "Loading...", "header": 0, "nrows": 50, "na_values": ["#N/A", "#N/A N/A", "#NA", "-NA", "#NULL!", "#NUM!", "#DIV/0!", "#VALUE!", "#REF!", "#NAME?", "#DIV/0", "#NUM", "#REF", "#VALUE"], "engine": "openpyxl", "parse_dates": true}}
2025-05-22 20:54:20,193 - data_source_panel - ERROR - Error loading file preview: Failed to load data from ExcelConnector: Error executing read_excel: Worksheet named 'Loading...' not found - Details: {"function": "read_excel", "args": "('C:\\\\Users\\\\luria\\\\PycharmProjects\\\\AuditQAStudio2\\\\test_data\\\\audit_workpapers_2025Q2.xlsx',)", "kwargs": {"sheet_name": "Loading...", "header": 0, "nrows": 50, "na_values": ["#N/A", "#N/A N/A", "#NA", "-NA", "#NULL!", "#NUM!", "#DIV/0!", "#VALUE!", "#REF!", "#NAME?", "#DIV/0", "#NUM", "#REF", "#VALUE"], "engine": "openpyxl", "parse_dates": true}} - Details: {"source_name": "ExcelConnector", "params": {"sheet_name": "Loading...", "header": 0, "nrows": 50, "na_values": ["#N/A", "#N/A N/A", "#NA", "-NA", "#NULL!", "#NUM!", "#DIV/0!", "#VALUE!", "#REF!", "#NAME?", "#DIV/0", "#NUM", "#REF", "#VALUE"], "engine": "openpyxl", "parse_dates": true}}
2025-05-22 20:54:20,200 - data_source_panel - ERROR - Preview error: Error loading file preview: Failed to load data from ExcelConnector: Error executing read_excel: Worksheet named 'Loading...' not found - Details: {"function": "read_excel", "args": "('C:\\\\Users\\\\luria\\\\PycharmProjects\\\\AuditQAStudio2\\\\test_data\\\\audit_workpapers_2025Q2.xlsx',)", "kwargs": {"sheet_name": "Loading...", "header": 0, "nrows": 50, "na_values": ["#N/A", "#N/A N/A", "#NA", "-NA", "#NULL!", "#NUM!", "#DIV/0!", "#VALUE!", "#REF!", "#NAME?", "#DIV/0", "#NUM", "#REF", "#VALUE"], "engine": "openpyxl", "parse_dates": true}} - Details: {"source_name": "ExcelConnector", "params": {"sheet_name": "Loading...", "header": 0, "nrows": 50, "na_values": ["#N/A", "#N/A N/A", "#NA", "-NA", "#NULL!", "#NUM!", "#DIV/0!", "#VALUE!", "#REF!", "#NAME?", "#DIV/0", "#NUM", "#REF", "#VALUE"], "engine": "openpyxl", "parse_dates": true}}
2025-05-22 20:54:20,224 - __main__ - INFO - Data preview loaded: 30 rows, 11 columns
2025-05-22 20:54:20,225 - data_source_panel - INFO - Preview loaded: 30 rows, 11 columns
2025-05-22 20:54:28,487 - __main__ - INFO - Data preview loaded: 30 rows, 11 columns
2025-05-22 20:54:28,488 - data_source_panel - INFO - Preview loaded: 30 rows, 11 columns
2025-05-22 20:55:04,747 - __main__ - INFO - Application closing
2025-05-22 20:55:04,750 - error_handler - CRITICAL - TypeError: Object of type QByteArray is not JSON serializable
2025-05-22 20:55:05,743 - __main__ - ERROR - ERROR: Object of type QByteArray is not JSON serializable
2025-05-22 20:55:21,881 - error_handler - INFO - Error handler initialized
2025-05-22 20:55:21,882 - session_manager - WARNING - Error loading configuration: Expecting value: line 2 column 22 (char 23)
2025-05-22 20:55:21,882 - session_manager - INFO - Attempting to restore from backup...
2025-05-22 20:55:21,882 - session_manager - INFO - Configuration restored from backup: session_backups\session_backup1.json
2025-05-22 20:55:21,882 - session_manager - INFO - Session manager initialized with config: session.json
2025-05-22 20:55:21,882 - session_manager - INFO - Backup directory: session_backups
2025-05-22 20:55:21,920 - __main__ - INFO - Application state restored
2025-05-22 20:55:21,920 - __main__ - INFO - Backend systems initialized
2025-05-22 20:55:21,920 - __main__ - INFO - Analytics Runner application initialized successfully
2025-05-22 20:55:24,680 - __main__ - INFO - Data source changed: audit_workpapers_2025Q2.xlsx
2025-05-22 20:55:24,680 - __main__ - INFO - Data source validation: File appears valid
2025-05-22 20:55:25,081 - data_integration.connectors.excel_connector - ERROR - Error loading Excel file C:\Users\luria\PycharmProjects\AuditQAStudio2\test_data\audit_workpapers_2025Q2.xlsx: Error executing read_excel: Worksheet named 'Loading...' not found - Details: {"function": "read_excel", "args": "('C:\\\\Users\\\\luria\\\\PycharmProjects\\\\AuditQAStudio2\\\\test_data\\\\audit_workpapers_2025Q2.xlsx',)", "kwargs": {"sheet_name": "Loading...", "header": 0, "nrows": 50, "na_values": ["#N/A", "#N/A N/A", "#NA", "-NA", "#NULL!", "#NUM!", "#DIV/0!", "#VALUE!", "#REF!", "#NAME?", "#DIV/0", "#NUM", "#REF", "#VALUE"], "engine": "openpyxl", "parse_dates": true}}
2025-05-22 20:55:25,081 - data_integration.errors.error_handler - ERROR - Failed to load data from ExcelConnector: Error executing read_excel: Worksheet named 'Loading...' not found - Details: {"function": "read_excel", "args": "('C:\\\\Users\\\\luria\\\\PycharmProjects\\\\AuditQAStudio2\\\\test_data\\\\audit_workpapers_2025Q2.xlsx',)", "kwargs": {"sheet_name": "Loading...", "header": 0, "nrows": 50, "na_values": ["#N/A", "#N/A N/A", "#NA", "-NA", "#NULL!", "#NUM!", "#DIV/0!", "#VALUE!", "#REF!", "#NAME?", "#DIV/0", "#NUM", "#REF", "#VALUE"], "engine": "openpyxl", "parse_dates": true}} - Details: {"source_name": "ExcelConnector", "params": {"sheet_name": "Loading...", "header": 0, "nrows": 50, "na_values": ["#N/A", "#N/A N/A", "#NA", "-NA", "#NULL!", "#NUM!", "#DIV/0!", "#VALUE!", "#REF!", "#NAME?", "#DIV/0", "#NUM", "#REF", "#VALUE"], "engine": "openpyxl", "parse_dates": true}}
Traceback (most recent call last):
  File "C:\Users\luria\PycharmProjects\QAStudiov3\data_integration\errors\error_handler.py", line 328, in safe_dataframe_operation
    return func(*args, **kwargs)
           ^^^^^^^^^^^^^^^^^^^^^
  File "C:\Users\luria\PycharmProjects\QAStudiov3\.venv\Lib\site-packages\pandas\io\excel\_base.py", line 508, in read_excel
    data = io.parse(
           ^^^^^^^^^
  File "C:\Users\luria\PycharmProjects\QAStudiov3\.venv\Lib\site-packages\pandas\io\excel\_base.py", line 1616, in parse
    return self._reader.parse(
           ^^^^^^^^^^^^^^^^^^^
  File "C:\Users\luria\PycharmProjects\QAStudiov3\.venv\Lib\site-packages\pandas\io\excel\_base.py", line 773, in parse
    sheet = self.get_sheet_by_name(asheetname)
            ^^^^^^^^^^^^^^^^^^^^^^^^^^^^^^^^^^
  File "C:\Users\luria\PycharmProjects\QAStudiov3\.venv\Lib\site-packages\pandas\io\excel\_openpyxl.py", line 582, in get_sheet_by_name
    self.raise_if_bad_sheet_by_name(name)
  File "C:\Users\luria\PycharmProjects\QAStudiov3\.venv\Lib\site-packages\pandas\io\excel\_base.py", line 624, in raise_if_bad_sheet_by_name
    raise ValueError(f"Worksheet named '{name}' not found")
ValueError: Worksheet named 'Loading...' not found

During handling of the above exception, another exception occurred:

Traceback (most recent call last):
  File "C:\Users\luria\PycharmProjects\QAStudiov3\data_integration\connectors\excel_connector.py", line 195, in get_data
    df = retry_operation(
         ^^^^^^^^^^^^^^^^
  File "C:\Users\luria\PycharmProjects\QAStudiov3\data_integration\errors\error_handler.py", line 379, in retry_operation
    return func(*args, **kwargs)
           ^^^^^^^^^^^^^^^^^^^^^
  File "C:\Users\luria\PycharmProjects\QAStudiov3\data_integration\connectors\excel_connector.py", line 183, in load_excel
    return safe_dataframe_operation(
           ^^^^^^^^^^^^^^^^^^^^^^^^^
  File "C:\Users\luria\PycharmProjects\QAStudiov3\data_integration\errors\error_handler.py", line 344, in safe_dataframe_operation
    raise DataIntegrationError(error_msg, details)
data_integration.errors.error_handler.DataIntegrationError: Error executing read_excel: Worksheet named 'Loading...' not found - Details: {"function": "read_excel", "args": "('C:\\\\Users\\\\luria\\\\PycharmProjects\\\\AuditQAStudio2\\\\test_data\\\\audit_workpapers_2025Q2.xlsx',)", "kwargs": {"sheet_name": "Loading...", "header": 0, "nrows": 50, "na_values": ["#N/A", "#N/A N/A", "#NA", "-NA", "#NULL!", "#NUM!", "#DIV/0!", "#VALUE!", "#REF!", "#NAME?", "#DIV/0", "#NUM", "#REF", "#VALUE"], "engine": "openpyxl", "parse_dates": true}}
2025-05-22 20:55:25,082 - data_integration.io.importer - ERROR - Error previewing file C:\Users\luria\PycharmProjects\AuditQAStudio2\test_data\audit_workpapers_2025Q2.xlsx: Failed to load data from ExcelConnector: Error executing read_excel: Worksheet named 'Loading...' not found - Details: {"function": "read_excel", "args": "('C:\\\\Users\\\\luria\\\\PycharmProjects\\\\AuditQAStudio2\\\\test_data\\\\audit_workpapers_2025Q2.xlsx',)", "kwargs": {"sheet_name": "Loading...", "header": 0, "nrows": 50, "na_values": ["#N/A", "#N/A N/A", "#NA", "-NA", "#NULL!", "#NUM!", "#DIV/0!", "#VALUE!", "#REF!", "#NAME?", "#DIV/0", "#NUM", "#REF", "#VALUE"], "engine": "openpyxl", "parse_dates": true}} - Details: {"source_name": "ExcelConnector", "params": {"sheet_name": "Loading...", "header": 0, "nrows": 50, "na_values": ["#N/A", "#N/A N/A", "#NA", "-NA", "#NULL!", "#NUM!", "#DIV/0!", "#VALUE!", "#REF!", "#NAME?", "#DIV/0", "#NUM", "#REF", "#VALUE"], "engine": "openpyxl", "parse_dates": true}}
2025-05-22 20:55:25,082 - data_source_panel - ERROR - Error loading file preview: Failed to load data from ExcelConnector: Error executing read_excel: Worksheet named 'Loading...' not found - Details: {"function": "read_excel", "args": "('C:\\\\Users\\\\luria\\\\PycharmProjects\\\\AuditQAStudio2\\\\test_data\\\\audit_workpapers_2025Q2.xlsx',)", "kwargs": {"sheet_name": "Loading...", "header": 0, "nrows": 50, "na_values": ["#N/A", "#N/A N/A", "#NA", "-NA", "#NULL!", "#NUM!", "#DIV/0!", "#VALUE!", "#REF!", "#NAME?", "#DIV/0", "#NUM", "#REF", "#VALUE"], "engine": "openpyxl", "parse_dates": true}} - Details: {"source_name": "ExcelConnector", "params": {"sheet_name": "Loading...", "header": 0, "nrows": 50, "na_values": ["#N/A", "#N/A N/A", "#NA", "-NA", "#NULL!", "#NUM!", "#DIV/0!", "#VALUE!", "#REF!", "#NAME?", "#DIV/0", "#NUM", "#REF", "#VALUE"], "engine": "openpyxl", "parse_dates": true}}
2025-05-22 20:55:25,086 - data_source_panel - ERROR - Preview error: Error loading file preview: Failed to load data from ExcelConnector: Error executing read_excel: Worksheet named 'Loading...' not found - Details: {"function": "read_excel", "args": "('C:\\\\Users\\\\luria\\\\PycharmProjects\\\\AuditQAStudio2\\\\test_data\\\\audit_workpapers_2025Q2.xlsx',)", "kwargs": {"sheet_name": "Loading...", "header": 0, "nrows": 50, "na_values": ["#N/A", "#N/A N/A", "#NA", "-NA", "#NULL!", "#NUM!", "#DIV/0!", "#VALUE!", "#REF!", "#NAME?", "#DIV/0", "#NUM", "#REF", "#VALUE"], "engine": "openpyxl", "parse_dates": true}} - Details: {"source_name": "ExcelConnector", "params": {"sheet_name": "Loading...", "header": 0, "nrows": 50, "na_values": ["#N/A", "#N/A N/A", "#NA", "-NA", "#NULL!", "#NUM!", "#DIV/0!", "#VALUE!", "#REF!", "#NAME?", "#DIV/0", "#NUM", "#REF", "#VALUE"], "engine": "openpyxl", "parse_dates": true}}
2025-05-22 20:55:25,108 - __main__ - INFO - Data preview loaded: 30 rows, 11 columns
2025-05-22 20:55:25,108 - data_source_panel - INFO - Preview loaded: 30 rows, 11 columns
2025-05-22 20:55:36,489 - __main__ - INFO - Application closing
2025-05-22 20:55:36,493 - error_handler - CRITICAL - TypeError: Object of type QByteArray is not JSON serializable
2025-05-22 20:55:37,379 - __main__ - ERROR - ERROR: Object of type QByteArray is not JSON serializable
2025-05-23 11:17:46,786 - error_handler - INFO - Error handler initialized
2025-05-23 11:17:46,787 - session_manager - WARNING - Error loading configuration: Expecting value: line 2 column 22 (char 23)
2025-05-23 11:17:46,787 - session_manager - INFO - Attempting to restore from backup...
2025-05-23 11:17:46,787 - session_manager - WARNING - Using default configuration
2025-05-23 11:17:46,788 - session_manager - INFO - Session manager initialized with config: session.json
2025-05-23 11:17:46,788 - data_source_registry - INFO - No existing registry found, starting with empty registry
2025-05-23 11:17:46,789 - data_source_registry - INFO - Data source registry initialized with 0 sources
2025-05-23 11:17:46,797 - ui.analytics_runner.data_source_registry - INFO - Loaded 0 data sources from registry
2025-05-23 11:17:46,797 - ui.analytics_runner.data_source_registry - INFO - Data source registry initialized with 0 sources
2025-05-23 11:17:46,854 - __main__ - INFO - Application state restored
2025-05-23 11:17:46,855 - __main__ - INFO - Backend systems initialized
2025-05-23 11:17:46,855 - __main__ - INFO - Analytics Runner application initialized successfully
2025-05-23 11:18:00,876 - __main__ - INFO - Data source changed: audit_workpapers_2025Q2.xlsx
2025-05-23 11:18:00,877 - __main__ - INFO - Data source validation: File appears valid
2025-05-23 11:18:01,730 - data_integration.connectors.excel_connector - ERROR - Error loading Excel file C:/Users/luria/PycharmProjects/AuditQAStudio2/test_data/audit_workpapers_2025Q2.xlsx: Error executing read_excel: Worksheet named 'Loading...' not found - Details: {"function": "read_excel", "args": "('C:/Users/luria/PycharmProjects/AuditQAStudio2/test_data/audit_workpapers_2025Q2.xlsx',)", "kwargs": {"sheet_name": "Loading...", "header": 0, "nrows": 50, "na_values": ["#N/A", "#N/A N/A", "#NA", "-NA", "#NULL!", "#NUM!", "#DIV/0!", "#VALUE!", "#REF!", "#NAME?", "#DIV/0", "#NUM", "#REF", "#VALUE"], "engine": "openpyxl", "parse_dates": true}}
2025-05-23 11:18:01,731 - data_integration.errors.error_handler - ERROR - Failed to load data from ExcelConnector: Error executing read_excel: Worksheet named 'Loading...' not found - Details: {"function": "read_excel", "args": "('C:/Users/luria/PycharmProjects/AuditQAStudio2/test_data/audit_workpapers_2025Q2.xlsx',)", "kwargs": {"sheet_name": "Loading...", "header": 0, "nrows": 50, "na_values": ["#N/A", "#N/A N/A", "#NA", "-NA", "#NULL!", "#NUM!", "#DIV/0!", "#VALUE!", "#REF!", "#NAME?", "#DIV/0", "#NUM", "#REF", "#VALUE"], "engine": "openpyxl", "parse_dates": true}} - Details: {"source_name": "ExcelConnector", "params": {"sheet_name": "Loading...", "header": 0, "nrows": 50, "na_values": ["#N/A", "#N/A N/A", "#NA", "-NA", "#NULL!", "#NUM!", "#DIV/0!", "#VALUE!", "#REF!", "#NAME?", "#DIV/0", "#NUM", "#REF", "#VALUE"], "engine": "openpyxl", "parse_dates": true}}
Traceback (most recent call last):
  File "C:\Users\luria\PycharmProjects\QAStudiov3\data_integration\errors\error_handler.py", line 328, in safe_dataframe_operation
    return func(*args, **kwargs)
           ^^^^^^^^^^^^^^^^^^^^^
  File "C:\Users\luria\PycharmProjects\QAStudiov3\.venv\Lib\site-packages\pandas\io\excel\_base.py", line 508, in read_excel
    data = io.parse(
           ^^^^^^^^^
  File "C:\Users\luria\PycharmProjects\QAStudiov3\.venv\Lib\site-packages\pandas\io\excel\_base.py", line 1616, in parse
    return self._reader.parse(
           ^^^^^^^^^^^^^^^^^^^
  File "C:\Users\luria\PycharmProjects\QAStudiov3\.venv\Lib\site-packages\pandas\io\excel\_base.py", line 773, in parse
    sheet = self.get_sheet_by_name(asheetname)
            ^^^^^^^^^^^^^^^^^^^^^^^^^^^^^^^^^^
  File "C:\Users\luria\PycharmProjects\QAStudiov3\.venv\Lib\site-packages\pandas\io\excel\_openpyxl.py", line 582, in get_sheet_by_name
    self.raise_if_bad_sheet_by_name(name)
  File "C:\Users\luria\PycharmProjects\QAStudiov3\.venv\Lib\site-packages\pandas\io\excel\_base.py", line 624, in raise_if_bad_sheet_by_name
    raise ValueError(f"Worksheet named '{name}' not found")
ValueError: Worksheet named 'Loading...' not found

During handling of the above exception, another exception occurred:

Traceback (most recent call last):
  File "C:\Users\luria\PycharmProjects\QAStudiov3\data_integration\connectors\excel_connector.py", line 195, in get_data
    df = retry_operation(
         ^^^^^^^^^^^^^^^^
  File "C:\Users\luria\PycharmProjects\QAStudiov3\data_integration\errors\error_handler.py", line 379, in retry_operation
    return func(*args, **kwargs)
           ^^^^^^^^^^^^^^^^^^^^^
  File "C:\Users\luria\PycharmProjects\QAStudiov3\data_integration\connectors\excel_connector.py", line 183, in load_excel
    return safe_dataframe_operation(
           ^^^^^^^^^^^^^^^^^^^^^^^^^
  File "C:\Users\luria\PycharmProjects\QAStudiov3\data_integration\errors\error_handler.py", line 344, in safe_dataframe_operation
    raise DataIntegrationError(error_msg, details)
data_integration.errors.error_handler.DataIntegrationError: Error executing read_excel: Worksheet named 'Loading...' not found - Details: {"function": "read_excel", "args": "('C:/Users/luria/PycharmProjects/AuditQAStudio2/test_data/audit_workpapers_2025Q2.xlsx',)", "kwargs": {"sheet_name": "Loading...", "header": 0, "nrows": 50, "na_values": ["#N/A", "#N/A N/A", "#NA", "-NA", "#NULL!", "#NUM!", "#DIV/0!", "#VALUE!", "#REF!", "#NAME?", "#DIV/0", "#NUM", "#REF", "#VALUE"], "engine": "openpyxl", "parse_dates": true}}
2025-05-23 11:18:01,736 - data_integration.io.importer - ERROR - Error previewing file C:/Users/luria/PycharmProjects/AuditQAStudio2/test_data/audit_workpapers_2025Q2.xlsx: Failed to load data from ExcelConnector: Error executing read_excel: Worksheet named 'Loading...' not found - Details: {"function": "read_excel", "args": "('C:/Users/luria/PycharmProjects/AuditQAStudio2/test_data/audit_workpapers_2025Q2.xlsx',)", "kwargs": {"sheet_name": "Loading...", "header": 0, "nrows": 50, "na_values": ["#N/A", "#N/A N/A", "#NA", "-NA", "#NULL!", "#NUM!", "#DIV/0!", "#VALUE!", "#REF!", "#NAME?", "#DIV/0", "#NUM", "#REF", "#VALUE"], "engine": "openpyxl", "parse_dates": true}} - Details: {"source_name": "ExcelConnector", "params": {"sheet_name": "Loading...", "header": 0, "nrows": 50, "na_values": ["#N/A", "#N/A N/A", "#NA", "-NA", "#NULL!", "#NUM!", "#DIV/0!", "#VALUE!", "#REF!", "#NAME?", "#DIV/0", "#NUM", "#REF", "#VALUE"], "engine": "openpyxl", "parse_dates": true}}
2025-05-23 11:18:01,736 - data_source_panel - ERROR - Error loading file preview: Failed to load data from ExcelConnector: Error executing read_excel: Worksheet named 'Loading...' not found - Details: {"function": "read_excel", "args": "('C:/Users/luria/PycharmProjects/AuditQAStudio2/test_data/audit_workpapers_2025Q2.xlsx',)", "kwargs": {"sheet_name": "Loading...", "header": 0, "nrows": 50, "na_values": ["#N/A", "#N/A N/A", "#NA", "-NA", "#NULL!", "#NUM!", "#DIV/0!", "#VALUE!", "#REF!", "#NAME?", "#DIV/0", "#NUM", "#REF", "#VALUE"], "engine": "openpyxl", "parse_dates": true}} - Details: {"source_name": "ExcelConnector", "params": {"sheet_name": "Loading...", "header": 0, "nrows": 50, "na_values": ["#N/A", "#N/A N/A", "#NA", "-NA", "#NULL!", "#NUM!", "#DIV/0!", "#VALUE!", "#REF!", "#NAME?", "#DIV/0", "#NUM", "#REF", "#VALUE"], "engine": "openpyxl", "parse_dates": true}}
2025-05-23 11:18:01,758 - data_source_panel - ERROR - Preview error: Error loading file preview: Failed to load data from ExcelConnector: Error executing read_excel: Worksheet named 'Loading...' not found - Details: {"function": "read_excel", "args": "('C:/Users/luria/PycharmProjects/AuditQAStudio2/test_data/audit_workpapers_2025Q2.xlsx',)", "kwargs": {"sheet_name": "Loading...", "header": 0, "nrows": 50, "na_values": ["#N/A", "#N/A N/A", "#NA", "-NA", "#NULL!", "#NUM!", "#DIV/0!", "#VALUE!", "#REF!", "#NAME?", "#DIV/0", "#NUM", "#REF", "#VALUE"], "engine": "openpyxl", "parse_dates": true}} - Details: {"source_name": "ExcelConnector", "params": {"sheet_name": "Loading...", "header": 0, "nrows": 50, "na_values": ["#N/A", "#N/A N/A", "#NA", "-NA", "#NULL!", "#NUM!", "#DIV/0!", "#VALUE!", "#REF!", "#NAME?", "#DIV/0", "#NUM", "#REF", "#VALUE"], "engine": "openpyxl", "parse_dates": true}}
2025-05-23 11:18:02,263 - pre_validation_widget - INFO - Started pre-validation for generic data
2025-05-23 11:18:02,264 - __main__ - INFO - Data preview loaded: 30 rows, 11 columns
2025-05-23 11:18:02,264 - data_source_panel - INFO - Preview loaded: 30 rows, 11 columns
2025-05-23 11:18:02,298 - data_source_panel - INFO - Pre-validation status: Valid - All validation checks passed
2025-05-23 11:18:02,298 - __main__ - INFO - Data source validation: Pre-validation: All validation checks passed
2025-05-23 11:18:02,298 - pre_validation_widget - INFO - Pre-validation complete: passed - 2/2 rules passed
2025-05-23 11:18:25,623 - data_source_registry - INFO - Registered data source: audit_workpapers_2025Q2_Workpapers (6eb7188a-6e90-40d9-9efe-34c68db4f27b)
2025-05-23 11:18:26,841 - data_source_panel - INFO - Data source saved with ID: 6eb7188a-6e90-40d9-9efe-34c68db4f27b
2025-05-23 11:18:26,846 - save_data_source_dialog - INFO - Data source saved successfully: audit_workpapers_2025Q2_Workpapers (6eb7188a-6e90-40d9-9efe-34c68db4f27b)
2025-05-23 11:18:28,468 - __main__ - INFO - Data source changed: 
2025-05-23 11:18:58,207 - __main__ - INFO - Application closing
2025-05-23 11:18:58,209 - error_handler - CRITICAL - TypeError: Object of type QByteArray is not JSON serializable
2025-05-23 11:18:59,233 - __main__ - ERROR - ERROR: Object of type QByteArray is not JSON serializable
2025-05-23 11:20:38,192 - error_handler - INFO - Error handler initialized
2025-05-23 11:20:38,193 - session_manager - WARNING - Error loading configuration: Expecting value: line 2 column 22 (char 23)
2025-05-23 11:20:38,193 - session_manager - INFO - Attempting to restore from backup...
2025-05-23 11:20:38,193 - session_manager - INFO - Configuration restored from backup: session.backup1
2025-05-23 11:20:38,193 - session_manager - INFO - Session manager initialized with config: session.json
2025-05-23 11:20:38,193 - data_source_registry - INFO - Loaded 1 data sources from registry
2025-05-23 11:20:38,193 - data_source_registry - INFO - Data source registry initialized with 1 sources
2025-05-23 11:20:38,195 - ui.analytics_runner.data_source_registry - INFO - Loaded 1 data sources from registry
2025-05-23 11:20:38,195 - ui.analytics_runner.data_source_registry - INFO - Data source registry initialized with 1 sources
2025-05-23 11:20:38,280 - __main__ - INFO - Application state restored
2025-05-23 11:20:38,280 - __main__ - INFO - Backend systems initialized
2025-05-23 11:20:38,280 - __main__ - INFO - Analytics Runner application initialized successfully
2025-05-23 11:20:44,051 - __main__ - INFO - Loading data source: audit_workpapers_2025Q2.xlsx
2025-05-23 11:20:44,055 - __main__ - INFO - Loaded saved data source: audit_workpapers_2025Q2_Workpapers
2025-05-23 11:20:50,100 - __main__ - INFO - Loading data source: audit_workpapers_2025Q2.xlsx
2025-05-23 11:20:50,103 - __main__ - INFO - Loaded saved data source: audit_workpapers_2025Q2_Workpapers
2025-05-23 11:25:33,125 - __main__ - INFO - Application closing
2025-05-23 11:25:33,129 - error_handler - CRITICAL - TypeError: Object of type QByteArray is not JSON serializable
2025-05-23 11:25:35,009 - __main__ - ERROR - ERROR: Object of type QByteArray is not JSON serializable
2025-05-23 11:33:00,424 - error_handler - INFO - Error handler initialized
2025-05-23 11:33:00,425 - session_manager - WARNING - Error loading configuration: Expecting value: line 2 column 22 (char 23)
2025-05-23 11:33:00,425 - session_manager - INFO - Attempting to restore from backup...
2025-05-23 11:33:00,425 - session_manager - INFO - Configuration restored from backup: session.backup1
2025-05-23 11:33:00,425 - session_manager - INFO - Session manager initialized with config: session.json
2025-05-23 11:33:00,425 - data_source_registry - INFO - Loaded 1 data sources from registry
2025-05-23 11:33:00,426 - data_source_registry - INFO - Data source registry initialized with 1 sources
2025-05-23 11:33:00,427 - ui.analytics_runner.data_source_registry - INFO - Loaded 1 data sources from registry
2025-05-23 11:33:00,427 - ui.analytics_runner.data_source_registry - INFO - Data source registry initialized with 1 sources
2025-05-23 11:33:00,472 - __main__ - INFO - Application state restored
2025-05-23 11:33:00,472 - __main__ - INFO - Backend systems initialized
2025-05-23 11:33:00,472 - __main__ - INFO - Analytics Runner application initialized successfully
2025-05-23 11:33:04,027 - __main__ - INFO - Loading saved data source: audit_workpapers_2025Q2_Workpapers
2025-05-23 11:33:04,027 - __main__ - WARNING - Enhanced loading failed, using basic method: 'DataSourcePanel' object has no attribute 'load_saved_data_source'
2025-05-23 11:33:04,034 - __main__ - INFO - Data source changed: audit_workpapers_2025Q2.xlsx
2025-05-23 11:33:04,036 - __main__ - INFO - Data source validation: File appears valid
2025-05-23 11:33:04,045 - __main__ - INFO - Successfully loaded saved data source: audit_workpapers_2025Q2_Workpapers
2025-05-23 11:33:04,752 - data_integration.connectors.excel_connector - ERROR - Error loading Excel file C:\Users\luria\PycharmProjects\AuditQAStudio2\test_data\audit_workpapers_2025Q2.xlsx: Error executing read_excel: Worksheet named 'Loading...' not found - Details: {"function": "read_excel", "args": "('C:\\\\Users\\\\luria\\\\PycharmProjects\\\\AuditQAStudio2\\\\test_data\\\\audit_workpapers_2025Q2.xlsx',)", "kwargs": {"sheet_name": "Loading...", "header": 0, "nrows": 50, "na_values": ["#N/A", "#N/A N/A", "#NA", "-NA", "#NULL!", "#NUM!", "#DIV/0!", "#VALUE!", "#REF!", "#NAME?", "#DIV/0", "#NUM", "#REF", "#VALUE"], "engine": "openpyxl", "parse_dates": true}}
2025-05-23 11:33:04,753 - data_integration.errors.error_handler - ERROR - Failed to load data from ExcelConnector: Error executing read_excel: Worksheet named 'Loading...' not found - Details: {"function": "read_excel", "args": "('C:\\\\Users\\\\luria\\\\PycharmProjects\\\\AuditQAStudio2\\\\test_data\\\\audit_workpapers_2025Q2.xlsx',)", "kwargs": {"sheet_name": "Loading...", "header": 0, "nrows": 50, "na_values": ["#N/A", "#N/A N/A", "#NA", "-NA", "#NULL!", "#NUM!", "#DIV/0!", "#VALUE!", "#REF!", "#NAME?", "#DIV/0", "#NUM", "#REF", "#VALUE"], "engine": "openpyxl", "parse_dates": true}} - Details: {"source_name": "ExcelConnector", "params": {"sheet_name": "Loading...", "header": 0, "nrows": 50, "na_values": ["#N/A", "#N/A N/A", "#NA", "-NA", "#NULL!", "#NUM!", "#DIV/0!", "#VALUE!", "#REF!", "#NAME?", "#DIV/0", "#NUM", "#REF", "#VALUE"], "engine": "openpyxl", "parse_dates": true}}
Traceback (most recent call last):
  File "C:\Users\luria\PycharmProjects\QAStudiov3\data_integration\errors\error_handler.py", line 328, in safe_dataframe_operation
    return func(*args, **kwargs)
           ^^^^^^^^^^^^^^^^^^^^^
  File "C:\Users\luria\PycharmProjects\QAStudiov3\.venv\Lib\site-packages\pandas\io\excel\_base.py", line 508, in read_excel
    data = io.parse(
           ^^^^^^^^^
  File "C:\Users\luria\PycharmProjects\QAStudiov3\.venv\Lib\site-packages\pandas\io\excel\_base.py", line 1616, in parse
    return self._reader.parse(
           ^^^^^^^^^^^^^^^^^^^
  File "C:\Users\luria\PycharmProjects\QAStudiov3\.venv\Lib\site-packages\pandas\io\excel\_base.py", line 773, in parse
    sheet = self.get_sheet_by_name(asheetname)
            ^^^^^^^^^^^^^^^^^^^^^^^^^^^^^^^^^^
  File "C:\Users\luria\PycharmProjects\QAStudiov3\.venv\Lib\site-packages\pandas\io\excel\_openpyxl.py", line 582, in get_sheet_by_name
    self.raise_if_bad_sheet_by_name(name)
  File "C:\Users\luria\PycharmProjects\QAStudiov3\.venv\Lib\site-packages\pandas\io\excel\_base.py", line 624, in raise_if_bad_sheet_by_name
    raise ValueError(f"Worksheet named '{name}' not found")
ValueError: Worksheet named 'Loading...' not found

During handling of the above exception, another exception occurred:

Traceback (most recent call last):
  File "C:\Users\luria\PycharmProjects\QAStudiov3\data_integration\connectors\excel_connector.py", line 195, in get_data
    df = retry_operation(
         ^^^^^^^^^^^^^^^^
  File "C:\Users\luria\PycharmProjects\QAStudiov3\data_integration\errors\error_handler.py", line 379, in retry_operation
    return func(*args, **kwargs)
           ^^^^^^^^^^^^^^^^^^^^^
  File "C:\Users\luria\PycharmProjects\QAStudiov3\data_integration\connectors\excel_connector.py", line 183, in load_excel
    return safe_dataframe_operation(
           ^^^^^^^^^^^^^^^^^^^^^^^^^
  File "C:\Users\luria\PycharmProjects\QAStudiov3\data_integration\errors\error_handler.py", line 344, in safe_dataframe_operation
    raise DataIntegrationError(error_msg, details)
data_integration.errors.error_handler.DataIntegrationError: Error executing read_excel: Worksheet named 'Loading...' not found - Details: {"function": "read_excel", "args": "('C:\\\\Users\\\\luria\\\\PycharmProjects\\\\AuditQAStudio2\\\\test_data\\\\audit_workpapers_2025Q2.xlsx',)", "kwargs": {"sheet_name": "Loading...", "header": 0, "nrows": 50, "na_values": ["#N/A", "#N/A N/A", "#NA", "-NA", "#NULL!", "#NUM!", "#DIV/0!", "#VALUE!", "#REF!", "#NAME?", "#DIV/0", "#NUM", "#REF", "#VALUE"], "engine": "openpyxl", "parse_dates": true}}
2025-05-23 11:33:04,757 - data_integration.io.importer - ERROR - Error previewing file C:\Users\luria\PycharmProjects\AuditQAStudio2\test_data\audit_workpapers_2025Q2.xlsx: Failed to load data from ExcelConnector: Error executing read_excel: Worksheet named 'Loading...' not found - Details: {"function": "read_excel", "args": "('C:\\\\Users\\\\luria\\\\PycharmProjects\\\\AuditQAStudio2\\\\test_data\\\\audit_workpapers_2025Q2.xlsx',)", "kwargs": {"sheet_name": "Loading...", "header": 0, "nrows": 50, "na_values": ["#N/A", "#N/A N/A", "#NA", "-NA", "#NULL!", "#NUM!", "#DIV/0!", "#VALUE!", "#REF!", "#NAME?", "#DIV/0", "#NUM", "#REF", "#VALUE"], "engine": "openpyxl", "parse_dates": true}} - Details: {"source_name": "ExcelConnector", "params": {"sheet_name": "Loading...", "header": 0, "nrows": 50, "na_values": ["#N/A", "#N/A N/A", "#NA", "-NA", "#NULL!", "#NUM!", "#DIV/0!", "#VALUE!", "#REF!", "#NAME?", "#DIV/0", "#NUM", "#REF", "#VALUE"], "engine": "openpyxl", "parse_dates": true}}
2025-05-23 11:33:04,757 - data_source_panel - ERROR - Error loading file preview: Failed to load data from ExcelConnector: Error executing read_excel: Worksheet named 'Loading...' not found - Details: {"function": "read_excel", "args": "('C:\\\\Users\\\\luria\\\\PycharmProjects\\\\AuditQAStudio2\\\\test_data\\\\audit_workpapers_2025Q2.xlsx',)", "kwargs": {"sheet_name": "Loading...", "header": 0, "nrows": 50, "na_values": ["#N/A", "#N/A N/A", "#NA", "-NA", "#NULL!", "#NUM!", "#DIV/0!", "#VALUE!", "#REF!", "#NAME?", "#DIV/0", "#NUM", "#REF", "#VALUE"], "engine": "openpyxl", "parse_dates": true}} - Details: {"source_name": "ExcelConnector", "params": {"sheet_name": "Loading...", "header": 0, "nrows": 50, "na_values": ["#N/A", "#N/A N/A", "#NA", "-NA", "#NULL!", "#NUM!", "#DIV/0!", "#VALUE!", "#REF!", "#NAME?", "#DIV/0", "#NUM", "#REF", "#VALUE"], "engine": "openpyxl", "parse_dates": true}}
2025-05-23 11:33:04,778 - data_source_panel - ERROR - Preview error: Error loading file preview: Failed to load data from ExcelConnector: Error executing read_excel: Worksheet named 'Loading...' not found - Details: {"function": "read_excel", "args": "('C:\\\\Users\\\\luria\\\\PycharmProjects\\\\AuditQAStudio2\\\\test_data\\\\audit_workpapers_2025Q2.xlsx',)", "kwargs": {"sheet_name": "Loading...", "header": 0, "nrows": 50, "na_values": ["#N/A", "#N/A N/A", "#NA", "-NA", "#NULL!", "#NUM!", "#DIV/0!", "#VALUE!", "#REF!", "#NAME?", "#DIV/0", "#NUM", "#REF", "#VALUE"], "engine": "openpyxl", "parse_dates": true}} - Details: {"source_name": "ExcelConnector", "params": {"sheet_name": "Loading...", "header": 0, "nrows": 50, "na_values": ["#N/A", "#N/A N/A", "#NA", "-NA", "#NULL!", "#NUM!", "#DIV/0!", "#VALUE!", "#REF!", "#NAME?", "#DIV/0", "#NUM", "#REF", "#VALUE"], "engine": "openpyxl", "parse_dates": true}}
2025-05-23 11:33:05,284 - pre_validation_widget - INFO - Started pre-validation for generic data
2025-05-23 11:33:05,285 - __main__ - INFO - Data preview loaded: 30 rows, 11 columns
2025-05-23 11:33:05,285 - data_source_panel - INFO - Preview loaded: 30 rows, 11 columns
2025-05-23 11:33:05,307 - data_source_panel - INFO - Pre-validation status: Valid - All validation checks passed
2025-05-23 11:33:05,307 - __main__ - INFO - Data source validation: Pre-validation: All validation checks passed
2025-05-23 11:33:05,307 - pre_validation_widget - INFO - Pre-validation complete: passed - 2/2 rules passed
2025-05-23 11:33:32,964 - __main__ - INFO - Application closing
2025-05-23 11:33:32,967 - error_handler - CRITICAL - TypeError: Object of type QByteArray is not JSON serializable
2025-05-23 11:33:34,156 - __main__ - ERROR - ERROR: Object of type QByteArray is not JSON serializable
2025-05-23 11:35:19,370 - error_handler - INFO - Error handler initialized
2025-05-23 11:35:19,370 - session_manager - WARNING - Error loading configuration: Expecting value: line 2 column 22 (char 23)
2025-05-23 11:35:19,370 - session_manager - INFO - Attempting to restore from backup...
2025-05-23 11:35:19,371 - session_manager - INFO - Configuration restored from backup: session.backup1
2025-05-23 11:35:19,371 - session_manager - INFO - Session manager initialized with config: session.json
2025-05-23 11:35:19,371 - data_source_registry - INFO - Loaded 1 data sources from registry
2025-05-23 11:35:19,371 - data_source_registry - INFO - Data source registry initialized with 1 sources
2025-05-23 11:35:19,374 - ui.analytics_runner.data_source_registry - INFO - Loaded 1 data sources from registry
2025-05-23 11:35:19,374 - ui.analytics_runner.data_source_registry - INFO - Data source registry initialized with 1 sources
2025-05-23 11:35:19,454 - __main__ - INFO - Application state restored
2025-05-23 11:35:19,454 - __main__ - INFO - Backend systems initialized
2025-05-23 11:35:19,455 - __main__ - INFO - Analytics Runner application initialized successfully
2025-05-23 11:35:21,387 - __main__ - INFO - Application closing
2025-05-23 11:35:21,389 - error_handler - CRITICAL - TypeError: Object of type QByteArray is not JSON serializable
2025-05-23 11:35:34,868 - __main__ - ERROR - ERROR: Object of type QByteArray is not JSON serializable
2025-05-23 11:35:42,436 - error_handler - INFO - Error handler initialized
2025-05-23 11:35:42,436 - session_manager - WARNING - Error loading configuration: Expecting value: line 2 column 22 (char 23)
2025-05-23 11:35:42,436 - session_manager - INFO - Attempting to restore from backup...
2025-05-23 11:35:42,436 - session_manager - WARNING - Backup file session.backup1 is corrupted: Expecting value: line 2 column 22 (char 23)
2025-05-23 11:35:42,436 - session_manager - INFO - Configuration restored from backup: session.backup2
2025-05-23 11:35:42,437 - session_manager - INFO - Session manager initialized with config: session.json
2025-05-23 11:35:42,437 - data_source_registry - INFO - Loaded 1 data sources from registry
2025-05-23 11:35:42,437 - data_source_registry - INFO - Data source registry initialized with 1 sources
2025-05-23 11:35:42,438 - ui.analytics_runner.data_source_registry - INFO - Loaded 1 data sources from registry
2025-05-23 11:35:42,438 - ui.analytics_runner.data_source_registry - INFO - Data source registry initialized with 1 sources
2025-05-23 11:35:42,477 - __main__ - INFO - Application state restored
2025-05-23 11:35:42,477 - __main__ - INFO - Backend systems initialized
2025-05-23 11:35:42,477 - __main__ - INFO - Analytics Runner application initialized successfully
2025-05-23 11:35:44,860 - __main__ - INFO - Application closing
2025-05-23 11:35:44,863 - error_handler - CRITICAL - TypeError: Object of type QByteArray is not JSON serializable
## 2025-05-23 11:36:22,243 - __main__ - ERROR - ERROR: Object of type QByteArray is not JSON serializable
