2025-05-22 20:57:51,812 - data_integration.connectors.excel_connector - ERROR - Error loading Excel file C:/Users/luria/PycharmProjects/AuditQAStudio2/test_data/audit_workpapers_2025Q2.xlsx: Error executing read_excel: Worksheet named 'Loading...' not found - Details: {"function": "read_excel", "args": "('C:/Users/luria/PycharmProjects/AuditQAStudio2/test_data/audit_workpapers_2025Q2.xlsx',)", "kwargs": {"sheet_name": "Loading...", "header": 0, "nrows": 50, "na_values": ["#N/A", "#N/A N/A", "#NA", "-NA", "#NULL!", "#NUM!", "#DIV/0!", "#VALUE!", "#REF!", "#NAME?", "#DIV/0", "#NUM", "#REF", "#VALUE"], "engine": "openpyxl", "parse_dates": true}}
2025-05-22 20:57:51,812 - data_integration.errors.error_handler - ERROR - Failed to load data from ExcelConnector: Error executing read_excel: Worksheet named 'Loading...' not found - Details: {"function": "read_excel", "args": "('C:/Users/luria/PycharmProjects/AuditQAStudio2/test_data/audit_workpapers_2025Q2.xlsx',)", "kwargs": {"sheet_name": "Loading...", "header": 0, "nrows": 50, "na_values": ["#N/A", "#N/A N/A", "#NA", "-NA", "#NULL!", "#NUM!", "#DIV/0!", "#VALUE!", "#REF!", "#NAME?", "#DIV/0", "#NUM", "#REF", "#VALUE"], "engine": "openpyxl", "parse_dates": true}} - Details: {"source_name": "ExcelConnector", "params": {"sheet_name": "Loading...", "header": 0, "nrows": 50, "na_values": ["#N/A", "#N/A N/A", "#NA", "-NA", "#NULL!", "#NUM!", "#DIV/0!", "#VALUE!", "#REF!", "#NAME?", "#DIV/0", "#NUM", "#REF", "#VALUE"], "engine": "openpyxl", "parse_dates": true}}
Traceback (most recent call last):
  File "C:\Users\luria\PycharmProjects\QAStudiov3\data_integration\errors\error_handler.py", line 328, in safe_dataframe_operation
    return func(*args, **kwargs)
           ^^^^^^^^^^^^^^^^^^^^^
  File "C:\Users\luria\PycharmProjects\QAStudiov3\.venv\Lib\site-packages\pandas\io\excel\_base.py", line 508, in read_excel
    data = io.parse(
           ^^^^^^^^^
  File "C:\Users\luria\PycharmProjects\QAStudiov3\.venv\Lib\site-packages\pandas\io\excel\_base.py", line 1616, in parse
    return self._reader.parse(
           ^^^^^^^^^^^^^^^^^^^
  File "C:\Users\luria\PycharmProjects\QAStudiov3\.venv\Lib\site-packages\pandas\io\excel\_base.py", line 773, in parse
    sheet = self.get_sheet_by_name(asheetname)
            ^^^^^^^^^^^^^^^^^^^^^^^^^^^^^^^^^^
  File "C:\Users\luria\PycharmProjects\QAStudiov3\.venv\Lib\site-packages\pandas\io\excel\_openpyxl.py", line 582, in get_sheet_by_name
    self.raise_if_bad_sheet_by_name(name)
  File "C:\Users\luria\PycharmProjects\QAStudiov3\.venv\Lib\site-packages\pandas\io\excel\_base.py", line 624, in raise_if_bad_sheet_by_name
    raise ValueError(f"Worksheet named '{name}' not found")
ValueError: Worksheet named 'Loading...' not found

During handling of the above exception, another exception occurred:

Traceback (most recent call last):
  File "C:\Users\luria\PycharmProjects\QAStudiov3\data_integration\connectors\excel_connector.py", line 195, in get_data
    df = retry_operation(
         ^^^^^^^^^^^^^^^^
  File "C:\Users\luria\PycharmProjects\QAStudiov3\data_integration\errors\error_handler.py", line 379, in retry_operation
    return func(*args, **kwargs)
           ^^^^^^^^^^^^^^^^^^^^^
  File "C:\Users\luria\PycharmProjects\QAStudiov3\data_integration\connectors\excel_connector.py", line 183, in load_excel
    return safe_dataframe_operation(
           ^^^^^^^^^^^^^^^^^^^^^^^^^
  File "C:\Users\luria\PycharmProjects\QAStudiov3\data_integration\errors\error_handler.py", line 344, in safe_dataframe_operation
    raise DataIntegrationError(error_msg, details)
data_integration.errors.error_handler.DataIntegrationError: Error executing read_excel: Worksheet named 'Loading...' not found - Details: {"function": "read_excel", "args": "('C:/Users/luria/PycharmProjects/AuditQAStudio2/test_data/audit_workpapers_2025Q2.xlsx',)", "kwargs": {"sheet_name": "Loading...", "header": 0, "nrows": 50, "na_values": ["#N/A", "#N/A N/A", "#NA", "-NA", "#NULL!", "#NUM!", "#DIV/0!", "#VALUE!", "#REF!", "#NAME?", "#DIV/0", "#NUM", "#REF", "#VALUE"], "engine": "openpyxl", "parse_dates": true}}
2025-05-22 20:57:51,814 - data_integration.io.importer - ERROR - Error previewing file C:/Users/luria/PycharmProjects/AuditQAStudio2/test_data/audit_workpapers_2025Q2.xlsx: Failed to load data from ExcelConnector: Error executing read_excel: Worksheet named 'Loading...' not found - Details: {"function": "read_excel", "args": "('C:/Users/luria/PycharmProjects/AuditQAStudio2/test_data/audit_workpapers_2025Q2.xlsx',)", "kwargs": {"sheet_name": "Loading...", "header": 0, "nrows": 50, "na_values": ["#N/A", "#N/A N/A", "#NA", "-NA", "#NULL!", "#NUM!", "#DIV/0!", "#VALUE!", "#REF!", "#NAME?", "#DIV/0", "#NUM", "#REF", "#VALUE"], "engine": "openpyxl", "parse_dates": true}} - Details: {"source_name": "ExcelConnector", "params": {"sheet_name": "Loading...", "header": 0, "nrows": 50, "na_values": ["#N/A", "#N/A N/A", "#NA", "-NA", "#NULL!", "#NUM!", "#DIV/0!", "#VALUE!", "#REF!", "#NAME?", "#DIV/0", "#NUM", "#REF", "#VALUE"], "engine": "openpyxl", "parse_dates": true}}
2025-05-22 20:57:51,814 - data_source_panel - ERROR - Error loading file preview: Failed to load data from ExcelConnector: Error executing read_excel: Worksheet named 'Loading...' not found - Details: {"function": "read_excel", "args": "('C:/Users/luria/PycharmProjects/AuditQAStudio2/test_data/audit_workpapers_2025Q2.xlsx',)", "kwargs": {"sheet_name": "Loading...", "header": 0, "nrows": 50, "na_values": ["#N/A", "#N/A N/A", "#NA", "-NA", "#NULL!", "#NUM!", "#DIV/0!", "#VALUE!", "#REF!", "#NAME?", "#DIV/0", "#NUM", "#REF", "#VALUE"], "engine": "openpyxl", "parse_dates": true}} - Details: {"source_name": "ExcelConnector", "params": {"sheet_name": "Loading...", "header": 0, "nrows": 50, "na_values": ["#N/A", "#N/A N/A", "#NA", "-NA", "#NULL!", "#NUM!", "#DIV/0!", "#VALUE!", "#REF!", "#NAME?", "#DIV/0", "#NUM", "#REF", "#VALUE"], "engine": "openpyxl", "parse_dates": true}}
2025-05-22 20:57:51,825 - data_source_panel - ERROR - Preview error: Error loading file preview: Failed to load data from ExcelConnector: Error executing read_excel: Worksheet named 'Loading...' not found - Details: {"function": "read_excel", "args": "('C:/Users/luria/PycharmProjects/AuditQAStudio2/test_data/audit_workpapers_2025Q2.xlsx',)", "kwargs": {"sheet_name": "Loading...", "header": 0, "nrows": 50, "na_values": ["#N/A", "#N/A N/A", "#NA", "-NA", "#NULL!", "#NUM!", "#DIV/0!", "#VALUE!", "#REF!", "#NAME?", "#DIV/0", "#NUM", "#REF", "#VALUE"], "engine": "openpyxl", "parse_dates": true}} - Details: {"source_name": "ExcelConnector", "params": {"sheet_name": "Loading...", "header": 0, "nrows": 50, "na_values": ["#N/A", "#N/A N/A", "#NA", "-NA", "#NULL!", "#NUM!", "#DIV/0!", "#VALUE!", "#REF!", "#NAME?", "#DIV/0", "#NUM", "#REF", "#VALUE"], "engine": "openpyxl", "parse_dates": true}}
2025-05-22 20:58:46,680 - error_handler - CRITICAL - TypeError: Object of type QByteArray is not JSON serializable
2025-05-22 20:58:47,567 - __main__ - ERROR - ERROR: Object of type QByteArray is not JSON serializable
2025-05-22 21:00:06,496 - data_integration.connectors.excel_connector - ERROR - Error loading Excel file C:\Users\luria\PycharmProjects\AuditQAStudio2\test_data\audit_workpapers_2025Q2.xlsx: Error executing read_excel: Worksheet named 'Loading...' not found - Details: {"function": "read_excel", "args": "('C:\\\\Users\\\\luria\\\\PycharmProjects\\\\AuditQAStudio2\\\\test_data\\\\audit_workpapers_2025Q2.xlsx',)", "kwargs": {"sheet_name": "Loading...", "header": 0, "nrows": 50, "na_values": ["#N/A", "#N/A N/A", "#NA", "-NA", "#NULL!", "#NUM!", "#DIV/0!", "#VALUE!", "#REF!", "#NAME?", "#DIV/0", "#NUM", "#REF", "#VALUE"], "engine": "openpyxl", "parse_dates": true}}
2025-05-22 21:00:06,496 - data_integration.errors.error_handler - ERROR - Failed to load data from ExcelConnector: Error executing read_excel: Worksheet named 'Loading...' not found - Details: {"function": "read_excel", "args": "('C:\\\\Users\\\\luria\\\\PycharmProjects\\\\AuditQAStudio2\\\\test_data\\\\audit_workpapers_2025Q2.xlsx',)", "kwargs": {"sheet_name": "Loading...", "header": 0, "nrows": 50, "na_values": ["#N/A", "#N/A N/A", "#NA", "-NA", "#NULL!", "#NUM!", "#DIV/0!", "#VALUE!", "#REF!", "#NAME?", "#DIV/0", "#NUM", "#REF", "#VALUE"], "engine": "openpyxl", "parse_dates": true}} - Details: {"source_name": "ExcelConnector", "params": {"sheet_name": "Loading...", "header": 0, "nrows": 50, "na_values": ["#N/A", "#N/A N/A", "#NA", "-NA", "#NULL!", "#NUM!", "#DIV/0!", "#VALUE!", "#REF!", "#NAME?", "#DIV/0", "#NUM", "#REF", "#VALUE"], "engine": "openpyxl", "parse_dates": true}}
Traceback (most recent call last):
  File "C:\Users\luria\PycharmProjects\QAStudiov3\data_integration\errors\error_handler.py", line 328, in safe_dataframe_operation
    return func(*args, **kwargs)
           ^^^^^^^^^^^^^^^^^^^^^
  File "C:\Users\luria\PycharmProjects\QAStudiov3\.venv\Lib\site-packages\pandas\io\excel\_base.py", line 508, in read_excel
    data = io.parse(
           ^^^^^^^^^
  File "C:\Users\luria\PycharmProjects\QAStudiov3\.venv\Lib\site-packages\pandas\io\excel\_base.py", line 1616, in parse
    return self._reader.parse(
           ^^^^^^^^^^^^^^^^^^^
  File "C:\Users\luria\PycharmProjects\QAStudiov3\.venv\Lib\site-packages\pandas\io\excel\_base.py", line 773, in parse
    sheet = self.get_sheet_by_name(asheetname)
            ^^^^^^^^^^^^^^^^^^^^^^^^^^^^^^^^^^
  File "C:\Users\luria\PycharmProjects\QAStudiov3\.venv\Lib\site-packages\pandas\io\excel\_openpyxl.py", line 582, in get_sheet_by_name
    self.raise_if_bad_sheet_by_name(name)
  File "C:\Users\luria\PycharmProjects\QAStudiov3\.venv\Lib\site-packages\pandas\io\excel\_base.py", line 624, in raise_if_bad_sheet_by_name
    raise ValueError(f"Worksheet named '{name}' not found")
ValueError: Worksheet named 'Loading...' not found

During handling of the above exception, another exception occurred:

Traceback (most recent call last):
  File "C:\Users\luria\PycharmProjects\QAStudiov3\data_integration\connectors\excel_connector.py", line 195, in get_data
    df = retry_operation(
         ^^^^^^^^^^^^^^^^
  File "C:\Users\luria\PycharmProjects\QAStudiov3\data_integration\errors\error_handler.py", line 379, in retry_operation
    return func(*args, **kwargs)
           ^^^^^^^^^^^^^^^^^^^^^
  File "C:\Users\luria\PycharmProjects\QAStudiov3\data_integration\connectors\excel_connector.py", line 183, in load_excel
    return safe_dataframe_operation(
           ^^^^^^^^^^^^^^^^^^^^^^^^^
  File "C:\Users\luria\PycharmProjects\QAStudiov3\data_integration\errors\error_handler.py", line 344, in safe_dataframe_operation
    raise DataIntegrationError(error_msg, details)
data_integration.errors.error_handler.DataIntegrationError: Error executing read_excel: Worksheet named 'Loading...' not found - Details: {"function": "read_excel", "args": "('C:\\\\Users\\\\luria\\\\PycharmProjects\\\\AuditQAStudio2\\\\test_data\\\\audit_workpapers_2025Q2.xlsx',)", "kwargs": {"sheet_name": "Loading...", "header": 0, "nrows": 50, "na_values": ["#N/A", "#N/A N/A", "#NA", "-NA", "#NULL!", "#NUM!", "#DIV/0!", "#VALUE!", "#REF!", "#NAME?", "#DIV/0", "#NUM", "#REF", "#VALUE"], "engine": "openpyxl", "parse_dates": true}}
2025-05-22 21:00:06,498 - data_integration.io.importer - ERROR - Error previewing file C:\Users\luria\PycharmProjects\AuditQAStudio2\test_data\audit_workpapers_2025Q2.xlsx: Failed to load data from ExcelConnector: Error executing read_excel: Worksheet named 'Loading...' not found - Details: {"function": "read_excel", "args": "('C:\\\\Users\\\\luria\\\\PycharmProjects\\\\AuditQAStudio2\\\\test_data\\\\audit_workpapers_2025Q2.xlsx',)", "kwargs": {"sheet_name": "Loading...", "header": 0, "nrows": 50, "na_values": ["#N/A", "#N/A N/A", "#NA", "-NA", "#NULL!", "#NUM!", "#DIV/0!", "#VALUE!", "#REF!", "#NAME?", "#DIV/0", "#NUM", "#REF", "#VALUE"], "engine": "openpyxl", "parse_dates": true}} - Details: {"source_name": "ExcelConnector", "params": {"sheet_name": "Loading...", "header": 0, "nrows": 50, "na_values": ["#N/A", "#N/A N/A", "#NA", "-NA", "#NULL!", "#NUM!", "#DIV/0!", "#VALUE!", "#REF!", "#NAME?", "#DIV/0", "#NUM", "#REF", "#VALUE"], "engine": "openpyxl", "parse_dates": true}}
2025-05-22 21:00:06,498 - data_source_panel - ERROR - Error loading file preview: Failed to load data from ExcelConnector: Error executing read_excel: Worksheet named 'Loading...' not found - Details: {"function": "read_excel", "args": "('C:\\\\Users\\\\luria\\\\PycharmProjects\\\\AuditQAStudio2\\\\test_data\\\\audit_workpapers_2025Q2.xlsx',)", "kwargs": {"sheet_name": "Loading...", "header": 0, "nrows": 50, "na_values": ["#N/A", "#N/A N/A", "#NA", "-NA", "#NULL!", "#NUM!", "#DIV/0!", "#VALUE!", "#REF!", "#NAME?", "#DIV/0", "#NUM", "#REF", "#VALUE"], "engine": "openpyxl", "parse_dates": true}} - Details: {"source_name": "ExcelConnector", "params": {"sheet_name": "Loading...", "header": 0, "nrows": 50, "na_values": ["#N/A", "#N/A N/A", "#NA", "-NA", "#NULL!", "#NUM!", "#DIV/0!", "#VALUE!", "#REF!", "#NAME?", "#DIV/0", "#NUM", "#REF", "#VALUE"], "engine": "openpyxl", "parse_dates": true}}
2025-05-22 21:00:06,507 - data_source_panel - ERROR - Preview error: Error loading file preview: Failed to load data from ExcelConnector: Error executing read_excel: Worksheet named 'Loading...' not found - Details: {"function": "read_excel", "args": "('C:\\\\Users\\\\luria\\\\PycharmProjects\\\\AuditQAStudio2\\\\test_data\\\\audit_workpapers_2025Q2.xlsx',)", "kwargs": {"sheet_name": "Loading...", "header": 0, "nrows": 50, "na_values": ["#N/A", "#N/A N/A", "#NA", "-NA", "#NULL!", "#NUM!", "#DIV/0!", "#VALUE!", "#REF!", "#NAME?", "#DIV/0", "#NUM", "#REF", "#VALUE"], "engine": "openpyxl", "parse_dates": true}} - Details: {"source_name": "ExcelConnector", "params": {"sheet_name": "Loading...", "header": 0, "nrows": 50, "na_values": ["#N/A", "#N/A N/A", "#NA", "-NA", "#NULL!", "#NUM!", "#DIV/0!", "#VALUE!", "#REF!", "#NAME?", "#DIV/0", "#NUM", "#REF", "#VALUE"], "engine": "openpyxl", "parse_dates": true}}
2025-05-22 21:01:18,317 - error_handler - CRITICAL - TypeError: Object of type QByteArray is not JSON serializable
2025-05-22 21:01:19,423 - __main__ - ERROR - ERROR: Object of type QByteArray is not JSON serializable
2025-05-22 21:01:23,912 - data_integration.connectors.excel_connector - ERROR - Error loading Excel file C:\Users\luria\PycharmProjects\AuditQAStudio2\test_data\audit_workpapers_2025Q2.xlsx: Error executing read_excel: Worksheet named 'Loading...' not found - Details: {"function": "read_excel", "args": "('C:\\\\Users\\\\luria\\\\PycharmProjects\\\\AuditQAStudio2\\\\test_data\\\\audit_workpapers_2025Q2.xlsx',)", "kwargs": {"sheet_name": "Loading...", "header": 0, "nrows": 50, "na_values": ["#N/A", "#N/A N/A", "#NA", "-NA", "#NULL!", "#NUM!", "#DIV/0!", "#VALUE!", "#REF!", "#NAME?", "#DIV/0", "#NUM", "#REF", "#VALUE"], "engine": "openpyxl", "parse_dates": true}}
2025-05-22 21:01:23,912 - data_integration.errors.error_handler - ERROR - Failed to load data from ExcelConnector: Error executing read_excel: Worksheet named 'Loading...' not found - Details: {"function": "read_excel", "args": "('C:\\\\Users\\\\luria\\\\PycharmProjects\\\\AuditQAStudio2\\\\test_data\\\\audit_workpapers_2025Q2.xlsx',)", "kwargs": {"sheet_name": "Loading...", "header": 0, "nrows": 50, "na_values": ["#N/A", "#N/A N/A", "#NA", "-NA", "#NULL!", "#NUM!", "#DIV/0!", "#VALUE!", "#REF!", "#NAME?", "#DIV/0", "#NUM", "#REF", "#VALUE"], "engine": "openpyxl", "parse_dates": true}} - Details: {"source_name": "ExcelConnector", "params": {"sheet_name": "Loading...", "header": 0, "nrows": 50, "na_values": ["#N/A", "#N/A N/A", "#NA", "-NA", "#NULL!", "#NUM!", "#DIV/0!", "#VALUE!", "#REF!", "#NAME?", "#DIV/0", "#NUM", "#REF", "#VALUE"], "engine": "openpyxl", "parse_dates": true}}
Traceback (most recent call last):
  File "C:\Users\luria\PycharmProjects\QAStudiov3\data_integration\errors\error_handler.py", line 328, in safe_dataframe_operation
    return func(*args, **kwargs)
           ^^^^^^^^^^^^^^^^^^^^^
  File "C:\Users\luria\PycharmProjects\QAStudiov3\.venv\Lib\site-packages\pandas\io\excel\_base.py", line 508, in read_excel
    data = io.parse(
           ^^^^^^^^^
  File "C:\Users\luria\PycharmProjects\QAStudiov3\.venv\Lib\site-packages\pandas\io\excel\_base.py", line 1616, in parse
    return self._reader.parse(
           ^^^^^^^^^^^^^^^^^^^
  File "C:\Users\luria\PycharmProjects\QAStudiov3\.venv\Lib\site-packages\pandas\io\excel\_base.py", line 773, in parse
    sheet = self.get_sheet_by_name(asheetname)
            ^^^^^^^^^^^^^^^^^^^^^^^^^^^^^^^^^^
  File "C:\Users\luria\PycharmProjects\QAStudiov3\.venv\Lib\site-packages\pandas\io\excel\_openpyxl.py", line 582, in get_sheet_by_name
    self.raise_if_bad_sheet_by_name(name)
  File "C:\Users\luria\PycharmProjects\QAStudiov3\.venv\Lib\site-packages\pandas\io\excel\_base.py", line 624, in raise_if_bad_sheet_by_name
    raise ValueError(f"Worksheet named '{name}' not found")
ValueError: Worksheet named 'Loading...' not found

During handling of the above exception, another exception occurred:

Traceback (most recent call last):
  File "C:\Users\luria\PycharmProjects\QAStudiov3\data_integration\connectors\excel_connector.py", line 195, in get_data
    df = retry_operation(
         ^^^^^^^^^^^^^^^^
  File "C:\Users\luria\PycharmProjects\QAStudiov3\data_integration\errors\error_handler.py", line 379, in retry_operation
    return func(*args, **kwargs)
           ^^^^^^^^^^^^^^^^^^^^^
  File "C:\Users\luria\PycharmProjects\QAStudiov3\data_integration\connectors\excel_connector.py", line 183, in load_excel
    return safe_dataframe_operation(
           ^^^^^^^^^^^^^^^^^^^^^^^^^
  File "C:\Users\luria\PycharmProjects\QAStudiov3\data_integration\errors\error_handler.py", line 344, in safe_dataframe_operation
    raise DataIntegrationError(error_msg, details)
data_integration.errors.error_handler.DataIntegrationError: Error executing read_excel: Worksheet named 'Loading...' not found - Details: {"function": "read_excel", "args": "('C:\\\\Users\\\\luria\\\\PycharmProjects\\\\AuditQAStudio2\\\\test_data\\\\audit_workpapers_2025Q2.xlsx',)", "kwargs": {"sheet_name": "Loading...", "header": 0, "nrows": 50, "na_values": ["#N/A", "#N/A N/A", "#NA", "-NA", "#NULL!", "#NUM!", "#DIV/0!", "#VALUE!", "#REF!", "#NAME?", "#DIV/0", "#NUM", "#REF", "#VALUE"], "engine": "openpyxl", "parse_dates": true}}
2025-05-22 21:01:23,914 - data_integration.io.importer - ERROR - Error previewing file C:\Users\luria\PycharmProjects\AuditQAStudio2\test_data\audit_workpapers_2025Q2.xlsx: Failed to load data from ExcelConnector: Error executing read_excel: Worksheet named 'Loading...' not found - Details: {"function": "read_excel", "args": "('C:\\\\Users\\\\luria\\\\PycharmProjects\\\\AuditQAStudio2\\\\test_data\\\\audit_workpapers_2025Q2.xlsx',)", "kwargs": {"sheet_name": "Loading...", "header": 0, "nrows": 50, "na_values": ["#N/A", "#N/A N/A", "#NA", "-NA", "#NULL!", "#NUM!", "#DIV/0!", "#VALUE!", "#REF!", "#NAME?", "#DIV/0", "#NUM", "#REF", "#VALUE"], "engine": "openpyxl", "parse_dates": true}} - Details: {"source_name": "ExcelConnector", "params": {"sheet_name": "Loading...", "header": 0, "nrows": 50, "na_values": ["#N/A", "#N/A N/A", "#NA", "-NA", "#NULL!", "#NUM!", "#DIV/0!", "#VALUE!", "#REF!", "#NAME?", "#DIV/0", "#NUM", "#REF", "#VALUE"], "engine": "openpyxl", "parse_dates": true}}
2025-05-22 21:01:23,914 - data_source_panel - ERROR - Error loading file preview: Failed to load data from ExcelConnector: Error executing read_excel: Worksheet named 'Loading...' not found - Details: {"function": "read_excel", "args": "('C:\\\\Users\\\\luria\\\\PycharmProjects\\\\AuditQAStudio2\\\\test_data\\\\audit_workpapers_2025Q2.xlsx',)", "kwargs": {"sheet_name": "Loading...", "header": 0, "nrows": 50, "na_values": ["#N/A", "#N/A N/A", "#NA", "-NA", "#NULL!", "#NUM!", "#DIV/0!", "#VALUE!", "#REF!", "#NAME?", "#DIV/0", "#NUM", "#REF", "#VALUE"], "engine": "openpyxl", "parse_dates": true}} - Details: {"source_name": "ExcelConnector", "params": {"sheet_name": "Loading...", "header": 0, "nrows": 50, "na_values": ["#N/A", "#N/A N/A", "#NA", "-NA", "#NULL!", "#NUM!", "#DIV/0!", "#VALUE!", "#REF!", "#NAME?", "#DIV/0", "#NUM", "#REF", "#VALUE"], "engine": "openpyxl", "parse_dates": true}}
2025-05-22 21:01:23,923 - data_source_panel - ERROR - Preview error: Error loading file preview: Failed to load data from ExcelConnector: Error executing read_excel: Worksheet named 'Loading...' not found - Details: {"function": "read_excel", "args": "('C:\\\\Users\\\\luria\\\\PycharmProjects\\\\AuditQAStudio2\\\\test_data\\\\audit_workpapers_2025Q2.xlsx',)", "kwargs": {"sheet_name": "Loading...", "header": 0, "nrows": 50, "na_values": ["#N/A", "#N/A N/A", "#NA", "-NA", "#NULL!", "#NUM!", "#DIV/0!", "#VALUE!", "#REF!", "#NAME?", "#DIV/0", "#NUM", "#REF", "#VALUE"], "engine": "openpyxl", "parse_dates": true}} - Details: {"source_name": "ExcelConnector", "params": {"sheet_name": "Loading...", "header": 0, "nrows": 50, "na_values": ["#N/A", "#N/A N/A", "#NA", "-NA", "#NULL!", "#NUM!", "#DIV/0!", "#VALUE!", "#REF!", "#NAME?", "#DIV/0", "#NUM", "#REF", "#VALUE"], "engine": "openpyxl", "parse_dates": true}}
2025-05-22 21:02:32,278 - error_handler - CRITICAL - TypeError: Object of type QByteArray is not JSON serializable
2025-05-22 21:02:33,368 - __main__ - ERROR - ERROR: Object of type QByteArray is not JSON serializable
2025-05-22 21:04:03,353 - error_handler - CRITICAL - TypeError: Object of type QByteArray is not JSON serializable
2025-05-22 21:04:04,359 - __main__ - ERROR - ERROR: Object of type QByteArray is not JSON serializable
2025-05-22 21:04:10,911 - data_integration.connectors.excel_connector - ERROR - Error loading Excel file C:\Users\luria\PycharmProjects\AuditQAStudio2\test_data\audit_workpapers_2025Q2.xlsx: Error executing read_excel: Worksheet named 'Loading...' not found - Details: {"function": "read_excel", "args": "('C:\\\\Users\\\\luria\\\\PycharmProjects\\\\AuditQAStudio2\\\\test_data\\\\audit_workpapers_2025Q2.xlsx',)", "kwargs": {"sheet_name": "Loading...", "header": 0, "nrows": 50, "na_values": ["#N/A", "#N/A N/A", "#NA", "-NA", "#NULL!", "#NUM!", "#DIV/0!", "#VALUE!", "#REF!", "#NAME?", "#DIV/0", "#NUM", "#REF", "#VALUE"], "engine": "openpyxl", "parse_dates": true}}
2025-05-22 21:04:10,911 - data_integration.errors.error_handler - ERROR - Failed to load data from ExcelConnector: Error executing read_excel: Worksheet named 'Loading...' not found - Details: {"function": "read_excel", "args": "('C:\\\\Users\\\\luria\\\\PycharmProjects\\\\AuditQAStudio2\\\\test_data\\\\audit_workpapers_2025Q2.xlsx',)", "kwargs": {"sheet_name": "Loading...", "header": 0, "nrows": 50, "na_values": ["#N/A", "#N/A N/A", "#NA", "-NA", "#NULL!", "#NUM!", "#DIV/0!", "#VALUE!", "#REF!", "#NAME?", "#DIV/0", "#NUM", "#REF", "#VALUE"], "engine": "openpyxl", "parse_dates": true}} - Details: {"source_name": "ExcelConnector", "params": {"sheet_name": "Loading...", "header": 0, "nrows": 50, "na_values": ["#N/A", "#N/A N/A", "#NA", "-NA", "#NULL!", "#NUM!", "#DIV/0!", "#VALUE!", "#REF!", "#NAME?", "#DIV/0", "#NUM", "#REF", "#VALUE"], "engine": "openpyxl", "parse_dates": true}}
Traceback (most recent call last):
  File "C:\Users\luria\PycharmProjects\QAStudiov3\data_integration\errors\error_handler.py", line 328, in safe_dataframe_operation
    return func(*args, **kwargs)
           ^^^^^^^^^^^^^^^^^^^^^
  File "C:\Users\luria\PycharmProjects\QAStudiov3\.venv\Lib\site-packages\pandas\io\excel\_base.py", line 508, in read_excel
    data = io.parse(
           ^^^^^^^^^
  File "C:\Users\luria\PycharmProjects\QAStudiov3\.venv\Lib\site-packages\pandas\io\excel\_base.py", line 1616, in parse
    return self._reader.parse(
           ^^^^^^^^^^^^^^^^^^^
  File "C:\Users\luria\PycharmProjects\QAStudiov3\.venv\Lib\site-packages\pandas\io\excel\_base.py", line 773, in parse
    sheet = self.get_sheet_by_name(asheetname)
            ^^^^^^^^^^^^^^^^^^^^^^^^^^^^^^^^^^
  File "C:\Users\luria\PycharmProjects\QAStudiov3\.venv\Lib\site-packages\pandas\io\excel\_openpyxl.py", line 582, in get_sheet_by_name
    self.raise_if_bad_sheet_by_name(name)
  File "C:\Users\luria\PycharmProjects\QAStudiov3\.venv\Lib\site-packages\pandas\io\excel\_base.py", line 624, in raise_if_bad_sheet_by_name
    raise ValueError(f"Worksheet named '{name}' not found")
ValueError: Worksheet named 'Loading...' not found

During handling of the above exception, another exception occurred:

Traceback (most recent call last):
  File "C:\Users\luria\PycharmProjects\QAStudiov3\data_integration\connectors\excel_connector.py", line 195, in get_data
    df = retry_operation(
         ^^^^^^^^^^^^^^^^
  File "C:\Users\luria\PycharmProjects\QAStudiov3\data_integration\errors\error_handler.py", line 379, in retry_operation
    return func(*args, **kwargs)
           ^^^^^^^^^^^^^^^^^^^^^
  File "C:\Users\luria\PycharmProjects\QAStudiov3\data_integration\connectors\excel_connector.py", line 183, in load_excel
    return safe_dataframe_operation(
           ^^^^^^^^^^^^^^^^^^^^^^^^^
  File "C:\Users\luria\PycharmProjects\QAStudiov3\data_integration\errors\error_handler.py", line 344, in safe_dataframe_operation
    raise DataIntegrationError(error_msg, details)
data_integration.errors.error_handler.DataIntegrationError: Error executing read_excel: Worksheet named 'Loading...' not found - Details: {"function": "read_excel", "args": "('C:\\\\Users\\\\luria\\\\PycharmProjects\\\\AuditQAStudio2\\\\test_data\\\\audit_workpapers_2025Q2.xlsx',)", "kwargs": {"sheet_name": "Loading...", "header": 0, "nrows": 50, "na_values": ["#N/A", "#N/A N/A", "#NA", "-NA", "#NULL!", "#NUM!", "#DIV/0!", "#VALUE!", "#REF!", "#NAME?", "#DIV/0", "#NUM", "#REF", "#VALUE"], "engine": "openpyxl", "parse_dates": true}}
2025-05-22 21:04:10,914 - data_integration.io.importer - ERROR - Error previewing file C:\Users\luria\PycharmProjects\AuditQAStudio2\test_data\audit_workpapers_2025Q2.xlsx: Failed to load data from ExcelConnector: Error executing read_excel: Worksheet named 'Loading...' not found - Details: {"function": "read_excel", "args": "('C:\\\\Users\\\\luria\\\\PycharmProjects\\\\AuditQAStudio2\\\\test_data\\\\audit_workpapers_2025Q2.xlsx',)", "kwargs": {"sheet_name": "Loading...", "header": 0, "nrows": 50, "na_values": ["#N/A", "#N/A N/A", "#NA", "-NA", "#NULL!", "#NUM!", "#DIV/0!", "#VALUE!", "#REF!", "#NAME?", "#DIV/0", "#NUM", "#REF", "#VALUE"], "engine": "openpyxl", "parse_dates": true}} - Details: {"source_name": "ExcelConnector", "params": {"sheet_name": "Loading...", "header": 0, "nrows": 50, "na_values": ["#N/A", "#N/A N/A", "#NA", "-NA", "#NULL!", "#NUM!", "#DIV/0!", "#VALUE!", "#REF!", "#NAME?", "#DIV/0", "#NUM", "#REF", "#VALUE"], "engine": "openpyxl", "parse_dates": true}}
2025-05-22 21:04:10,914 - data_source_panel - ERROR - Error loading file preview: Failed to load data from ExcelConnector: Error executing read_excel: Worksheet named 'Loading...' not found - Details: {"function": "read_excel", "args": "('C:\\\\Users\\\\luria\\\\PycharmProjects\\\\AuditQAStudio2\\\\test_data\\\\audit_workpapers_2025Q2.xlsx',)", "kwargs": {"sheet_name": "Loading...", "header": 0, "nrows": 50, "na_values": ["#N/A", "#N/A N/A", "#NA", "-NA", "#NULL!", "#NUM!", "#DIV/0!", "#VALUE!", "#REF!", "#NAME?", "#DIV/0", "#NUM", "#REF", "#VALUE"], "engine": "openpyxl", "parse_dates": true}} - Details: {"source_name": "ExcelConnector", "params": {"sheet_name": "Loading...", "header": 0, "nrows": 50, "na_values": ["#N/A", "#N/A N/A", "#NA", "-NA", "#NULL!", "#NUM!", "#DIV/0!", "#VALUE!", "#REF!", "#NAME?", "#DIV/0", "#NUM", "#REF", "#VALUE"], "engine": "openpyxl", "parse_dates": true}}
2025-05-22 21:04:10,920 - data_source_panel - ERROR - Preview error: Error loading file preview: Failed to load data from ExcelConnector: Error executing read_excel: Worksheet named 'Loading...' not found - Details: {"function": "read_excel", "args": "('C:\\\\Users\\\\luria\\\\PycharmProjects\\\\AuditQAStudio2\\\\test_data\\\\audit_workpapers_2025Q2.xlsx',)", "kwargs": {"sheet_name": "Loading...", "header": 0, "nrows": 50, "na_values": ["#N/A", "#N/A N/A", "#NA", "-NA", "#NULL!", "#NUM!", "#DIV/0!", "#VALUE!", "#REF!", "#NAME?", "#DIV/0", "#NUM", "#REF", "#VALUE"], "engine": "openpyxl", "parse_dates": true}} - Details: {"source_name": "ExcelConnector", "params": {"sheet_name": "Loading...", "header": 0, "nrows": 50, "na_values": ["#N/A", "#N/A N/A", "#NA", "-NA", "#NULL!", "#NUM!", "#DIV/0!", "#VALUE!", "#REF!", "#NAME?", "#DIV/0", "#NUM", "#REF", "#VALUE"], "engine": "openpyxl", "parse_dates": true}}
2025-05-22 21:04:10,955 - error_handler - CRITICAL - TypeError: QTableWidget.update() takes exactly one argument (0 given)
2025-05-22 21:04:12,135 - __main__ - ERROR - ERROR: QTableWidget.update() takes exactly one argument (0 given)
2025-05-22 21:05:41,787 - error_handler - CRITICAL - TypeError: Object of type QByteArray is not JSON serializable
2025-05-22 21:05:43,369 - __main__ - ERROR - ERROR: Object of type QByteArray is not JSON serializable
2025-05-22 21:06:41,613 - data_integration.connectors.excel_connector - ERROR - Error loading Excel file C:\Users\luria\PycharmProjects\AuditQAStudio2\test_data\audit_workpapers_2025Q2.xlsx: Error executing read_excel: Worksheet named 'Loading...' not found - Details: {"function": "read_excel", "args": "('C:\\\\Users\\\\luria\\\\PycharmProjects\\\\AuditQAStudio2\\\\test_data\\\\audit_workpapers_2025Q2.xlsx',)", "kwargs": {"sheet_name": "Loading...", "header": 0, "nrows": 50, "na_values": ["#N/A", "#N/A N/A", "#NA", "-NA", "#NULL!", "#NUM!", "#DIV/0!", "#VALUE!", "#REF!", "#NAME?", "#DIV/0", "#NUM", "#REF", "#VALUE"], "engine": "openpyxl", "parse_dates": true}}
2025-05-22 21:06:41,613 - data_integration.errors.error_handler - ERROR - Failed to load data from ExcelConnector: Error executing read_excel: Worksheet named 'Loading...' not found - Details: {"function": "read_excel", "args": "('C:\\\\Users\\\\luria\\\\PycharmProjects\\\\AuditQAStudio2\\\\test_data\\\\audit_workpapers_2025Q2.xlsx',)", "kwargs": {"sheet_name": "Loading...", "header": 0, "nrows": 50, "na_values": ["#N/A", "#N/A N/A", "#NA", "-NA", "#NULL!", "#NUM!", "#DIV/0!", "#VALUE!", "#REF!", "#NAME?", "#DIV/0", "#NUM", "#REF", "#VALUE"], "engine": "openpyxl", "parse_dates": true}} - Details: {"source_name": "ExcelConnector", "params": {"sheet_name": "Loading...", "header": 0, "nrows": 50, "na_values": ["#N/A", "#N/A N/A", "#NA", "-NA", "#NULL!", "#NUM!", "#DIV/0!", "#VALUE!", "#REF!", "#NAME?", "#DIV/0", "#NUM", "#REF", "#VALUE"], "engine": "openpyxl", "parse_dates": true}}
Traceback (most recent call last):
  File "C:\Users\luria\PycharmProjects\QAStudiov3\data_integration\errors\error_handler.py", line 328, in safe_dataframe_operation
    return func(*args, **kwargs)
           ^^^^^^^^^^^^^^^^^^^^^
  File "C:\Users\luria\PycharmProjects\QAStudiov3\.venv\Lib\site-packages\pandas\io\excel\_base.py", line 508, in read_excel
    data = io.parse(
           ^^^^^^^^^
  File "C:\Users\luria\PycharmProjects\QAStudiov3\.venv\Lib\site-packages\pandas\io\excel\_base.py", line 1616, in parse
    return self._reader.parse(
           ^^^^^^^^^^^^^^^^^^^
  File "C:\Users\luria\PycharmProjects\QAStudiov3\.venv\Lib\site-packages\pandas\io\excel\_base.py", line 773, in parse
    sheet = self.get_sheet_by_name(asheetname)
            ^^^^^^^^^^^^^^^^^^^^^^^^^^^^^^^^^^
  File "C:\Users\luria\PycharmProjects\QAStudiov3\.venv\Lib\site-packages\pandas\io\excel\_openpyxl.py", line 582, in get_sheet_by_name
    self.raise_if_bad_sheet_by_name(name)
  File "C:\Users\luria\PycharmProjects\QAStudiov3\.venv\Lib\site-packages\pandas\io\excel\_base.py", line 624, in raise_if_bad_sheet_by_name
    raise ValueError(f"Worksheet named '{name}' not found")
ValueError: Worksheet named 'Loading...' not found

During handling of the above exception, another exception occurred:

Traceback (most recent call last):
  File "C:\Users\luria\PycharmProjects\QAStudiov3\data_integration\connectors\excel_connector.py", line 195, in get_data
    df = retry_operation(
         ^^^^^^^^^^^^^^^^
  File "C:\Users\luria\PycharmProjects\QAStudiov3\data_integration\errors\error_handler.py", line 379, in retry_operation
    return func(*args, **kwargs)
           ^^^^^^^^^^^^^^^^^^^^^
  File "C:\Users\luria\PycharmProjects\QAStudiov3\data_integration\connectors\excel_connector.py", line 183, in load_excel
    return safe_dataframe_operation(
           ^^^^^^^^^^^^^^^^^^^^^^^^^
  File "C:\Users\luria\PycharmProjects\QAStudiov3\data_integration\errors\error_handler.py", line 344, in safe_dataframe_operation
    raise DataIntegrationError(error_msg, details)
data_integration.errors.error_handler.DataIntegrationError: Error executing read_excel: Worksheet named 'Loading...' not found - Details: {"function": "read_excel", "args": "('C:\\\\Users\\\\luria\\\\PycharmProjects\\\\AuditQAStudio2\\\\test_data\\\\audit_workpapers_2025Q2.xlsx',)", "kwargs": {"sheet_name": "Loading...", "header": 0, "nrows": 50, "na_values": ["#N/A", "#N/A N/A", "#NA", "-NA", "#NULL!", "#NUM!", "#DIV/0!", "#VALUE!", "#REF!", "#NAME?", "#DIV/0", "#NUM", "#REF", "#VALUE"], "engine": "openpyxl", "parse_dates": true}}
2025-05-22 21:06:41,615 - data_integration.io.importer - ERROR - Error previewing file C:\Users\luria\PycharmProjects\AuditQAStudio2\test_data\audit_workpapers_2025Q2.xlsx: Failed to load data from ExcelConnector: Error executing read_excel: Worksheet named 'Loading...' not found - Details: {"function": "read_excel", "args": "('C:\\\\Users\\\\luria\\\\PycharmProjects\\\\AuditQAStudio2\\\\test_data\\\\audit_workpapers_2025Q2.xlsx',)", "kwargs": {"sheet_name": "Loading...", "header": 0, "nrows": 50, "na_values": ["#N/A", "#N/A N/A", "#NA", "-NA", "#NULL!", "#NUM!", "#DIV/0!", "#VALUE!", "#REF!", "#NAME?", "#DIV/0", "#NUM", "#REF", "#VALUE"], "engine": "openpyxl", "parse_dates": true}} - Details: {"source_name": "ExcelConnector", "params": {"sheet_name": "Loading...", "header": 0, "nrows": 50, "na_values": ["#N/A", "#N/A N/A", "#NA", "-NA", "#NULL!", "#NUM!", "#DIV/0!", "#VALUE!", "#REF!", "#NAME?", "#DIV/0", "#NUM", "#REF", "#VALUE"], "engine": "openpyxl", "parse_dates": true}}
2025-05-22 21:06:41,615 - data_source_panel - ERROR - Error loading file preview: Failed to load data from ExcelConnector: Error executing read_excel: Worksheet named 'Loading...' not found - Details: {"function": "read_excel", "args": "('C:\\\\Users\\\\luria\\\\PycharmProjects\\\\AuditQAStudio2\\\\test_data\\\\audit_workpapers_2025Q2.xlsx',)", "kwargs": {"sheet_name": "Loading...", "header": 0, "nrows": 50, "na_values": ["#N/A", "#N/A N/A", "#NA", "-NA", "#NULL!", "#NUM!", "#DIV/0!", "#VALUE!", "#REF!", "#NAME?", "#DIV/0", "#NUM", "#REF", "#VALUE"], "engine": "openpyxl", "parse_dates": true}} - Details: {"source_name": "ExcelConnector", "params": {"sheet_name": "Loading...", "header": 0, "nrows": 50, "na_values": ["#N/A", "#N/A N/A", "#NA", "-NA", "#NULL!", "#NUM!", "#DIV/0!", "#VALUE!", "#REF!", "#NAME?", "#DIV/0", "#NUM", "#REF", "#VALUE"], "engine": "openpyxl", "parse_dates": true}}
2025-05-22 21:06:41,620 - data_source_panel - ERROR - Preview error: Error loading file preview: Failed to load data from ExcelConnector: Error executing read_excel: Worksheet named 'Loading...' not found - Details: {"function": "read_excel", "args": "('C:\\\\Users\\\\luria\\\\PycharmProjects\\\\AuditQAStudio2\\\\test_data\\\\audit_workpapers_2025Q2.xlsx',)", "kwargs": {"sheet_name": "Loading...", "header": 0, "nrows": 50, "na_values": ["#N/A", "#N/A N/A", "#NA", "-NA", "#NULL!", "#NUM!", "#DIV/0!", "#VALUE!", "#REF!", "#NAME?", "#DIV/0", "#NUM", "#REF", "#VALUE"], "engine": "openpyxl", "parse_dates": true}} - Details: {"source_name": "ExcelConnector", "params": {"sheet_name": "Loading...", "header": 0, "nrows": 50, "na_values": ["#N/A", "#N/A N/A", "#NA", "-NA", "#NULL!", "#NUM!", "#DIV/0!", "#VALUE!", "#REF!", "#NAME?", "#DIV/0", "#NUM", "#REF", "#VALUE"], "engine": "openpyxl", "parse_dates": true}}
2025-05-22 21:06:41,650 - error_handler - CRITICAL - TypeError: QTableWidget.update() takes exactly one argument (0 given)
2025-05-22 21:06:43,136 - __main__ - ERROR - ERROR: QTableWidget.update() takes exactly one argument (0 given)
2025-05-22 21:06:55,150 - error_handler - CRITICAL - TypeError: Object of type QByteArray is not JSON serializable
2025-05-22 21:06:56,292 - __main__ - ERROR - ERROR: Object of type QByteArray is not JSON serializable
2025-05-22 21:07:01,872 - data_integration.connectors.excel_connector - ERROR - Error loading Excel file C:\Users\luria\PycharmProjects\AuditQAStudio2\test_data\audit_workpapers_2025Q2.xlsx: Error executing read_excel: Worksheet named 'Loading...' not found - Details: {"function": "read_excel", "args": "('C:\\\\Users\\\\luria\\\\PycharmProjects\\\\AuditQAStudio2\\\\test_data\\\\audit_workpapers_2025Q2.xlsx',)", "kwargs": {"sheet_name": "Loading...", "header": 0, "nrows": 50, "na_values": ["#N/A", "#N/A N/A", "#NA", "-NA", "#NULL!", "#NUM!", "#DIV/0!", "#VALUE!", "#REF!", "#NAME?", "#DIV/0", "#NUM", "#REF", "#VALUE"], "engine": "openpyxl", "parse_dates": true}}
2025-05-22 21:07:01,872 - data_integration.errors.error_handler - ERROR - Failed to load data from ExcelConnector: Error executing read_excel: Worksheet named 'Loading...' not found - Details: {"function": "read_excel", "args": "('C:\\\\Users\\\\luria\\\\PycharmProjects\\\\AuditQAStudio2\\\\test_data\\\\audit_workpapers_2025Q2.xlsx',)", "kwargs": {"sheet_name": "Loading...", "header": 0, "nrows": 50, "na_values": ["#N/A", "#N/A N/A", "#NA", "-NA", "#NULL!", "#NUM!", "#DIV/0!", "#VALUE!", "#REF!", "#NAME?", "#DIV/0", "#NUM", "#REF", "#VALUE"], "engine": "openpyxl", "parse_dates": true}} - Details: {"source_name": "ExcelConnector", "params": {"sheet_name": "Loading...", "header": 0, "nrows": 50, "na_values": ["#N/A", "#N/A N/A", "#NA", "-NA", "#NULL!", "#NUM!", "#DIV/0!", "#VALUE!", "#REF!", "#NAME?", "#DIV/0", "#NUM", "#REF", "#VALUE"], "engine": "openpyxl", "parse_dates": true}}
Traceback (most recent call last):
  File "C:\Users\luria\PycharmProjects\QAStudiov3\data_integration\errors\error_handler.py", line 328, in safe_dataframe_operation
    return func(*args, **kwargs)
           ^^^^^^^^^^^^^^^^^^^^^
  File "C:\Users\luria\PycharmProjects\QAStudiov3\.venv\Lib\site-packages\pandas\io\excel\_base.py", line 508, in read_excel
    data = io.parse(
           ^^^^^^^^^
  File "C:\Users\luria\PycharmProjects\QAStudiov3\.venv\Lib\site-packages\pandas\io\excel\_base.py", line 1616, in parse
    return self._reader.parse(
           ^^^^^^^^^^^^^^^^^^^
  File "C:\Users\luria\PycharmProjects\QAStudiov3\.venv\Lib\site-packages\pandas\io\excel\_base.py", line 773, in parse
    sheet = self.get_sheet_by_name(asheetname)
            ^^^^^^^^^^^^^^^^^^^^^^^^^^^^^^^^^^
  File "C:\Users\luria\PycharmProjects\QAStudiov3\.venv\Lib\site-packages\pandas\io\excel\_openpyxl.py", line 582, in get_sheet_by_name
    self.raise_if_bad_sheet_by_name(name)
  File "C:\Users\luria\PycharmProjects\QAStudiov3\.venv\Lib\site-packages\pandas\io\excel\_base.py", line 624, in raise_if_bad_sheet_by_name
    raise ValueError(f"Worksheet named '{name}' not found")
ValueError: Worksheet named 'Loading...' not found

During handling of the above exception, another exception occurred:

Traceback (most recent call last):
  File "C:\Users\luria\PycharmProjects\QAStudiov3\data_integration\connectors\excel_connector.py", line 195, in get_data
    df = retry_operation(
         ^^^^^^^^^^^^^^^^
  File "C:\Users\luria\PycharmProjects\QAStudiov3\data_integration\errors\error_handler.py", line 379, in retry_operation
    return func(*args, **kwargs)
           ^^^^^^^^^^^^^^^^^^^^^
  File "C:\Users\luria\PycharmProjects\QAStudiov3\data_integration\connectors\excel_connector.py", line 183, in load_excel
    return safe_dataframe_operation(
           ^^^^^^^^^^^^^^^^^^^^^^^^^
  File "C:\Users\luria\PycharmProjects\QAStudiov3\data_integration\errors\error_handler.py", line 344, in safe_dataframe_operation
    raise DataIntegrationError(error_msg, details)
data_integration.errors.error_handler.DataIntegrationError: Error executing read_excel: Worksheet named 'Loading...' not found - Details: {"function": "read_excel", "args": "('C:\\\\Users\\\\luria\\\\PycharmProjects\\\\AuditQAStudio2\\\\test_data\\\\audit_workpapers_2025Q2.xlsx',)", "kwargs": {"sheet_name": "Loading...", "header": 0, "nrows": 50, "na_values": ["#N/A", "#N/A N/A", "#NA", "-NA", "#NULL!", "#NUM!", "#DIV/0!", "#VALUE!", "#REF!", "#NAME?", "#DIV/0", "#NUM", "#REF", "#VALUE"], "engine": "openpyxl", "parse_dates": true}}
2025-05-22 21:07:01,874 - data_integration.io.importer - ERROR - Error previewing file C:\Users\luria\PycharmProjects\AuditQAStudio2\test_data\audit_workpapers_2025Q2.xlsx: Failed to load data from ExcelConnector: Error executing read_excel: Worksheet named 'Loading...' not found - Details: {"function": "read_excel", "args": "('C:\\\\Users\\\\luria\\\\PycharmProjects\\\\AuditQAStudio2\\\\test_data\\\\audit_workpapers_2025Q2.xlsx',)", "kwargs": {"sheet_name": "Loading...", "header": 0, "nrows": 50, "na_values": ["#N/A", "#N/A N/A", "#NA", "-NA", "#NULL!", "#NUM!", "#DIV/0!", "#VALUE!", "#REF!", "#NAME?", "#DIV/0", "#NUM", "#REF", "#VALUE"], "engine": "openpyxl", "parse_dates": true}} - Details: {"source_name": "ExcelConnector", "params": {"sheet_name": "Loading...", "header": 0, "nrows": 50, "na_values": ["#N/A", "#N/A N/A", "#NA", "-NA", "#NULL!", "#NUM!", "#DIV/0!", "#VALUE!", "#REF!", "#NAME?", "#DIV/0", "#NUM", "#REF", "#VALUE"], "engine": "openpyxl", "parse_dates": true}}
2025-05-22 21:07:01,874 - data_source_panel - ERROR - Error loading file preview: Failed to load data from ExcelConnector: Error executing read_excel: Worksheet named 'Loading...' not found - Details: {"function": "read_excel", "args": "('C:\\\\Users\\\\luria\\\\PycharmProjects\\\\AuditQAStudio2\\\\test_data\\\\audit_workpapers_2025Q2.xlsx',)", "kwargs": {"sheet_name": "Loading...", "header": 0, "nrows": 50, "na_values": ["#N/A", "#N/A N/A", "#NA", "-NA", "#NULL!", "#NUM!", "#DIV/0!", "#VALUE!", "#REF!", "#NAME?", "#DIV/0", "#NUM", "#REF", "#VALUE"], "engine": "openpyxl", "parse_dates": true}} - Details: {"source_name": "ExcelConnector", "params": {"sheet_name": "Loading...", "header": 0, "nrows": 50, "na_values": ["#N/A", "#N/A N/A", "#NA", "-NA", "#NULL!", "#NUM!", "#DIV/0!", "#VALUE!", "#REF!", "#NAME?", "#DIV/0", "#NUM", "#REF", "#VALUE"], "engine": "openpyxl", "parse_dates": true}}
2025-05-22 21:07:01,880 - data_source_panel - ERROR - Preview error: Error loading file preview: Failed to load data from ExcelConnector: Error executing read_excel: Worksheet named 'Loading...' not found - Details: {"function": "read_excel", "args": "('C:\\\\Users\\\\luria\\\\PycharmProjects\\\\AuditQAStudio2\\\\test_data\\\\audit_workpapers_2025Q2.xlsx',)", "kwargs": {"sheet_name": "Loading...", "header": 0, "nrows": 50, "na_values": ["#N/A", "#N/A N/A", "#NA", "-NA", "#NULL!", "#NUM!", "#DIV/0!", "#VALUE!", "#REF!", "#NAME?", "#DIV/0", "#NUM", "#REF", "#VALUE"], "engine": "openpyxl", "parse_dates": true}} - Details: {"source_name": "ExcelConnector", "params": {"sheet_name": "Loading...", "header": 0, "nrows": 50, "na_values": ["#N/A", "#N/A N/A", "#NA", "-NA", "#NULL!", "#NUM!", "#DIV/0!", "#VALUE!", "#REF!", "#NAME?", "#DIV/0", "#NUM", "#REF", "#VALUE"], "engine": "openpyxl", "parse_dates": true}}
2025-05-22 21:07:01,910 - error_handler - CRITICAL - TypeError: QTableWidget.update() takes exactly one argument (0 given)
2025-05-22 21:08:36,046 - __main__ - ERROR - ERROR: QTableWidget.update() takes exactly one argument (0 given)
2025-05-22 21:08:37,862 - error_handler - CRITICAL - TypeError: Object of type QByteArray is not JSON serializable
2025-05-22 21:08:47,437 - __main__ - ERROR - ERROR: Object of type QByteArray is not JSON serializable
2025-05-22 21:09:23,150 - data_integration.connectors.excel_connector - ERROR - Error loading Excel file C:\Users\luria\PycharmProjects\AuditQAStudio2\test_data\audit_workpapers_2025Q2.xlsx: Error executing read_excel: Worksheet named 'Loading...' not found - Details: {"function": "read_excel", "args": "('C:\\\\Users\\\\luria\\\\PycharmProjects\\\\AuditQAStudio2\\\\test_data\\\\audit_workpapers_2025Q2.xlsx',)", "kwargs": {"sheet_name": "Loading...", "header": 0, "nrows": 50, "na_values": ["#N/A", "#N/A N/A", "#NA", "-NA", "#NULL!", "#NUM!", "#DIV/0!", "#VALUE!", "#REF!", "#NAME?", "#DIV/0", "#NUM", "#REF", "#VALUE"], "engine": "openpyxl", "parse_dates": true}}
2025-05-22 21:09:23,150 - data_integration.errors.error_handler - ERROR - Failed to load data from ExcelConnector: Error executing read_excel: Worksheet named 'Loading...' not found - Details: {"function": "read_excel", "args": "('C:\\\\Users\\\\luria\\\\PycharmProjects\\\\AuditQAStudio2\\\\test_data\\\\audit_workpapers_2025Q2.xlsx',)", "kwargs": {"sheet_name": "Loading...", "header": 0, "nrows": 50, "na_values": ["#N/A", "#N/A N/A", "#NA", "-NA", "#NULL!", "#NUM!", "#DIV/0!", "#VALUE!", "#REF!", "#NAME?", "#DIV/0", "#NUM", "#REF", "#VALUE"], "engine": "openpyxl", "parse_dates": true}} - Details: {"source_name": "ExcelConnector", "params": {"sheet_name": "Loading...", "header": 0, "nrows": 50, "na_values": ["#N/A", "#N/A N/A", "#NA", "-NA", "#NULL!", "#NUM!", "#DIV/0!", "#VALUE!", "#REF!", "#NAME?", "#DIV/0", "#NUM", "#REF", "#VALUE"], "engine": "openpyxl", "parse_dates": true}}
Traceback (most recent call last):
  File "C:\Users\luria\PycharmProjects\QAStudiov3\data_integration\errors\error_handler.py", line 328, in safe_dataframe_operation
    return func(*args, **kwargs)
           ^^^^^^^^^^^^^^^^^^^^^
  File "C:\Users\luria\PycharmProjects\QAStudiov3\.venv\Lib\site-packages\pandas\io\excel\_base.py", line 508, in read_excel
    data = io.parse(
           ^^^^^^^^^
  File "C:\Users\luria\PycharmProjects\QAStudiov3\.venv\Lib\site-packages\pandas\io\excel\_base.py", line 1616, in parse
    return self._reader.parse(
           ^^^^^^^^^^^^^^^^^^^
  File "C:\Users\luria\PycharmProjects\QAStudiov3\.venv\Lib\site-packages\pandas\io\excel\_base.py", line 773, in parse
    sheet = self.get_sheet_by_name(asheetname)
            ^^^^^^^^^^^^^^^^^^^^^^^^^^^^^^^^^^
  File "C:\Users\luria\PycharmProjects\QAStudiov3\.venv\Lib\site-packages\pandas\io\excel\_openpyxl.py", line 582, in get_sheet_by_name
    self.raise_if_bad_sheet_by_name(name)
  File "C:\Users\luria\PycharmProjects\QAStudiov3\.venv\Lib\site-packages\pandas\io\excel\_base.py", line 624, in raise_if_bad_sheet_by_name
    raise ValueError(f"Worksheet named '{name}' not found")
ValueError: Worksheet named 'Loading...' not found

During handling of the above exception, another exception occurred:

Traceback (most recent call last):
  File "C:\Users\luria\PycharmProjects\QAStudiov3\data_integration\connectors\excel_connector.py", line 195, in get_data
    df = retry_operation(
         ^^^^^^^^^^^^^^^^
  File "C:\Users\luria\PycharmProjects\QAStudiov3\data_integration\errors\error_handler.py", line 379, in retry_operation
    return func(*args, **kwargs)
           ^^^^^^^^^^^^^^^^^^^^^
  File "C:\Users\luria\PycharmProjects\QAStudiov3\data_integration\connectors\excel_connector.py", line 183, in load_excel
    return safe_dataframe_operation(
           ^^^^^^^^^^^^^^^^^^^^^^^^^
  File "C:\Users\luria\PycharmProjects\QAStudiov3\data_integration\errors\error_handler.py", line 344, in safe_dataframe_operation
    raise DataIntegrationError(error_msg, details)
data_integration.errors.error_handler.DataIntegrationError: Error executing read_excel: Worksheet named 'Loading...' not found - Details: {"function": "read_excel", "args": "('C:\\\\Users\\\\luria\\\\PycharmProjects\\\\AuditQAStudio2\\\\test_data\\\\audit_workpapers_2025Q2.xlsx',)", "kwargs": {"sheet_name": "Loading...", "header": 0, "nrows": 50, "na_values": ["#N/A", "#N/A N/A", "#NA", "-NA", "#NULL!", "#NUM!", "#DIV/0!", "#VALUE!", "#REF!", "#NAME?", "#DIV/0", "#NUM", "#REF", "#VALUE"], "engine": "openpyxl", "parse_dates": true}}
2025-05-22 21:09:23,153 - data_integration.io.importer - ERROR - Error previewing file C:\Users\luria\PycharmProjects\AuditQAStudio2\test_data\audit_workpapers_2025Q2.xlsx: Failed to load data from ExcelConnector: Error executing read_excel: Worksheet named 'Loading...' not found - Details: {"function": "read_excel", "args": "('C:\\\\Users\\\\luria\\\\PycharmProjects\\\\AuditQAStudio2\\\\test_data\\\\audit_workpapers_2025Q2.xlsx',)", "kwargs": {"sheet_name": "Loading...", "header": 0, "nrows": 50, "na_values": ["#N/A", "#N/A N/A", "#NA", "-NA", "#NULL!", "#NUM!", "#DIV/0!", "#VALUE!", "#REF!", "#NAME?", "#DIV/0", "#NUM", "#REF", "#VALUE"], "engine": "openpyxl", "parse_dates": true}} - Details: {"source_name": "ExcelConnector", "params": {"sheet_name": "Loading...", "header": 0, "nrows": 50, "na_values": ["#N/A", "#N/A N/A", "#NA", "-NA", "#NULL!", "#NUM!", "#DIV/0!", "#VALUE!", "#REF!", "#NAME?", "#DIV/0", "#NUM", "#REF", "#VALUE"], "engine": "openpyxl", "parse_dates": true}}
2025-05-22 21:09:23,153 - data_source_panel - ERROR - Error loading file preview: Failed to load data from ExcelConnector: Error executing read_excel: Worksheet named 'Loading...' not found - Details: {"function": "read_excel", "args": "('C:\\\\Users\\\\luria\\\\PycharmProjects\\\\AuditQAStudio2\\\\test_data\\\\audit_workpapers_2025Q2.xlsx',)", "kwargs": {"sheet_name": "Loading...", "header": 0, "nrows": 50, "na_values": ["#N/A", "#N/A N/A", "#NA", "-NA", "#NULL!", "#NUM!", "#DIV/0!", "#VALUE!", "#REF!", "#NAME?", "#DIV/0", "#NUM", "#REF", "#VALUE"], "engine": "openpyxl", "parse_dates": true}} - Details: {"source_name": "ExcelConnector", "params": {"sheet_name": "Loading...", "header": 0, "nrows": 50, "na_values": ["#N/A", "#N/A N/A", "#NA", "-NA", "#NULL!", "#NUM!", "#DIV/0!", "#VALUE!", "#REF!", "#NAME?", "#DIV/0", "#NUM", "#REF", "#VALUE"], "engine": "openpyxl", "parse_dates": true}}
2025-05-22 21:09:23,157 - data_source_panel - ERROR - Preview error: Error loading file preview: Failed to load data from ExcelConnector: Error executing read_excel: Worksheet named 'Loading...' not found - Details: {"function": "read_excel", "args": "('C:\\\\Users\\\\luria\\\\PycharmProjects\\\\AuditQAStudio2\\\\test_data\\\\audit_workpapers_2025Q2.xlsx',)", "kwargs": {"sheet_name": "Loading...", "header": 0, "nrows": 50, "na_values": ["#N/A", "#N/A N/A", "#NA", "-NA", "#NULL!", "#NUM!", "#DIV/0!", "#VALUE!", "#REF!", "#NAME?", "#DIV/0", "#NUM", "#REF", "#VALUE"], "engine": "openpyxl", "parse_dates": true}} - Details: {"source_name": "ExcelConnector", "params": {"sheet_name": "Loading...", "header": 0, "nrows": 50, "na_values": ["#N/A", "#N/A N/A", "#NA", "-NA", "#NULL!", "#NUM!", "#DIV/0!", "#VALUE!", "#REF!", "#NAME?", "#DIV/0", "#NUM", "#REF", "#VALUE"], "engine": "openpyxl", "parse_dates": true}}
2025-05-22 21:12:54,413 - error_handler - CRITICAL - TypeError: Object of type QByteArray is not JSON serializable
2025-05-22 21:12:55,714 - __main__ - ERROR - ERROR: Object of type QByteArray is not JSON serializable
2025-05-22 21:13:00,843 - data_integration.connectors.excel_connector - ERROR - Error loading Excel file C:\Users\luria\PycharmProjects\AuditQAStudio2\test_data\audit_workpapers_2025Q2.xlsx: Error executing read_excel: Worksheet named 'Loading...' not found - Details: {"function": "read_excel", "args": "('C:\\\\Users\\\\luria\\\\PycharmProjects\\\\AuditQAStudio2\\\\test_data\\\\audit_workpapers_2025Q2.xlsx',)", "kwargs": {"sheet_name": "Loading...", "header": 0, "nrows": 50, "na_values": ["#N/A", "#N/A N/A", "#NA", "-NA", "#NULL!", "#NUM!", "#DIV/0!", "#VALUE!", "#REF!", "#NAME?", "#DIV/0", "#NUM", "#REF", "#VALUE"], "engine": "openpyxl", "parse_dates": true}}
2025-05-22 21:13:00,843 - data_integration.errors.error_handler - ERROR - Failed to load data from ExcelConnector: Error executing read_excel: Worksheet named 'Loading...' not found - Details: {"function": "read_excel", "args": "('C:\\\\Users\\\\luria\\\\PycharmProjects\\\\AuditQAStudio2\\\\test_data\\\\audit_workpapers_2025Q2.xlsx',)", "kwargs": {"sheet_name": "Loading...", "header": 0, "nrows": 50, "na_values": ["#N/A", "#N/A N/A", "#NA", "-NA", "#NULL!", "#NUM!", "#DIV/0!", "#VALUE!", "#REF!", "#NAME?", "#DIV/0", "#NUM", "#REF", "#VALUE"], "engine": "openpyxl", "parse_dates": true}} - Details: {"source_name": "ExcelConnector", "params": {"sheet_name": "Loading...", "header": 0, "nrows": 50, "na_values": ["#N/A", "#N/A N/A", "#NA", "-NA", "#NULL!", "#NUM!", "#DIV/0!", "#VALUE!", "#REF!", "#NAME?", "#DIV/0", "#NUM", "#REF", "#VALUE"], "engine": "openpyxl", "parse_dates": true}}
Traceback (most recent call last):
  File "C:\Users\luria\PycharmProjects\QAStudiov3\data_integration\errors\error_handler.py", line 328, in safe_dataframe_operation
    return func(*args, **kwargs)
           ^^^^^^^^^^^^^^^^^^^^^
  File "C:\Users\luria\PycharmProjects\QAStudiov3\.venv\Lib\site-packages\pandas\io\excel\_base.py", line 508, in read_excel
    data = io.parse(
           ^^^^^^^^^
  File "C:\Users\luria\PycharmProjects\QAStudiov3\.venv\Lib\site-packages\pandas\io\excel\_base.py", line 1616, in parse
    return self._reader.parse(
           ^^^^^^^^^^^^^^^^^^^
  File "C:\Users\luria\PycharmProjects\QAStudiov3\.venv\Lib\site-packages\pandas\io\excel\_base.py", line 773, in parse
    sheet = self.get_sheet_by_name(asheetname)
            ^^^^^^^^^^^^^^^^^^^^^^^^^^^^^^^^^^
  File "C:\Users\luria\PycharmProjects\QAStudiov3\.venv\Lib\site-packages\pandas\io\excel\_openpyxl.py", line 582, in get_sheet_by_name
    self.raise_if_bad_sheet_by_name(name)
  File "C:\Users\luria\PycharmProjects\QAStudiov3\.venv\Lib\site-packages\pandas\io\excel\_base.py", line 624, in raise_if_bad_sheet_by_name
    raise ValueError(f"Worksheet named '{name}' not found")
ValueError: Worksheet named 'Loading...' not found

During handling of the above exception, another exception occurred:

Traceback (most recent call last):
  File "C:\Users\luria\PycharmProjects\QAStudiov3\data_integration\connectors\excel_connector.py", line 195, in get_data
    df = retry_operation(
         ^^^^^^^^^^^^^^^^
  File "C:\Users\luria\PycharmProjects\QAStudiov3\data_integration\errors\error_handler.py", line 379, in retry_operation
    return func(*args, **kwargs)
           ^^^^^^^^^^^^^^^^^^^^^
  File "C:\Users\luria\PycharmProjects\QAStudiov3\data_integration\connectors\excel_connector.py", line 183, in load_excel
    return safe_dataframe_operation(
           ^^^^^^^^^^^^^^^^^^^^^^^^^
  File "C:\Users\luria\PycharmProjects\QAStudiov3\data_integration\errors\error_handler.py", line 344, in safe_dataframe_operation
    raise DataIntegrationError(error_msg, details)
data_integration.errors.error_handler.DataIntegrationError: Error executing read_excel: Worksheet named 'Loading...' not found - Details: {"function": "read_excel", "args": "('C:\\\\Users\\\\luria\\\\PycharmProjects\\\\AuditQAStudio2\\\\test_data\\\\audit_workpapers_2025Q2.xlsx',)", "kwargs": {"sheet_name": "Loading...", "header": 0, "nrows": 50, "na_values": ["#N/A", "#N/A N/A", "#NA", "-NA", "#NULL!", "#NUM!", "#DIV/0!", "#VALUE!", "#REF!", "#NAME?", "#DIV/0", "#NUM", "#REF", "#VALUE"], "engine": "openpyxl", "parse_dates": true}}
2025-05-22 21:13:00,845 - data_integration.io.importer - ERROR - Error previewing file C:\Users\luria\PycharmProjects\AuditQAStudio2\test_data\audit_workpapers_2025Q2.xlsx: Failed to load data from ExcelConnector: Error executing read_excel: Worksheet named 'Loading...' not found - Details: {"function": "read_excel", "args": "('C:\\\\Users\\\\luria\\\\PycharmProjects\\\\AuditQAStudio2\\\\test_data\\\\audit_workpapers_2025Q2.xlsx',)", "kwargs": {"sheet_name": "Loading...", "header": 0, "nrows": 50, "na_values": ["#N/A", "#N/A N/A", "#NA", "-NA", "#NULL!", "#NUM!", "#DIV/0!", "#VALUE!", "#REF!", "#NAME?", "#DIV/0", "#NUM", "#REF", "#VALUE"], "engine": "openpyxl", "parse_dates": true}} - Details: {"source_name": "ExcelConnector", "params": {"sheet_name": "Loading...", "header": 0, "nrows": 50, "na_values": ["#N/A", "#N/A N/A", "#NA", "-NA", "#NULL!", "#NUM!", "#DIV/0!", "#VALUE!", "#REF!", "#NAME?", "#DIV/0", "#NUM", "#REF", "#VALUE"], "engine": "openpyxl", "parse_dates": true}}
2025-05-22 21:13:00,845 - data_source_panel - ERROR - Error loading file preview: Failed to load data from ExcelConnector: Error executing read_excel: Worksheet named 'Loading...' not found - Details: {"function": "read_excel", "args": "('C:\\\\Users\\\\luria\\\\PycharmProjects\\\\AuditQAStudio2\\\\test_data\\\\audit_workpapers_2025Q2.xlsx',)", "kwargs": {"sheet_name": "Loading...", "header": 0, "nrows": 50, "na_values": ["#N/A", "#N/A N/A", "#NA", "-NA", "#NULL!", "#NUM!", "#DIV/0!", "#VALUE!", "#REF!", "#NAME?", "#DIV/0", "#NUM", "#REF", "#VALUE"], "engine": "openpyxl", "parse_dates": true}} - Details: {"source_name": "ExcelConnector", "params": {"sheet_name": "Loading...", "header": 0, "nrows": 50, "na_values": ["#N/A", "#N/A N/A", "#NA", "-NA", "#NULL!", "#NUM!", "#DIV/0!", "#VALUE!", "#REF!", "#NAME?", "#DIV/0", "#NUM", "#REF", "#VALUE"], "engine": "openpyxl", "parse_dates": true}}
2025-05-22 21:13:00,850 - data_source_panel - ERROR - Preview error: Error loading file preview: Failed to load data from ExcelConnector: Error executing read_excel: Worksheet named 'Loading...' not found - Details: {"function": "read_excel", "args": "('C:\\\\Users\\\\luria\\\\PycharmProjects\\\\AuditQAStudio2\\\\test_data\\\\audit_workpapers_2025Q2.xlsx',)", "kwargs": {"sheet_name": "Loading...", "header": 0, "nrows": 50, "na_values": ["#N/A", "#N/A N/A", "#NA", "-NA", "#NULL!", "#NUM!", "#DIV/0!", "#VALUE!", "#REF!", "#NAME?", "#DIV/0", "#NUM", "#REF", "#VALUE"], "engine": "openpyxl", "parse_dates": true}} - Details: {"source_name": "ExcelConnector", "params": {"sheet_name": "Loading...", "header": 0, "nrows": 50, "na_values": ["#N/A", "#N/A N/A", "#NA", "-NA", "#NULL!", "#NUM!", "#DIV/0!", "#VALUE!", "#REF!", "#NAME?", "#DIV/0", "#NUM", "#REF", "#VALUE"], "engine": "openpyxl", "parse_dates": true}}
2025-05-22 21:13:52,722 - error_handler - CRITICAL - TypeError: Object of type QByteArray is not JSON serializable
2025-05-22 21:13:53,581 - __main__ - ERROR - ERROR: Object of type QByteArray is not JSON serializable
2025-05-22 21:13:58,478 - error_handler - CRITICAL - TypeError: Object of type QByteArray is not JSON serializable
2025-05-22 21:15:36,098 - __main__ - ERROR - ERROR: Object of type QByteArray is not JSON serializable
2025-05-22 21:15:44,837 - error_handler - ERROR - TypeError: 'PySide6.QtWidgets.QWidget.restoreGeometry' called with wrong argument types:
  PySide6.QtWidgets.QWidget.restoreGeometry(dict)
Supported signatures:
  PySide6.QtWidgets.QWidget.restoreGeometry(geometry: PySide6.QtCore.QByteArray | bytes | bytearray | memoryview, /)
2025-05-22 21:15:52,969 - error_handler - ERROR - TypeError: 'PySide6.QtWidgets.QWidget.restoreGeometry' called with wrong argument types:
  PySide6.QtWidgets.QWidget.restoreGeometry(dict)
Supported signatures:
  PySide6.QtWidgets.QWidget.restoreGeometry(geometry: PySide6.QtCore.QByteArray | bytes | bytearray | memoryview, /)
2025-05-22 21:17:52,890 - error_handler - CRITICAL - AttributeError: 'SessionManager' object has no attribute '_convert_qt_objects_for_json'
2025-05-22 21:19:06,964 - __main__ - ERROR - ERROR: 'SessionManager' object has no attribute '_convert_qt_objects_for_json'
2025-05-22 21:19:07,819 - error_handler - CRITICAL - AttributeError: 'SessionManager' object has no attribute '_convert_qt_objects_for_json'
2025-05-22 21:19:09,269 - __main__ - ERROR - ERROR: 'SessionManager' object has no attribute '_convert_qt_objects_for_json'
2025-05-22 21:19:13,345 - error_handler - CRITICAL - AttributeError: 'SessionManager' object has no attribute '_convert_qt_objects_for_json'
2025-05-22 21:19:24,060 - __main__ - ERROR - ERROR: 'SessionManager' object has no attribute '_convert_qt_objects_for_json'
2025-05-22 21:19:27,226 - error_handler - CRITICAL - AttributeError: 'SessionManager' object has no attribute '_convert_qt_objects_for_json'
2025-05-22 21:19:28,301 - __main__ - ERROR - ERROR: 'SessionManager' object has no attribute '_convert_qt_objects_for_json'
2025-05-22 21:19:38,979 - error_handler - ERROR - TypeError: 'PySide6.QtWidgets.QWidget.restoreGeometry' called with wrong argument types:
  PySide6.QtWidgets.QWidget.restoreGeometry(dict)
Supported signatures:
  PySide6.QtWidgets.QWidget.restoreGeometry(geometry: PySide6.QtCore.QByteArray | bytes | bytearray | memoryview, /)
2025-05-22 21:19:41,674 - error_handler - CRITICAL - TypeError: Object of type QByteArray is not JSON serializable
2025-05-22 21:19:55,448 - data_integration.connectors.excel_connector - ERROR - Error loading Excel file C:/Users/luria/PycharmProjects/AuditQAStudio2/test_data/audit_workpapers_2025Q2.xlsx: Error executing read_excel: Worksheet named 'Loading...' not found - Details: {"function": "read_excel", "args": "('C:/Users/luria/PycharmProjects/AuditQAStudio2/test_data/audit_workpapers_2025Q2.xlsx',)", "kwargs": {"sheet_name": "Loading...", "header": 0, "nrows": 50, "na_values": ["#N/A", "#N/A N/A", "#NA", "-NA", "#NULL!", "#NUM!", "#DIV/0!", "#VALUE!", "#REF!", "#NAME?", "#DIV/0", "#NUM", "#REF", "#VALUE"], "engine": "openpyxl", "parse_dates": true}}
2025-05-22 21:19:55,448 - data_integration.errors.error_handler - ERROR - Failed to load data from ExcelConnector: Error executing read_excel: Worksheet named 'Loading...' not found - Details: {"function": "read_excel", "args": "('C:/Users/luria/PycharmProjects/AuditQAStudio2/test_data/audit_workpapers_2025Q2.xlsx',)", "kwargs": {"sheet_name": "Loading...", "header": 0, "nrows": 50, "na_values": ["#N/A", "#N/A N/A", "#NA", "-NA", "#NULL!", "#NUM!", "#DIV/0!", "#VALUE!", "#REF!", "#NAME?", "#DIV/0", "#NUM", "#REF", "#VALUE"], "engine": "openpyxl", "parse_dates": true}} - Details: {"source_name": "ExcelConnector", "params": {"sheet_name": "Loading...", "header": 0, "nrows": 50, "na_values": ["#N/A", "#N/A N/A", "#NA", "-NA", "#NULL!", "#NUM!", "#DIV/0!", "#VALUE!", "#REF!", "#NAME?", "#DIV/0", "#NUM", "#REF", "#VALUE"], "engine": "openpyxl", "parse_dates": true}}
Traceback (most recent call last):
  File "C:\Users\luria\PycharmProjects\QAStudiov3\data_integration\errors\error_handler.py", line 328, in safe_dataframe_operation
    return func(*args, **kwargs)
           ^^^^^^^^^^^^^^^^^^^^^
  File "C:\Users\luria\PycharmProjects\QAStudiov3\.venv\Lib\site-packages\pandas\io\excel\_base.py", line 508, in read_excel
    data = io.parse(
           ^^^^^^^^^
  File "C:\Users\luria\PycharmProjects\QAStudiov3\.venv\Lib\site-packages\pandas\io\excel\_base.py", line 1616, in parse
    return self._reader.parse(
           ^^^^^^^^^^^^^^^^^^^
  File "C:\Users\luria\PycharmProjects\QAStudiov3\.venv\Lib\site-packages\pandas\io\excel\_base.py", line 773, in parse
    sheet = self.get_sheet_by_name(asheetname)
            ^^^^^^^^^^^^^^^^^^^^^^^^^^^^^^^^^^
  File "C:\Users\luria\PycharmProjects\QAStudiov3\.venv\Lib\site-packages\pandas\io\excel\_openpyxl.py", line 582, in get_sheet_by_name
    self.raise_if_bad_sheet_by_name(name)
  File "C:\Users\luria\PycharmProjects\QAStudiov3\.venv\Lib\site-packages\pandas\io\excel\_base.py", line 624, in raise_if_bad_sheet_by_name
    raise ValueError(f"Worksheet named '{name}' not found")
ValueError: Worksheet named 'Loading...' not found

During handling of the above exception, another exception occurred:

Traceback (most recent call last):
  File "C:\Users\luria\PycharmProjects\QAStudiov3\data_integration\connectors\excel_connector.py", line 195, in get_data
    df = retry_operation(
         ^^^^^^^^^^^^^^^^
  File "C:\Users\luria\PycharmProjects\QAStudiov3\data_integration\errors\error_handler.py", line 379, in retry_operation
    return func(*args, **kwargs)
           ^^^^^^^^^^^^^^^^^^^^^
  File "C:\Users\luria\PycharmProjects\QAStudiov3\data_integration\connectors\excel_connector.py", line 183, in load_excel
    return safe_dataframe_operation(
           ^^^^^^^^^^^^^^^^^^^^^^^^^
  File "C:\Users\luria\PycharmProjects\QAStudiov3\data_integration\errors\error_handler.py", line 344, in safe_dataframe_operation
    raise DataIntegrationError(error_msg, details)
data_integration.errors.error_handler.DataIntegrationError: Error executing read_excel: Worksheet named 'Loading...' not found - Details: {"function": "read_excel", "args": "('C:/Users/luria/PycharmProjects/AuditQAStudio2/test_data/audit_workpapers_2025Q2.xlsx',)", "kwargs": {"sheet_name": "Loading...", "header": 0, "nrows": 50, "na_values": ["#N/A", "#N/A N/A", "#NA", "-NA", "#NULL!", "#NUM!", "#DIV/0!", "#VALUE!", "#REF!", "#NAME?", "#DIV/0", "#NUM", "#REF", "#VALUE"], "engine": "openpyxl", "parse_dates": true}}
2025-05-22 21:19:55,450 - data_integration.io.importer - ERROR - Error previewing file C:/Users/luria/PycharmProjects/AuditQAStudio2/test_data/audit_workpapers_2025Q2.xlsx: Failed to load data from ExcelConnector: Error executing read_excel: Worksheet named 'Loading...' not found - Details: {"function": "read_excel", "args": "('C:/Users/luria/PycharmProjects/AuditQAStudio2/test_data/audit_workpapers_2025Q2.xlsx',)", "kwargs": {"sheet_name": "Loading...", "header": 0, "nrows": 50, "na_values": ["#N/A", "#N/A N/A", "#NA", "-NA", "#NULL!", "#NUM!", "#DIV/0!", "#VALUE!", "#REF!", "#NAME?", "#DIV/0", "#NUM", "#REF", "#VALUE"], "engine": "openpyxl", "parse_dates": true}} - Details: {"source_name": "ExcelConnector", "params": {"sheet_name": "Loading...", "header": 0, "nrows": 50, "na_values": ["#N/A", "#N/A N/A", "#NA", "-NA", "#NULL!", "#NUM!", "#DIV/0!", "#VALUE!", "#REF!", "#NAME?", "#DIV/0", "#NUM", "#REF", "#VALUE"], "engine": "openpyxl", "parse_dates": true}}
2025-05-22 21:19:55,450 - data_source_panel - ERROR - Error loading file preview: Failed to load data from ExcelConnector: Error executing read_excel: Worksheet named 'Loading...' not found - Details: {"function": "read_excel", "args": "('C:/Users/luria/PycharmProjects/AuditQAStudio2/test_data/audit_workpapers_2025Q2.xlsx',)", "kwargs": {"sheet_name": "Loading...", "header": 0, "nrows": 50, "na_values": ["#N/A", "#N/A N/A", "#NA", "-NA", "#NULL!", "#NUM!", "#DIV/0!", "#VALUE!", "#REF!", "#NAME?", "#DIV/0", "#NUM", "#REF", "#VALUE"], "engine": "openpyxl", "parse_dates": true}} - Details: {"source_name": "ExcelConnector", "params": {"sheet_name": "Loading...", "header": 0, "nrows": 50, "na_values": ["#N/A", "#N/A N/A", "#NA", "-NA", "#NULL!", "#NUM!", "#DIV/0!", "#VALUE!", "#REF!", "#NAME?", "#DIV/0", "#NUM", "#REF", "#VALUE"], "engine": "openpyxl", "parse_dates": true}}
2025-05-22 21:19:55,460 - data_source_panel - ERROR - Preview error: Error loading file preview: Failed to load data from ExcelConnector: Error executing read_excel: Worksheet named 'Loading...' not found - Details: {"function": "read_excel", "args": "('C:/Users/luria/PycharmProjects/AuditQAStudio2/test_data/audit_workpapers_2025Q2.xlsx',)", "kwargs": {"sheet_name": "Loading...", "header": 0, "nrows": 50, "na_values": ["#N/A", "#N/A N/A", "#NA", "-NA", "#NULL!", "#NUM!", "#DIV/0!", "#VALUE!", "#REF!", "#NAME?", "#DIV/0", "#NUM", "#REF", "#VALUE"], "engine": "openpyxl", "parse_dates": true}} - Details: {"source_name": "ExcelConnector", "params": {"sheet_name": "Loading...", "header": 0, "nrows": 50, "na_values": ["#N/A", "#N/A N/A", "#NA", "-NA", "#NULL!", "#NUM!", "#DIV/0!", "#VALUE!", "#REF!", "#NAME?", "#DIV/0", "#NUM", "#REF", "#VALUE"], "engine": "openpyxl", "parse_dates": true}}
2025-05-22 21:20:00,515 - error_handler - CRITICAL - TypeError: Object of type QByteArray is not JSON serializable
2025-05-22 21:20:01,472 - __main__ - ERROR - ERROR: Object of type QByteArray is not JSON serializable
2025-05-23 08:22:29,458 - error_handler - CRITICAL - TypeError: Object of type QByteArray is not JSON serializable
2025-05-23 08:22:30,959 - __main__ - ERROR - ERROR: Object of type QByteArray is not JSON serializable
2025-05-23 08:43:07,779 - data_integration.connectors.excel_connector - ERROR - Error loading Excel file C:\Users\luria\PycharmProjects\AuditQAStudio2\test_data\audit_workpapers_2025Q2.xlsx: Error executing read_excel: Worksheet named 'Loading...' not found - Details: {"function": "read_excel", "args": "('C:\\\\Users\\\\luria\\\\PycharmProjects\\\\AuditQAStudio2\\\\test_data\\\\audit_workpapers_2025Q2.xlsx',)", "kwargs": {"sheet_name": "Loading...", "header": 0, "nrows": 50, "na_values": ["#N/A", "#N/A N/A", "#NA", "-NA", "#NULL!", "#NUM!", "#DIV/0!", "#VALUE!", "#REF!", "#NAME?", "#DIV/0", "#NUM", "#REF", "#VALUE"], "engine": "openpyxl", "parse_dates": true}}
2025-05-23 08:43:07,779 - data_integration.errors.error_handler - ERROR - Failed to load data from ExcelConnector: Error executing read_excel: Worksheet named 'Loading...' not found - Details: {"function": "read_excel", "args": "('C:\\\\Users\\\\luria\\\\PycharmProjects\\\\AuditQAStudio2\\\\test_data\\\\audit_workpapers_2025Q2.xlsx',)", "kwargs": {"sheet_name": "Loading...", "header": 0, "nrows": 50, "na_values": ["#N/A", "#N/A N/A", "#NA", "-NA", "#NULL!", "#NUM!", "#DIV/0!", "#VALUE!", "#REF!", "#NAME?", "#DIV/0", "#NUM", "#REF", "#VALUE"], "engine": "openpyxl", "parse_dates": true}} - Details: {"source_name": "ExcelConnector", "params": {"sheet_name": "Loading...", "header": 0, "nrows": 50, "na_values": ["#N/A", "#N/A N/A", "#NA", "-NA", "#NULL!", "#NUM!", "#DIV/0!", "#VALUE!", "#REF!", "#NAME?", "#DIV/0", "#NUM", "#REF", "#VALUE"], "engine": "openpyxl", "parse_dates": true}}
Traceback (most recent call last):
  File "C:\Users\luria\PycharmProjects\QAStudiov3\data_integration\errors\error_handler.py", line 328, in safe_dataframe_operation
    return func(*args, **kwargs)
           ^^^^^^^^^^^^^^^^^^^^^
  File "C:\Users\luria\PycharmProjects\QAStudiov3\.venv\Lib\site-packages\pandas\io\excel\_base.py", line 508, in read_excel
    data = io.parse(
           ^^^^^^^^^
  File "C:\Users\luria\PycharmProjects\QAStudiov3\.venv\Lib\site-packages\pandas\io\excel\_base.py", line 1616, in parse
    return self._reader.parse(
           ^^^^^^^^^^^^^^^^^^^
  File "C:\Users\luria\PycharmProjects\QAStudiov3\.venv\Lib\site-packages\pandas\io\excel\_base.py", line 773, in parse
    sheet = self.get_sheet_by_name(asheetname)
            ^^^^^^^^^^^^^^^^^^^^^^^^^^^^^^^^^^
  File "C:\Users\luria\PycharmProjects\QAStudiov3\.venv\Lib\site-packages\pandas\io\excel\_openpyxl.py", line 582, in get_sheet_by_name
    self.raise_if_bad_sheet_by_name(name)
  File "C:\Users\luria\PycharmProjects\QAStudiov3\.venv\Lib\site-packages\pandas\io\excel\_base.py", line 624, in raise_if_bad_sheet_by_name
    raise ValueError(f"Worksheet named '{name}' not found")
ValueError: Worksheet named 'Loading...' not found

During handling of the above exception, another exception occurred:

Traceback (most recent call last):
  File "C:\Users\luria\PycharmProjects\QAStudiov3\data_integration\connectors\excel_connector.py", line 195, in get_data
    df = retry_operation(
         ^^^^^^^^^^^^^^^^
  File "C:\Users\luria\PycharmProjects\QAStudiov3\data_integration\errors\error_handler.py", line 379, in retry_operation
    return func(*args, **kwargs)
           ^^^^^^^^^^^^^^^^^^^^^
  File "C:\Users\luria\PycharmProjects\QAStudiov3\data_integration\connectors\excel_connector.py", line 183, in load_excel
    return safe_dataframe_operation(
           ^^^^^^^^^^^^^^^^^^^^^^^^^
  File "C:\Users\luria\PycharmProjects\QAStudiov3\data_integration\errors\error_handler.py", line 344, in safe_dataframe_operation
    raise DataIntegrationError(error_msg, details)
data_integration.errors.error_handler.DataIntegrationError: Error executing read_excel: Worksheet named 'Loading...' not found - Details: {"function": "read_excel", "args": "('C:\\\\Users\\\\luria\\\\PycharmProjects\\\\AuditQAStudio2\\\\test_data\\\\audit_workpapers_2025Q2.xlsx',)", "kwargs": {"sheet_name": "Loading...", "header": 0, "nrows": 50, "na_values": ["#N/A", "#N/A N/A", "#NA", "-NA", "#NULL!", "#NUM!", "#DIV/0!", "#VALUE!", "#REF!", "#NAME?", "#DIV/0", "#NUM", "#REF", "#VALUE"], "engine": "openpyxl", "parse_dates": true}}
2025-05-23 08:43:07,816 - data_integration.io.importer - ERROR - Error previewing file C:\Users\luria\PycharmProjects\AuditQAStudio2\test_data\audit_workpapers_2025Q2.xlsx: Failed to load data from ExcelConnector: Error executing read_excel: Worksheet named 'Loading...' not found - Details: {"function": "read_excel", "args": "('C:\\\\Users\\\\luria\\\\PycharmProjects\\\\AuditQAStudio2\\\\test_data\\\\audit_workpapers_2025Q2.xlsx',)", "kwargs": {"sheet_name": "Loading...", "header": 0, "nrows": 50, "na_values": ["#N/A", "#N/A N/A", "#NA", "-NA", "#NULL!", "#NUM!", "#DIV/0!", "#VALUE!", "#REF!", "#NAME?", "#DIV/0", "#NUM", "#REF", "#VALUE"], "engine": "openpyxl", "parse_dates": true}} - Details: {"source_name": "ExcelConnector", "params": {"sheet_name": "Loading...", "header": 0, "nrows": 50, "na_values": ["#N/A", "#N/A N/A", "#NA", "-NA", "#NULL!", "#NUM!", "#DIV/0!", "#VALUE!", "#REF!", "#NAME?", "#DIV/0", "#NUM", "#REF", "#VALUE"], "engine": "openpyxl", "parse_dates": true}}
2025-05-23 08:43:07,816 - data_source_panel - ERROR - Error loading file preview: Failed to load data from ExcelConnector: Error executing read_excel: Worksheet named 'Loading...' not found - Details: {"function": "read_excel", "args": "('C:\\\\Users\\\\luria\\\\PycharmProjects\\\\AuditQAStudio2\\\\test_data\\\\audit_workpapers_2025Q2.xlsx',)", "kwargs": {"sheet_name": "Loading...", "header": 0, "nrows": 50, "na_values": ["#N/A", "#N/A N/A", "#NA", "-NA", "#NULL!", "#NUM!", "#DIV/0!", "#VALUE!", "#REF!", "#NAME?", "#DIV/0", "#NUM", "#REF", "#VALUE"], "engine": "openpyxl", "parse_dates": true}} - Details: {"source_name": "ExcelConnector", "params": {"sheet_name": "Loading...", "header": 0, "nrows": 50, "na_values": ["#N/A", "#N/A N/A", "#NA", "-NA", "#NULL!", "#NUM!", "#DIV/0!", "#VALUE!", "#REF!", "#NAME?", "#DIV/0", "#NUM", "#REF", "#VALUE"], "engine": "openpyxl", "parse_dates": true}}
2025-05-23 08:43:07,823 - data_source_panel - ERROR - Preview error: Error loading file preview: Failed to load data from ExcelConnector: Error executing read_excel: Worksheet named 'Loading...' not found - Details: {"function": "read_excel", "args": "('C:\\\\Users\\\\luria\\\\PycharmProjects\\\\AuditQAStudio2\\\\test_data\\\\audit_workpapers_2025Q2.xlsx',)", "kwargs": {"sheet_name": "Loading...", "header": 0, "nrows": 50, "na_values": ["#N/A", "#N/A N/A", "#NA", "-NA", "#NULL!", "#NUM!", "#DIV/0!", "#VALUE!", "#REF!", "#NAME?", "#DIV/0", "#NUM", "#REF", "#VALUE"], "engine": "openpyxl", "parse_dates": true}} - Details: {"source_name": "ExcelConnector", "params": {"sheet_name": "Loading...", "header": 0, "nrows": 50, "na_values": ["#N/A", "#N/A N/A", "#NA", "-NA", "#NULL!", "#NUM!", "#DIV/0!", "#VALUE!", "#REF!", "#NAME?", "#DIV/0", "#NUM", "#REF", "#VALUE"], "engine": "openpyxl", "parse_dates": true}}
2025-05-23 08:43:33,708 - error_handler - CRITICAL - TypeError: Object of type QByteArray is not JSON serializable
2025-05-23 08:43:34,611 - __main__ - ERROR - ERROR: Object of type QByteArray is not JSON serializable
2025-05-23 08:44:01,241 - data_integration.connectors.excel_connector - ERROR - Error loading Excel file C:\Users\luria\PycharmProjects\AuditQAStudio2\test_data\audit_workpapers_2025Q2.xlsx: Error executing read_excel: Worksheet named 'Loading...' not found - Details: {"function": "read_excel", "args": "('C:\\\\Users\\\\luria\\\\PycharmProjects\\\\AuditQAStudio2\\\\test_data\\\\audit_workpapers_2025Q2.xlsx',)", "kwargs": {"sheet_name": "Loading...", "header": 0, "nrows": 50, "na_values": ["#N/A", "#N/A N/A", "#NA", "-NA", "#NULL!", "#NUM!", "#DIV/0!", "#VALUE!", "#REF!", "#NAME?", "#DIV/0", "#NUM", "#REF", "#VALUE"], "engine": "openpyxl", "parse_dates": true}}
2025-05-23 08:44:01,241 - data_integration.errors.error_handler - ERROR - Failed to load data from ExcelConnector: Error executing read_excel: Worksheet named 'Loading...' not found - Details: {"function": "read_excel", "args": "('C:\\\\Users\\\\luria\\\\PycharmProjects\\\\AuditQAStudio2\\\\test_data\\\\audit_workpapers_2025Q2.xlsx',)", "kwargs": {"sheet_name": "Loading...", "header": 0, "nrows": 50, "na_values": ["#N/A", "#N/A N/A", "#NA", "-NA", "#NULL!", "#NUM!", "#DIV/0!", "#VALUE!", "#REF!", "#NAME?", "#DIV/0", "#NUM", "#REF", "#VALUE"], "engine": "openpyxl", "parse_dates": true}} - Details: {"source_name": "ExcelConnector", "params": {"sheet_name": "Loading...", "header": 0, "nrows": 50, "na_values": ["#N/A", "#N/A N/A", "#NA", "-NA", "#NULL!", "#NUM!", "#DIV/0!", "#VALUE!", "#REF!", "#NAME?", "#DIV/0", "#NUM", "#REF", "#VALUE"], "engine": "openpyxl", "parse_dates": true}}
Traceback (most recent call last):
  File "C:\Users\luria\PycharmProjects\QAStudiov3\data_integration\errors\error_handler.py", line 328, in safe_dataframe_operation
    return func(*args, **kwargs)
           ^^^^^^^^^^^^^^^^^^^^^
  File "C:\Users\luria\PycharmProjects\QAStudiov3\.venv\Lib\site-packages\pandas\io\excel\_base.py", line 508, in read_excel
    data = io.parse(
           ^^^^^^^^^
  File "C:\Users\luria\PycharmProjects\QAStudiov3\.venv\Lib\site-packages\pandas\io\excel\_base.py", line 1616, in parse
    return self._reader.parse(
           ^^^^^^^^^^^^^^^^^^^
  File "C:\Users\luria\PycharmProjects\QAStudiov3\.venv\Lib\site-packages\pandas\io\excel\_base.py", line 773, in parse
    sheet = self.get_sheet_by_name(asheetname)
            ^^^^^^^^^^^^^^^^^^^^^^^^^^^^^^^^^^
  File "C:\Users\luria\PycharmProjects\QAStudiov3\.venv\Lib\site-packages\pandas\io\excel\_openpyxl.py", line 582, in get_sheet_by_name
    self.raise_if_bad_sheet_by_name(name)
  File "C:\Users\luria\PycharmProjects\QAStudiov3\.venv\Lib\site-packages\pandas\io\excel\_base.py", line 624, in raise_if_bad_sheet_by_name
    raise ValueError(f"Worksheet named '{name}' not found")
ValueError: Worksheet named 'Loading...' not found

During handling of the above exception, another exception occurred:

Traceback (most recent call last):
  File "C:\Users\luria\PycharmProjects\QAStudiov3\data_integration\connectors\excel_connector.py", line 195, in get_data
    df = retry_operation(
         ^^^^^^^^^^^^^^^^
  File "C:\Users\luria\PycharmProjects\QAStudiov3\data_integration\errors\error_handler.py", line 379, in retry_operation
    return func(*args, **kwargs)
           ^^^^^^^^^^^^^^^^^^^^^
  File "C:\Users\luria\PycharmProjects\QAStudiov3\data_integration\connectors\excel_connector.py", line 183, in load_excel
    return safe_dataframe_operation(
           ^^^^^^^^^^^^^^^^^^^^^^^^^
  File "C:\Users\luria\PycharmProjects\QAStudiov3\data_integration\errors\error_handler.py", line 344, in safe_dataframe_operation
    raise DataIntegrationError(error_msg, details)
data_integration.errors.error_handler.DataIntegrationError: Error executing read_excel: Worksheet named 'Loading...' not found - Details: {"function": "read_excel", "args": "('C:\\\\Users\\\\luria\\\\PycharmProjects\\\\AuditQAStudio2\\\\test_data\\\\audit_workpapers_2025Q2.xlsx',)", "kwargs": {"sheet_name": "Loading...", "header": 0, "nrows": 50, "na_values": ["#N/A", "#N/A N/A", "#NA", "-NA", "#NULL!", "#NUM!", "#DIV/0!", "#VALUE!", "#REF!", "#NAME?", "#DIV/0", "#NUM", "#REF", "#VALUE"], "engine": "openpyxl", "parse_dates": true}}
2025-05-23 08:44:01,244 - data_integration.io.importer - ERROR - Error previewing file C:\Users\luria\PycharmProjects\AuditQAStudio2\test_data\audit_workpapers_2025Q2.xlsx: Failed to load data from ExcelConnector: Error executing read_excel: Worksheet named 'Loading...' not found - Details: {"function": "read_excel", "args": "('C:\\\\Users\\\\luria\\\\PycharmProjects\\\\AuditQAStudio2\\\\test_data\\\\audit_workpapers_2025Q2.xlsx',)", "kwargs": {"sheet_name": "Loading...", "header": 0, "nrows": 50, "na_values": ["#N/A", "#N/A N/A", "#NA", "-NA", "#NULL!", "#NUM!", "#DIV/0!", "#VALUE!", "#REF!", "#NAME?", "#DIV/0", "#NUM", "#REF", "#VALUE"], "engine": "openpyxl", "parse_dates": true}} - Details: {"source_name": "ExcelConnector", "params": {"sheet_name": "Loading...", "header": 0, "nrows": 50, "na_values": ["#N/A", "#N/A N/A", "#NA", "-NA", "#NULL!", "#NUM!", "#DIV/0!", "#VALUE!", "#REF!", "#NAME?", "#DIV/0", "#NUM", "#REF", "#VALUE"], "engine": "openpyxl", "parse_dates": true}}
2025-05-23 08:44:01,244 - data_source_panel - ERROR - Error loading file preview: Failed to load data from ExcelConnector: Error executing read_excel: Worksheet named 'Loading...' not found - Details: {"function": "read_excel", "args": "('C:\\\\Users\\\\luria\\\\PycharmProjects\\\\AuditQAStudio2\\\\test_data\\\\audit_workpapers_2025Q2.xlsx',)", "kwargs": {"sheet_name": "Loading...", "header": 0, "nrows": 50, "na_values": ["#N/A", "#N/A N/A", "#NA", "-NA", "#NULL!", "#NUM!", "#DIV/0!", "#VALUE!", "#REF!", "#NAME?", "#DIV/0", "#NUM", "#REF", "#VALUE"], "engine": "openpyxl", "parse_dates": true}} - Details: {"source_name": "ExcelConnector", "params": {"sheet_name": "Loading...", "header": 0, "nrows": 50, "na_values": ["#N/A", "#N/A N/A", "#NA", "-NA", "#NULL!", "#NUM!", "#DIV/0!", "#VALUE!", "#REF!", "#NAME?", "#DIV/0", "#NUM", "#REF", "#VALUE"], "engine": "openpyxl", "parse_dates": true}}
2025-05-23 08:44:01,250 - data_source_panel - ERROR - Preview error: Error loading file preview: Failed to load data from ExcelConnector: Error executing read_excel: Worksheet named 'Loading...' not found - Details: {"function": "read_excel", "args": "('C:\\\\Users\\\\luria\\\\PycharmProjects\\\\AuditQAStudio2\\\\test_data\\\\audit_workpapers_2025Q2.xlsx',)", "kwargs": {"sheet_name": "Loading...", "header": 0, "nrows": 50, "na_values": ["#N/A", "#N/A N/A", "#NA", "-NA", "#NULL!", "#NUM!", "#DIV/0!", "#VALUE!", "#REF!", "#NAME?", "#DIV/0", "#NUM", "#REF", "#VALUE"], "engine": "openpyxl", "parse_dates": true}} - Details: {"source_name": "ExcelConnector", "params": {"sheet_name": "Loading...", "header": 0, "nrows": 50, "na_values": ["#N/A", "#N/A N/A", "#NA", "-NA", "#NULL!", "#NUM!", "#DIV/0!", "#VALUE!", "#REF!", "#NAME?", "#DIV/0", "#NUM", "#REF", "#VALUE"], "engine": "openpyxl", "parse_dates": true}}
2025-05-23 08:46:31,383 - error_handler - CRITICAL - TypeError: Object of type QByteArray is not JSON serializable
2025-05-23 08:46:32,268 - __main__ - ERROR - ERROR: Object of type QByteArray is not JSON serializable
2025-05-23 09:29:31,904 - data_integration.connectors.excel_connector - ERROR - Error loading Excel file C:\Users\luria\PycharmProjects\AuditQAStudio2\test_data\audit_workpapers_2025Q2.xlsx: Error executing read_excel: Worksheet named 'Loading...' not found - Details: {"function": "read_excel", "args": "('C:\\\\Users\\\\luria\\\\PycharmProjects\\\\AuditQAStudio2\\\\test_data\\\\audit_workpapers_2025Q2.xlsx',)", "kwargs": {"sheet_name": "Loading...", "header": 0, "nrows": 50, "na_values": ["#N/A", "#N/A N/A", "#NA", "-NA", "#NULL!", "#NUM!", "#DIV/0!", "#VALUE!", "#REF!", "#NAME?", "#DIV/0", "#NUM", "#REF", "#VALUE"], "engine": "openpyxl", "parse_dates": true}}
2025-05-23 09:29:31,904 - data_integration.errors.error_handler - ERROR - Failed to load data from ExcelConnector: Error executing read_excel: Worksheet named 'Loading...' not found - Details: {"function": "read_excel", "args": "('C:\\\\Users\\\\luria\\\\PycharmProjects\\\\AuditQAStudio2\\\\test_data\\\\audit_workpapers_2025Q2.xlsx',)", "kwargs": {"sheet_name": "Loading...", "header": 0, "nrows": 50, "na_values": ["#N/A", "#N/A N/A", "#NA", "-NA", "#NULL!", "#NUM!", "#DIV/0!", "#VALUE!", "#REF!", "#NAME?", "#DIV/0", "#NUM", "#REF", "#VALUE"], "engine": "openpyxl", "parse_dates": true}} - Details: {"source_name": "ExcelConnector", "params": {"sheet_name": "Loading...", "header": 0, "nrows": 50, "na_values": ["#N/A", "#N/A N/A", "#NA", "-NA", "#NULL!", "#NUM!", "#DIV/0!", "#VALUE!", "#REF!", "#NAME?", "#DIV/0", "#NUM", "#REF", "#VALUE"], "engine": "openpyxl", "parse_dates": true}}
Traceback (most recent call last):
  File "C:\Users\luria\PycharmProjects\QAStudiov3\data_integration\errors\error_handler.py", line 328, in safe_dataframe_operation
    return func(*args, **kwargs)
           ^^^^^^^^^^^^^^^^^^^^^
  File "C:\Users\luria\PycharmProjects\QAStudiov3\.venv\Lib\site-packages\pandas\io\excel\_base.py", line 508, in read_excel
    data = io.parse(
           ^^^^^^^^^
  File "C:\Users\luria\PycharmProjects\QAStudiov3\.venv\Lib\site-packages\pandas\io\excel\_base.py", line 1616, in parse
    return self._reader.parse(
           ^^^^^^^^^^^^^^^^^^^
  File "C:\Users\luria\PycharmProjects\QAStudiov3\.venv\Lib\site-packages\pandas\io\excel\_base.py", line 773, in parse
    sheet = self.get_sheet_by_name(asheetname)
            ^^^^^^^^^^^^^^^^^^^^^^^^^^^^^^^^^^
  File "C:\Users\luria\PycharmProjects\QAStudiov3\.venv\Lib\site-packages\pandas\io\excel\_openpyxl.py", line 582, in get_sheet_by_name
    self.raise_if_bad_sheet_by_name(name)
  File "C:\Users\luria\PycharmProjects\QAStudiov3\.venv\Lib\site-packages\pandas\io\excel\_base.py", line 624, in raise_if_bad_sheet_by_name
    raise ValueError(f"Worksheet named '{name}' not found")
ValueError: Worksheet named 'Loading...' not found

During handling of the above exception, another exception occurred:

Traceback (most recent call last):
  File "C:\Users\luria\PycharmProjects\QAStudiov3\data_integration\connectors\excel_connector.py", line 195, in get_data
    df = retry_operation(
         ^^^^^^^^^^^^^^^^
  File "C:\Users\luria\PycharmProjects\QAStudiov3\data_integration\errors\error_handler.py", line 379, in retry_operation
    return func(*args, **kwargs)
           ^^^^^^^^^^^^^^^^^^^^^
  File "C:\Users\luria\PycharmProjects\QAStudiov3\data_integration\connectors\excel_connector.py", line 183, in load_excel
    return safe_dataframe_operation(
           ^^^^^^^^^^^^^^^^^^^^^^^^^
  File "C:\Users\luria\PycharmProjects\QAStudiov3\data_integration\errors\error_handler.py", line 344, in safe_dataframe_operation
    raise DataIntegrationError(error_msg, details)
data_integration.errors.error_handler.DataIntegrationError: Error executing read_excel: Worksheet named 'Loading...' not found - Details: {"function": "read_excel", "args": "('C:\\\\Users\\\\luria\\\\PycharmProjects\\\\AuditQAStudio2\\\\test_data\\\\audit_workpapers_2025Q2.xlsx',)", "kwargs": {"sheet_name": "Loading...", "header": 0, "nrows": 50, "na_values": ["#N/A", "#N/A N/A", "#NA", "-NA", "#NULL!", "#NUM!", "#DIV/0!", "#VALUE!", "#REF!", "#NAME?", "#DIV/0", "#NUM", "#REF", "#VALUE"], "engine": "openpyxl", "parse_dates": true}}
2025-05-23 09:29:31,907 - data_integration.io.importer - ERROR - Error previewing file C:\Users\luria\PycharmProjects\AuditQAStudio2\test_data\audit_workpapers_2025Q2.xlsx: Failed to load data from ExcelConnector: Error executing read_excel: Worksheet named 'Loading...' not found - Details: {"function": "read_excel", "args": "('C:\\\\Users\\\\luria\\\\PycharmProjects\\\\AuditQAStudio2\\\\test_data\\\\audit_workpapers_2025Q2.xlsx',)", "kwargs": {"sheet_name": "Loading...", "header": 0, "nrows": 50, "na_values": ["#N/A", "#N/A N/A", "#NA", "-NA", "#NULL!", "#NUM!", "#DIV/0!", "#VALUE!", "#REF!", "#NAME?", "#DIV/0", "#NUM", "#REF", "#VALUE"], "engine": "openpyxl", "parse_dates": true}} - Details: {"source_name": "ExcelConnector", "params": {"sheet_name": "Loading...", "header": 0, "nrows": 50, "na_values": ["#N/A", "#N/A N/A", "#NA", "-NA", "#NULL!", "#NUM!", "#DIV/0!", "#VALUE!", "#REF!", "#NAME?", "#DIV/0", "#NUM", "#REF", "#VALUE"], "engine": "openpyxl", "parse_dates": true}}
2025-05-23 09:29:31,907 - data_source_panel - ERROR - Error loading file preview: Failed to load data from ExcelConnector: Error executing read_excel: Worksheet named 'Loading...' not found - Details: {"function": "read_excel", "args": "('C:\\\\Users\\\\luria\\\\PycharmProjects\\\\AuditQAStudio2\\\\test_data\\\\audit_workpapers_2025Q2.xlsx',)", "kwargs": {"sheet_name": "Loading...", "header": 0, "nrows": 50, "na_values": ["#N/A", "#N/A N/A", "#NA", "-NA", "#NULL!", "#NUM!", "#DIV/0!", "#VALUE!", "#REF!", "#NAME?", "#DIV/0", "#NUM", "#REF", "#VALUE"], "engine": "openpyxl", "parse_dates": true}} - Details: {"source_name": "ExcelConnector", "params": {"sheet_name": "Loading...", "header": 0, "nrows": 50, "na_values": ["#N/A", "#N/A N/A", "#NA", "-NA", "#NULL!", "#NUM!", "#DIV/0!", "#VALUE!", "#REF!", "#NAME?", "#DIV/0", "#NUM", "#REF", "#VALUE"], "engine": "openpyxl", "parse_dates": true}}
2025-05-23 09:29:31,914 - data_source_panel - ERROR - Preview error: Error loading file preview: Failed to load data from ExcelConnector: Error executing read_excel: Worksheet named 'Loading...' not found - Details: {"function": "read_excel", "args": "('C:\\\\Users\\\\luria\\\\PycharmProjects\\\\AuditQAStudio2\\\\test_data\\\\audit_workpapers_2025Q2.xlsx',)", "kwargs": {"sheet_name": "Loading...", "header": 0, "nrows": 50, "na_values": ["#N/A", "#N/A N/A", "#NA", "-NA", "#NULL!", "#NUM!", "#DIV/0!", "#VALUE!", "#REF!", "#NAME?", "#DIV/0", "#NUM", "#REF", "#VALUE"], "engine": "openpyxl", "parse_dates": true}} - Details: {"source_name": "ExcelConnector", "params": {"sheet_name": "Loading...", "header": 0, "nrows": 50, "na_values": ["#N/A", "#N/A N/A", "#NA", "-NA", "#NULL!", "#NUM!", "#DIV/0!", "#VALUE!", "#REF!", "#NAME?", "#DIV/0", "#NUM", "#REF", "#VALUE"], "engine": "openpyxl", "parse_dates": true}}
2025-05-23 09:31:59,049 - error_handler - CRITICAL - TypeError: Object of type QByteArray is not JSON serializable
2025-05-23 09:32:00,006 - __main__ - ERROR - ERROR: Object of type QByteArray is not JSON serializable
2025-05-23 09:34:56,670 - error_handler - ERROR - AttributeError: 'PreValidationWidget' object has no attribute 'proceed_button'
2025-05-23 09:35:05,352 - error_handler - CRITICAL - AttributeError: 'AnalyticsRunnerApp' object has no attribute 'log_view'
2025-05-23 09:35:08,964 - error_handler - ERROR - AttributeError: 'PreValidationWidget' object has no attribute 'proceed_button'
2025-05-23 09:35:28,821 - error_handler - CRITICAL - AttributeError: 'AnalyticsRunnerApp' object has no attribute 'log_view'
2025-05-23 09:38:45,874 - error_handler - ERROR - AttributeError: 'PreValidationWidget' object has no attribute 'proceedRequested'
2025-05-23 09:38:56,969 - error_handler - CRITICAL - AttributeError: 'AnalyticsRunnerApp' object has no attribute 'log_view'
2025-05-23 09:39:02,106 - error_handler - ERROR - AttributeError: 'PreValidationWidget' object has no attribute 'proceedRequested'
2025-05-23 09:39:19,281 - error_handler - CRITICAL - AttributeError: 'AnalyticsRunnerApp' object has no attribute 'log_view'
2025-05-23 09:41:39,896 - data_integration.connectors.excel_connector - ERROR - Error loading Excel file C:\Users\luria\PycharmProjects\AuditQAStudio2\test_data\audit_workpapers_2025Q2.xlsx: Error executing read_excel: Worksheet named 'Loading...' not found - Details: {"function": "read_excel", "args": "('C:\\\\Users\\\\luria\\\\PycharmProjects\\\\AuditQAStudio2\\\\test_data\\\\audit_workpapers_2025Q2.xlsx',)", "kwargs": {"sheet_name": "Loading...", "header": 0, "nrows": 50, "na_values": ["#N/A", "#N/A N/A", "#NA", "-NA", "#NULL!", "#NUM!", "#DIV/0!", "#VALUE!", "#REF!", "#NAME?", "#DIV/0", "#NUM", "#REF", "#VALUE"], "engine": "openpyxl", "parse_dates": true}}
2025-05-23 09:41:39,896 - data_integration.errors.error_handler - ERROR - Failed to load data from ExcelConnector: Error executing read_excel: Worksheet named 'Loading...' not found - Details: {"function": "read_excel", "args": "('C:\\\\Users\\\\luria\\\\PycharmProjects\\\\AuditQAStudio2\\\\test_data\\\\audit_workpapers_2025Q2.xlsx',)", "kwargs": {"sheet_name": "Loading...", "header": 0, "nrows": 50, "na_values": ["#N/A", "#N/A N/A", "#NA", "-NA", "#NULL!", "#NUM!", "#DIV/0!", "#VALUE!", "#REF!", "#NAME?", "#DIV/0", "#NUM", "#REF", "#VALUE"], "engine": "openpyxl", "parse_dates": true}} - Details: {"source_name": "ExcelConnector", "params": {"sheet_name": "Loading...", "header": 0, "nrows": 50, "na_values": ["#N/A", "#N/A N/A", "#NA", "-NA", "#NULL!", "#NUM!", "#DIV/0!", "#VALUE!", "#REF!", "#NAME?", "#DIV/0", "#NUM", "#REF", "#VALUE"], "engine": "openpyxl", "parse_dates": true}}
Traceback (most recent call last):
  File "C:\Users\luria\PycharmProjects\QAStudiov3\data_integration\errors\error_handler.py", line 328, in safe_dataframe_operation
    return func(*args, **kwargs)
           ^^^^^^^^^^^^^^^^^^^^^
  File "C:\Users\luria\PycharmProjects\QAStudiov3\.venv\Lib\site-packages\pandas\io\excel\_base.py", line 508, in read_excel
    data = io.parse(
           ^^^^^^^^^
  File "C:\Users\luria\PycharmProjects\QAStudiov3\.venv\Lib\site-packages\pandas\io\excel\_base.py", line 1616, in parse
    return self._reader.parse(
           ^^^^^^^^^^^^^^^^^^^
  File "C:\Users\luria\PycharmProjects\QAStudiov3\.venv\Lib\site-packages\pandas\io\excel\_base.py", line 773, in parse
    sheet = self.get_sheet_by_name(asheetname)
            ^^^^^^^^^^^^^^^^^^^^^^^^^^^^^^^^^^
  File "C:\Users\luria\PycharmProjects\QAStudiov3\.venv\Lib\site-packages\pandas\io\excel\_openpyxl.py", line 582, in get_sheet_by_name
    self.raise_if_bad_sheet_by_name(name)
  File "C:\Users\luria\PycharmProjects\QAStudiov3\.venv\Lib\site-packages\pandas\io\excel\_base.py", line 624, in raise_if_bad_sheet_by_name
    raise ValueError(f"Worksheet named '{name}' not found")
ValueError: Worksheet named 'Loading...' not found

During handling of the above exception, another exception occurred:

Traceback (most recent call last):
  File "C:\Users\luria\PycharmProjects\QAStudiov3\data_integration\connectors\excel_connector.py", line 195, in get_data
    df = retry_operation(
         ^^^^^^^^^^^^^^^^
  File "C:\Users\luria\PycharmProjects\QAStudiov3\data_integration\errors\error_handler.py", line 379, in retry_operation
    return func(*args, **kwargs)
           ^^^^^^^^^^^^^^^^^^^^^
  File "C:\Users\luria\PycharmProjects\QAStudiov3\data_integration\connectors\excel_connector.py", line 183, in load_excel
    return safe_dataframe_operation(
           ^^^^^^^^^^^^^^^^^^^^^^^^^
  File "C:\Users\luria\PycharmProjects\QAStudiov3\data_integration\errors\error_handler.py", line 344, in safe_dataframe_operation
    raise DataIntegrationError(error_msg, details)
data_integration.errors.error_handler.DataIntegrationError: Error executing read_excel: Worksheet named 'Loading...' not found - Details: {"function": "read_excel", "args": "('C:\\\\Users\\\\luria\\\\PycharmProjects\\\\AuditQAStudio2\\\\test_data\\\\audit_workpapers_2025Q2.xlsx',)", "kwargs": {"sheet_name": "Loading...", "header": 0, "nrows": 50, "na_values": ["#N/A", "#N/A N/A", "#NA", "-NA", "#NULL!", "#NUM!", "#DIV/0!", "#VALUE!", "#REF!", "#NAME?", "#DIV/0", "#NUM", "#REF", "#VALUE"], "engine": "openpyxl", "parse_dates": true}}
2025-05-23 09:41:39,898 - data_integration.io.importer - ERROR - Error previewing file C:\Users\luria\PycharmProjects\AuditQAStudio2\test_data\audit_workpapers_2025Q2.xlsx: Failed to load data from ExcelConnector: Error executing read_excel: Worksheet named 'Loading...' not found - Details: {"function": "read_excel", "args": "('C:\\\\Users\\\\luria\\\\PycharmProjects\\\\AuditQAStudio2\\\\test_data\\\\audit_workpapers_2025Q2.xlsx',)", "kwargs": {"sheet_name": "Loading...", "header": 0, "nrows": 50, "na_values": ["#N/A", "#N/A N/A", "#NA", "-NA", "#NULL!", "#NUM!", "#DIV/0!", "#VALUE!", "#REF!", "#NAME?", "#DIV/0", "#NUM", "#REF", "#VALUE"], "engine": "openpyxl", "parse_dates": true}} - Details: {"source_name": "ExcelConnector", "params": {"sheet_name": "Loading...", "header": 0, "nrows": 50, "na_values": ["#N/A", "#N/A N/A", "#NA", "-NA", "#NULL!", "#NUM!", "#DIV/0!", "#VALUE!", "#REF!", "#NAME?", "#DIV/0", "#NUM", "#REF", "#VALUE"], "engine": "openpyxl", "parse_dates": true}}
2025-05-23 09:41:39,898 - data_source_panel - ERROR - Error loading file preview: Failed to load data from ExcelConnector: Error executing read_excel: Worksheet named 'Loading...' not found - Details: {"function": "read_excel", "args": "('C:\\\\Users\\\\luria\\\\PycharmProjects\\\\AuditQAStudio2\\\\test_data\\\\audit_workpapers_2025Q2.xlsx',)", "kwargs": {"sheet_name": "Loading...", "header": 0, "nrows": 50, "na_values": ["#N/A", "#N/A N/A", "#NA", "-NA", "#NULL!", "#NUM!", "#DIV/0!", "#VALUE!", "#REF!", "#NAME?", "#DIV/0", "#NUM", "#REF", "#VALUE"], "engine": "openpyxl", "parse_dates": true}} - Details: {"source_name": "ExcelConnector", "params": {"sheet_name": "Loading...", "header": 0, "nrows": 50, "na_values": ["#N/A", "#N/A N/A", "#NA", "-NA", "#NULL!", "#NUM!", "#DIV/0!", "#VALUE!", "#REF!", "#NAME?", "#DIV/0", "#NUM", "#REF", "#VALUE"], "engine": "openpyxl", "parse_dates": true}}
2025-05-23 09:41:39,902 - data_source_panel - ERROR - Preview error: Error loading file preview: Failed to load data from ExcelConnector: Error executing read_excel: Worksheet named 'Loading...' not found - Details: {"function": "read_excel", "args": "('C:\\\\Users\\\\luria\\\\PycharmProjects\\\\AuditQAStudio2\\\\test_data\\\\audit_workpapers_2025Q2.xlsx',)", "kwargs": {"sheet_name": "Loading...", "header": 0, "nrows": 50, "na_values": ["#N/A", "#N/A N/A", "#NA", "-NA", "#NULL!", "#NUM!", "#DIV/0!", "#VALUE!", "#REF!", "#NAME?", "#DIV/0", "#NUM", "#REF", "#VALUE"], "engine": "openpyxl", "parse_dates": true}} - Details: {"source_name": "ExcelConnector", "params": {"sheet_name": "Loading...", "header": 0, "nrows": 50, "na_values": ["#N/A", "#N/A N/A", "#NA", "-NA", "#NULL!", "#NUM!", "#DIV/0!", "#VALUE!", "#REF!", "#NAME?", "#DIV/0", "#NUM", "#REF", "#VALUE"], "engine": "openpyxl", "parse_dates": true}}
2025-05-23 09:42:11,621 - error_handler - CRITICAL - TypeError: Object of type QByteArray is not JSON serializable
2025-05-23 09:42:13,210 - __main__ - ERROR - ERROR: Object of type QByteArray is not JSON serializable
2025-05-23 09:48:38,954 - data_integration.connectors.excel_connector - ERROR - Error loading Excel file C:\Users\luria\PycharmProjects\AuditQAStudio2\test_data\audit_workpapers_2025Q2.xlsx: Error executing read_excel: Worksheet named 'Loading...' not found - Details: {"function": "read_excel", "args": "('C:\\\\Users\\\\luria\\\\PycharmProjects\\\\AuditQAStudio2\\\\test_data\\\\audit_workpapers_2025Q2.xlsx',)", "kwargs": {"sheet_name": "Loading...", "header": 0, "nrows": 50, "na_values": ["#N/A", "#N/A N/A", "#NA", "-NA", "#NULL!", "#NUM!", "#DIV/0!", "#VALUE!", "#REF!", "#NAME?", "#DIV/0", "#NUM", "#REF", "#VALUE"], "engine": "openpyxl", "parse_dates": true}}
2025-05-23 09:48:38,954 - data_integration.errors.error_handler - ERROR - Failed to load data from ExcelConnector: Error executing read_excel: Worksheet named 'Loading...' not found - Details: {"function": "read_excel", "args": "('C:\\\\Users\\\\luria\\\\PycharmProjects\\\\AuditQAStudio2\\\\test_data\\\\audit_workpapers_2025Q2.xlsx',)", "kwargs": {"sheet_name": "Loading...", "header": 0, "nrows": 50, "na_values": ["#N/A", "#N/A N/A", "#NA", "-NA", "#NULL!", "#NUM!", "#DIV/0!", "#VALUE!", "#REF!", "#NAME?", "#DIV/0", "#NUM", "#REF", "#VALUE"], "engine": "openpyxl", "parse_dates": true}} - Details: {"source_name": "ExcelConnector", "params": {"sheet_name": "Loading...", "header": 0, "nrows": 50, "na_values": ["#N/A", "#N/A N/A", "#NA", "-NA", "#NULL!", "#NUM!", "#DIV/0!", "#VALUE!", "#REF!", "#NAME?", "#DIV/0", "#NUM", "#REF", "#VALUE"], "engine": "openpyxl", "parse_dates": true}}
Traceback (most recent call last):
  File "C:\Users\luria\PycharmProjects\QAStudiov3\data_integration\errors\error_handler.py", line 328, in safe_dataframe_operation
    return func(*args, **kwargs)
           ^^^^^^^^^^^^^^^^^^^^^
  File "C:\Users\luria\PycharmProjects\QAStudiov3\.venv\Lib\site-packages\pandas\io\excel\_base.py", line 508, in read_excel
    data = io.parse(
           ^^^^^^^^^
  File "C:\Users\luria\PycharmProjects\QAStudiov3\.venv\Lib\site-packages\pandas\io\excel\_base.py", line 1616, in parse
    return self._reader.parse(
           ^^^^^^^^^^^^^^^^^^^
  File "C:\Users\luria\PycharmProjects\QAStudiov3\.venv\Lib\site-packages\pandas\io\excel\_base.py", line 773, in parse
    sheet = self.get_sheet_by_name(asheetname)
            ^^^^^^^^^^^^^^^^^^^^^^^^^^^^^^^^^^
  File "C:\Users\luria\PycharmProjects\QAStudiov3\.venv\Lib\site-packages\pandas\io\excel\_openpyxl.py", line 582, in get_sheet_by_name
    self.raise_if_bad_sheet_by_name(name)
  File "C:\Users\luria\PycharmProjects\QAStudiov3\.venv\Lib\site-packages\pandas\io\excel\_base.py", line 624, in raise_if_bad_sheet_by_name
    raise ValueError(f"Worksheet named '{name}' not found")
ValueError: Worksheet named 'Loading...' not found

During handling of the above exception, another exception occurred:

Traceback (most recent call last):
  File "C:\Users\luria\PycharmProjects\QAStudiov3\data_integration\connectors\excel_connector.py", line 195, in get_data
    df = retry_operation(
         ^^^^^^^^^^^^^^^^
  File "C:\Users\luria\PycharmProjects\QAStudiov3\data_integration\errors\error_handler.py", line 379, in retry_operation
    return func(*args, **kwargs)
           ^^^^^^^^^^^^^^^^^^^^^
  File "C:\Users\luria\PycharmProjects\QAStudiov3\data_integration\connectors\excel_connector.py", line 183, in load_excel
    return safe_dataframe_operation(
           ^^^^^^^^^^^^^^^^^^^^^^^^^
  File "C:\Users\luria\PycharmProjects\QAStudiov3\data_integration\errors\error_handler.py", line 344, in safe_dataframe_operation
    raise DataIntegrationError(error_msg, details)
data_integration.errors.error_handler.DataIntegrationError: Error executing read_excel: Worksheet named 'Loading...' not found - Details: {"function": "read_excel", "args": "('C:\\\\Users\\\\luria\\\\PycharmProjects\\\\AuditQAStudio2\\\\test_data\\\\audit_workpapers_2025Q2.xlsx',)", "kwargs": {"sheet_name": "Loading...", "header": 0, "nrows": 50, "na_values": ["#N/A", "#N/A N/A", "#NA", "-NA", "#NULL!", "#NUM!", "#DIV/0!", "#VALUE!", "#REF!", "#NAME?", "#DIV/0", "#NUM", "#REF", "#VALUE"], "engine": "openpyxl", "parse_dates": true}}
2025-05-23 09:48:38,956 - data_integration.io.importer - ERROR - Error previewing file C:\Users\luria\PycharmProjects\AuditQAStudio2\test_data\audit_workpapers_2025Q2.xlsx: Failed to load data from ExcelConnector: Error executing read_excel: Worksheet named 'Loading...' not found - Details: {"function": "read_excel", "args": "('C:\\\\Users\\\\luria\\\\PycharmProjects\\\\AuditQAStudio2\\\\test_data\\\\audit_workpapers_2025Q2.xlsx',)", "kwargs": {"sheet_name": "Loading...", "header": 0, "nrows": 50, "na_values": ["#N/A", "#N/A N/A", "#NA", "-NA", "#NULL!", "#NUM!", "#DIV/0!", "#VALUE!", "#REF!", "#NAME?", "#DIV/0", "#NUM", "#REF", "#VALUE"], "engine": "openpyxl", "parse_dates": true}} - Details: {"source_name": "ExcelConnector", "params": {"sheet_name": "Loading...", "header": 0, "nrows": 50, "na_values": ["#N/A", "#N/A N/A", "#NA", "-NA", "#NULL!", "#NUM!", "#DIV/0!", "#VALUE!", "#REF!", "#NAME?", "#DIV/0", "#NUM", "#REF", "#VALUE"], "engine": "openpyxl", "parse_dates": true}}
2025-05-23 09:48:38,956 - data_source_panel - ERROR - Error loading file preview: Failed to load data from ExcelConnector: Error executing read_excel: Worksheet named 'Loading...' not found - Details: {"function": "read_excel", "args": "('C:\\\\Users\\\\luria\\\\PycharmProjects\\\\AuditQAStudio2\\\\test_data\\\\audit_workpapers_2025Q2.xlsx',)", "kwargs": {"sheet_name": "Loading...", "header": 0, "nrows": 50, "na_values": ["#N/A", "#N/A N/A", "#NA", "-NA", "#NULL!", "#NUM!", "#DIV/0!", "#VALUE!", "#REF!", "#NAME?", "#DIV/0", "#NUM", "#REF", "#VALUE"], "engine": "openpyxl", "parse_dates": true}} - Details: {"source_name": "ExcelConnector", "params": {"sheet_name": "Loading...", "header": 0, "nrows": 50, "na_values": ["#N/A", "#N/A N/A", "#NA", "-NA", "#NULL!", "#NUM!", "#DIV/0!", "#VALUE!", "#REF!", "#NAME?", "#DIV/0", "#NUM", "#REF", "#VALUE"], "engine": "openpyxl", "parse_dates": true}}
2025-05-23 09:48:38,963 - data_source_panel - ERROR - Preview error: Error loading file preview: Failed to load data from ExcelConnector: Error executing read_excel: Worksheet named 'Loading...' not found - Details: {"function": "read_excel", "args": "('C:\\\\Users\\\\luria\\\\PycharmProjects\\\\AuditQAStudio2\\\\test_data\\\\audit_workpapers_2025Q2.xlsx',)", "kwargs": {"sheet_name": "Loading...", "header": 0, "nrows": 50, "na_values": ["#N/A", "#N/A N/A", "#NA", "-NA", "#NULL!", "#NUM!", "#DIV/0!", "#VALUE!", "#REF!", "#NAME?", "#DIV/0", "#NUM", "#REF", "#VALUE"], "engine": "openpyxl", "parse_dates": true}} - Details: {"source_name": "ExcelConnector", "params": {"sheet_name": "Loading...", "header": 0, "nrows": 50, "na_values": ["#N/A", "#N/A N/A", "#NA", "-NA", "#NULL!", "#NUM!", "#DIV/0!", "#VALUE!", "#REF!", "#NAME?", "#DIV/0", "#NUM", "#REF", "#VALUE"], "engine": "openpyxl", "parse_dates": true}}
2025-05-23 09:50:24,005 - error_handler - CRITICAL - TypeError: Object of type QByteArray is not JSON serializable
2025-05-23 09:50:25,136 - __main__ - ERROR - ERROR: Object of type QByteArray is not JSON serializable
2025-05-23 09:57:58,900 - data_integration.connectors.excel_connector - ERROR - Error loading Excel file C:\Users\luria\PycharmProjects\AuditQAStudio2\test_data\audit_workpapers_2025Q2.xlsx: Error executing read_excel: Worksheet named 'Loading...' not found - Details: {"function": "read_excel", "args": "('C:\\\\Users\\\\luria\\\\PycharmProjects\\\\AuditQAStudio2\\\\test_data\\\\audit_workpapers_2025Q2.xlsx',)", "kwargs": {"sheet_name": "Loading...", "header": 0, "nrows": 50, "na_values": ["#N/A", "#N/A N/A", "#NA", "-NA", "#NULL!", "#NUM!", "#DIV/0!", "#VALUE!", "#REF!", "#NAME?", "#DIV/0", "#NUM", "#REF", "#VALUE"], "engine": "openpyxl", "parse_dates": true}}
2025-05-23 09:57:58,900 - data_integration.errors.error_handler - ERROR - Failed to load data from ExcelConnector: Error executing read_excel: Worksheet named 'Loading...' not found - Details: {"function": "read_excel", "args": "('C:\\\\Users\\\\luria\\\\PycharmProjects\\\\AuditQAStudio2\\\\test_data\\\\audit_workpapers_2025Q2.xlsx',)", "kwargs": {"sheet_name": "Loading...", "header": 0, "nrows": 50, "na_values": ["#N/A", "#N/A N/A", "#NA", "-NA", "#NULL!", "#NUM!", "#DIV/0!", "#VALUE!", "#REF!", "#NAME?", "#DIV/0", "#NUM", "#REF", "#VALUE"], "engine": "openpyxl", "parse_dates": true}} - Details: {"source_name": "ExcelConnector", "params": {"sheet_name": "Loading...", "header": 0, "nrows": 50, "na_values": ["#N/A", "#N/A N/A", "#NA", "-NA", "#NULL!", "#NUM!", "#DIV/0!", "#VALUE!", "#REF!", "#NAME?", "#DIV/0", "#NUM", "#REF", "#VALUE"], "engine": "openpyxl", "parse_dates": true}}
Traceback (most recent call last):
  File "C:\Users\luria\PycharmProjects\QAStudiov3\data_integration\errors\error_handler.py", line 328, in safe_dataframe_operation
    return func(*args, **kwargs)
           ^^^^^^^^^^^^^^^^^^^^^
  File "C:\Users\luria\PycharmProjects\QAStudiov3\.venv\Lib\site-packages\pandas\io\excel\_base.py", line 508, in read_excel
    data = io.parse(
           ^^^^^^^^^
  File "C:\Users\luria\PycharmProjects\QAStudiov3\.venv\Lib\site-packages\pandas\io\excel\_base.py", line 1616, in parse
    return self._reader.parse(
           ^^^^^^^^^^^^^^^^^^^
  File "C:\Users\luria\PycharmProjects\QAStudiov3\.venv\Lib\site-packages\pandas\io\excel\_base.py", line 773, in parse
    sheet = self.get_sheet_by_name(asheetname)
            ^^^^^^^^^^^^^^^^^^^^^^^^^^^^^^^^^^
  File "C:\Users\luria\PycharmProjects\QAStudiov3\.venv\Lib\site-packages\pandas\io\excel\_openpyxl.py", line 582, in get_sheet_by_name
    self.raise_if_bad_sheet_by_name(name)
  File "C:\Users\luria\PycharmProjects\QAStudiov3\.venv\Lib\site-packages\pandas\io\excel\_base.py", line 624, in raise_if_bad_sheet_by_name
    raise ValueError(f"Worksheet named '{name}' not found")
ValueError: Worksheet named 'Loading...' not found

During handling of the above exception, another exception occurred:

Traceback (most recent call last):
  File "C:\Users\luria\PycharmProjects\QAStudiov3\data_integration\connectors\excel_connector.py", line 195, in get_data
    df = retry_operation(
         ^^^^^^^^^^^^^^^^
  File "C:\Users\luria\PycharmProjects\QAStudiov3\data_integration\errors\error_handler.py", line 379, in retry_operation
    return func(*args, **kwargs)
           ^^^^^^^^^^^^^^^^^^^^^
  File "C:\Users\luria\PycharmProjects\QAStudiov3\data_integration\connectors\excel_connector.py", line 183, in load_excel
    return safe_dataframe_operation(
           ^^^^^^^^^^^^^^^^^^^^^^^^^
  File "C:\Users\luria\PycharmProjects\QAStudiov3\data_integration\errors\error_handler.py", line 344, in safe_dataframe_operation
    raise DataIntegrationError(error_msg, details)
data_integration.errors.error_handler.DataIntegrationError: Error executing read_excel: Worksheet named 'Loading...' not found - Details: {"function": "read_excel", "args": "('C:\\\\Users\\\\luria\\\\PycharmProjects\\\\AuditQAStudio2\\\\test_data\\\\audit_workpapers_2025Q2.xlsx',)", "kwargs": {"sheet_name": "Loading...", "header": 0, "nrows": 50, "na_values": ["#N/A", "#N/A N/A", "#NA", "-NA", "#NULL!", "#NUM!", "#DIV/0!", "#VALUE!", "#REF!", "#NAME?", "#DIV/0", "#NUM", "#REF", "#VALUE"], "engine": "openpyxl", "parse_dates": true}}
2025-05-23 09:57:58,904 - data_integration.io.importer - ERROR - Error previewing file C:\Users\luria\PycharmProjects\AuditQAStudio2\test_data\audit_workpapers_2025Q2.xlsx: Failed to load data from ExcelConnector: Error executing read_excel: Worksheet named 'Loading...' not found - Details: {"function": "read_excel", "args": "('C:\\\\Users\\\\luria\\\\PycharmProjects\\\\AuditQAStudio2\\\\test_data\\\\audit_workpapers_2025Q2.xlsx',)", "kwargs": {"sheet_name": "Loading...", "header": 0, "nrows": 50, "na_values": ["#N/A", "#N/A N/A", "#NA", "-NA", "#NULL!", "#NUM!", "#DIV/0!", "#VALUE!", "#REF!", "#NAME?", "#DIV/0", "#NUM", "#REF", "#VALUE"], "engine": "openpyxl", "parse_dates": true}} - Details: {"source_name": "ExcelConnector", "params": {"sheet_name": "Loading...", "header": 0, "nrows": 50, "na_values": ["#N/A", "#N/A N/A", "#NA", "-NA", "#NULL!", "#NUM!", "#DIV/0!", "#VALUE!", "#REF!", "#NAME?", "#DIV/0", "#NUM", "#REF", "#VALUE"], "engine": "openpyxl", "parse_dates": true}}
2025-05-23 09:57:58,904 - data_source_panel - ERROR - Error loading file preview: Failed to load data from ExcelConnector: Error executing read_excel: Worksheet named 'Loading...' not found - Details: {"function": "read_excel", "args": "('C:\\\\Users\\\\luria\\\\PycharmProjects\\\\AuditQAStudio2\\\\test_data\\\\audit_workpapers_2025Q2.xlsx',)", "kwargs": {"sheet_name": "Loading...", "header": 0, "nrows": 50, "na_values": ["#N/A", "#N/A N/A", "#NA", "-NA", "#NULL!", "#NUM!", "#DIV/0!", "#VALUE!", "#REF!", "#NAME?", "#DIV/0", "#NUM", "#REF", "#VALUE"], "engine": "openpyxl", "parse_dates": true}} - Details: {"source_name": "ExcelConnector", "params": {"sheet_name": "Loading...", "header": 0, "nrows": 50, "na_values": ["#N/A", "#N/A N/A", "#NA", "-NA", "#NULL!", "#NUM!", "#DIV/0!", "#VALUE!", "#REF!", "#NAME?", "#DIV/0", "#NUM", "#REF", "#VALUE"], "engine": "openpyxl", "parse_dates": true}}
2025-05-23 09:57:58,912 - data_source_panel - ERROR - Preview error: Error loading file preview: Failed to load data from ExcelConnector: Error executing read_excel: Worksheet named 'Loading...' not found - Details: {"function": "read_excel", "args": "('C:\\\\Users\\\\luria\\\\PycharmProjects\\\\AuditQAStudio2\\\\test_data\\\\audit_workpapers_2025Q2.xlsx',)", "kwargs": {"sheet_name": "Loading...", "header": 0, "nrows": 50, "na_values": ["#N/A", "#N/A N/A", "#NA", "-NA", "#NULL!", "#NUM!", "#DIV/0!", "#VALUE!", "#REF!", "#NAME?", "#DIV/0", "#NUM", "#REF", "#VALUE"], "engine": "openpyxl", "parse_dates": true}} - Details: {"source_name": "ExcelConnector", "params": {"sheet_name": "Loading...", "header": 0, "nrows": 50, "na_values": ["#N/A", "#N/A N/A", "#NA", "-NA", "#NULL!", "#NUM!", "#DIV/0!", "#VALUE!", "#REF!", "#NAME?", "#DIV/0", "#NUM", "#REF", "#VALUE"], "engine": "openpyxl", "parse_dates": true}}
2025-05-23 10:32:09,636 - error_handler - CRITICAL - TypeError: Object of type QByteArray is not JSON serializable
2025-05-23 10:32:10,662 - __main__ - ERROR - ERROR: Object of type QByteArray is not JSON serializable
2025-05-23 10:33:20,264 - data_integration.connectors.excel_connector - ERROR - Error loading Excel file C:\Users\luria\PycharmProjects\AuditQAStudio2\test_data\audit_workpapers_2025Q2.xlsx: Error executing read_excel: Worksheet named 'Loading...' not found - Details: {"function": "read_excel", "args": "('C:\\\\Users\\\\luria\\\\PycharmProjects\\\\AuditQAStudio2\\\\test_data\\\\audit_workpapers_2025Q2.xlsx',)", "kwargs": {"sheet_name": "Loading...", "header": 0, "nrows": 50, "na_values": ["#N/A", "#N/A N/A", "#NA", "-NA", "#NULL!", "#NUM!", "#DIV/0!", "#VALUE!", "#REF!", "#NAME?", "#DIV/0", "#NUM", "#REF", "#VALUE"], "engine": "openpyxl", "parse_dates": true}}
2025-05-23 10:33:20,264 - data_integration.errors.error_handler - ERROR - Failed to load data from ExcelConnector: Error executing read_excel: Worksheet named 'Loading...' not found - Details: {"function": "read_excel", "args": "('C:\\\\Users\\\\luria\\\\PycharmProjects\\\\AuditQAStudio2\\\\test_data\\\\audit_workpapers_2025Q2.xlsx',)", "kwargs": {"sheet_name": "Loading...", "header": 0, "nrows": 50, "na_values": ["#N/A", "#N/A N/A", "#NA", "-NA", "#NULL!", "#NUM!", "#DIV/0!", "#VALUE!", "#REF!", "#NAME?", "#DIV/0", "#NUM", "#REF", "#VALUE"], "engine": "openpyxl", "parse_dates": true}} - Details: {"source_name": "ExcelConnector", "params": {"sheet_name": "Loading...", "header": 0, "nrows": 50, "na_values": ["#N/A", "#N/A N/A", "#NA", "-NA", "#NULL!", "#NUM!", "#DIV/0!", "#VALUE!", "#REF!", "#NAME?", "#DIV/0", "#NUM", "#REF", "#VALUE"], "engine": "openpyxl", "parse_dates": true}}
Traceback (most recent call last):
  File "C:\Users\luria\PycharmProjects\QAStudiov3\data_integration\errors\error_handler.py", line 328, in safe_dataframe_operation
    return func(*args, **kwargs)
           ^^^^^^^^^^^^^^^^^^^^^
  File "C:\Users\luria\PycharmProjects\QAStudiov3\.venv\Lib\site-packages\pandas\io\excel\_base.py", line 508, in read_excel
    data = io.parse(
           ^^^^^^^^^
  File "C:\Users\luria\PycharmProjects\QAStudiov3\.venv\Lib\site-packages\pandas\io\excel\_base.py", line 1616, in parse
    return self._reader.parse(
           ^^^^^^^^^^^^^^^^^^^
  File "C:\Users\luria\PycharmProjects\QAStudiov3\.venv\Lib\site-packages\pandas\io\excel\_base.py", line 773, in parse
    sheet = self.get_sheet_by_name(asheetname)
            ^^^^^^^^^^^^^^^^^^^^^^^^^^^^^^^^^^
  File "C:\Users\luria\PycharmProjects\QAStudiov3\.venv\Lib\site-packages\pandas\io\excel\_openpyxl.py", line 582, in get_sheet_by_name
    self.raise_if_bad_sheet_by_name(name)
  File "C:\Users\luria\PycharmProjects\QAStudiov3\.venv\Lib\site-packages\pandas\io\excel\_base.py", line 624, in raise_if_bad_sheet_by_name
    raise ValueError(f"Worksheet named '{name}' not found")
ValueError: Worksheet named 'Loading...' not found

During handling of the above exception, another exception occurred:

Traceback (most recent call last):
  File "C:\Users\luria\PycharmProjects\QAStudiov3\data_integration\connectors\excel_connector.py", line 195, in get_data
    df = retry_operation(
         ^^^^^^^^^^^^^^^^
  File "C:\Users\luria\PycharmProjects\QAStudiov3\data_integration\errors\error_handler.py", line 379, in retry_operation
    return func(*args, **kwargs)
           ^^^^^^^^^^^^^^^^^^^^^
  File "C:\Users\luria\PycharmProjects\QAStudiov3\data_integration\connectors\excel_connector.py", line 183, in load_excel
    return safe_dataframe_operation(
           ^^^^^^^^^^^^^^^^^^^^^^^^^
  File "C:\Users\luria\PycharmProjects\QAStudiov3\data_integration\errors\error_handler.py", line 344, in safe_dataframe_operation
    raise DataIntegrationError(error_msg, details)
data_integration.errors.error_handler.DataIntegrationError: Error executing read_excel: Worksheet named 'Loading...' not found - Details: {"function": "read_excel", "args": "('C:\\\\Users\\\\luria\\\\PycharmProjects\\\\AuditQAStudio2\\\\test_data\\\\audit_workpapers_2025Q2.xlsx',)", "kwargs": {"sheet_name": "Loading...", "header": 0, "nrows": 50, "na_values": ["#N/A", "#N/A N/A", "#NA", "-NA", "#NULL!", "#NUM!", "#DIV/0!", "#VALUE!", "#REF!", "#NAME?", "#DIV/0", "#NUM", "#REF", "#VALUE"], "engine": "openpyxl", "parse_dates": true}}
2025-05-23 10:33:20,267 - data_integration.io.importer - ERROR - Error previewing file C:\Users\luria\PycharmProjects\AuditQAStudio2\test_data\audit_workpapers_2025Q2.xlsx: Failed to load data from ExcelConnector: Error executing read_excel: Worksheet named 'Loading...' not found - Details: {"function": "read_excel", "args": "('C:\\\\Users\\\\luria\\\\PycharmProjects\\\\AuditQAStudio2\\\\test_data\\\\audit_workpapers_2025Q2.xlsx',)", "kwargs": {"sheet_name": "Loading...", "header": 0, "nrows": 50, "na_values": ["#N/A", "#N/A N/A", "#NA", "-NA", "#NULL!", "#NUM!", "#DIV/0!", "#VALUE!", "#REF!", "#NAME?", "#DIV/0", "#NUM", "#REF", "#VALUE"], "engine": "openpyxl", "parse_dates": true}} - Details: {"source_name": "ExcelConnector", "params": {"sheet_name": "Loading...", "header": 0, "nrows": 50, "na_values": ["#N/A", "#N/A N/A", "#NA", "-NA", "#NULL!", "#NUM!", "#DIV/0!", "#VALUE!", "#REF!", "#NAME?", "#DIV/0", "#NUM", "#REF", "#VALUE"], "engine": "openpyxl", "parse_dates": true}}
2025-05-23 10:33:20,267 - data_source_panel - ERROR - Error loading file preview: Failed to load data from ExcelConnector: Error executing read_excel: Worksheet named 'Loading...' not found - Details: {"function": "read_excel", "args": "('C:\\\\Users\\\\luria\\\\PycharmProjects\\\\AuditQAStudio2\\\\test_data\\\\audit_workpapers_2025Q2.xlsx',)", "kwargs": {"sheet_name": "Loading...", "header": 0, "nrows": 50, "na_values": ["#N/A", "#N/A N/A", "#NA", "-NA", "#NULL!", "#NUM!", "#DIV/0!", "#VALUE!", "#REF!", "#NAME?", "#DIV/0", "#NUM", "#REF", "#VALUE"], "engine": "openpyxl", "parse_dates": true}} - Details: {"source_name": "ExcelConnector", "params": {"sheet_name": "Loading...", "header": 0, "nrows": 50, "na_values": ["#N/A", "#N/A N/A", "#NA", "-NA", "#NULL!", "#NUM!", "#DIV/0!", "#VALUE!", "#REF!", "#NAME?", "#DIV/0", "#NUM", "#REF", "#VALUE"], "engine": "openpyxl", "parse_dates": true}}
2025-05-23 10:33:20,272 - data_source_panel - ERROR - Preview error: Error loading file preview: Failed to load data from ExcelConnector: Error executing read_excel: Worksheet named 'Loading...' not found - Details: {"function": "read_excel", "args": "('C:\\\\Users\\\\luria\\\\PycharmProjects\\\\AuditQAStudio2\\\\test_data\\\\audit_workpapers_2025Q2.xlsx',)", "kwargs": {"sheet_name": "Loading...", "header": 0, "nrows": 50, "na_values": ["#N/A", "#N/A N/A", "#NA", "-NA", "#NULL!", "#NUM!", "#DIV/0!", "#VALUE!", "#REF!", "#NAME?", "#DIV/0", "#NUM", "#REF", "#VALUE"], "engine": "openpyxl", "parse_dates": true}} - Details: {"source_name": "ExcelConnector", "params": {"sheet_name": "Loading...", "header": 0, "nrows": 50, "na_values": ["#N/A", "#N/A N/A", "#NA", "-NA", "#NULL!", "#NUM!", "#DIV/0!", "#VALUE!", "#REF!", "#NAME?", "#DIV/0", "#NUM", "#REF", "#VALUE"], "engine": "openpyxl", "parse_dates": true}}
2025-05-23 10:33:42,106 - data_integration.connectors.excel_connector - ERROR - Error loading Excel file C:/Users/luria/PycharmProjects/AuditQAStudio2/test_data/audit_workpapers_2025Q2.xlsx: Error executing read_excel: Worksheet named 'Loading...' not found - Details: {"function": "read_excel", "args": "('C:/Users/luria/PycharmProjects/AuditQAStudio2/test_data/audit_workpapers_2025Q2.xlsx',)", "kwargs": {"sheet_name": "Loading...", "header": 0, "nrows": 50, "na_values": ["#N/A", "#N/A N/A", "#NA", "-NA", "#NULL!", "#NUM!", "#DIV/0!", "#VALUE!", "#REF!", "#NAME?", "#DIV/0", "#NUM", "#REF", "#VALUE"], "engine": "openpyxl", "parse_dates": true}}
2025-05-23 10:33:42,106 - data_integration.errors.error_handler - ERROR - Failed to load data from ExcelConnector: Error executing read_excel: Worksheet named 'Loading...' not found - Details: {"function": "read_excel", "args": "('C:/Users/luria/PycharmProjects/AuditQAStudio2/test_data/audit_workpapers_2025Q2.xlsx',)", "kwargs": {"sheet_name": "Loading...", "header": 0, "nrows": 50, "na_values": ["#N/A", "#N/A N/A", "#NA", "-NA", "#NULL!", "#NUM!", "#DIV/0!", "#VALUE!", "#REF!", "#NAME?", "#DIV/0", "#NUM", "#REF", "#VALUE"], "engine": "openpyxl", "parse_dates": true}} - Details: {"source_name": "ExcelConnector", "params": {"sheet_name": "Loading...", "header": 0, "nrows": 50, "na_values": ["#N/A", "#N/A N/A", "#NA", "-NA", "#NULL!", "#NUM!", "#DIV/0!", "#VALUE!", "#REF!", "#NAME?", "#DIV/0", "#NUM", "#REF", "#VALUE"], "engine": "openpyxl", "parse_dates": true}}
Traceback (most recent call last):
  File "C:\Users\luria\PycharmProjects\QAStudiov3\data_integration\errors\error_handler.py", line 328, in safe_dataframe_operation
    return func(*args, **kwargs)
           ^^^^^^^^^^^^^^^^^^^^^
  File "C:\Users\luria\PycharmProjects\QAStudiov3\.venv\Lib\site-packages\pandas\io\excel\_base.py", line 508, in read_excel
    data = io.parse(
           ^^^^^^^^^
  File "C:\Users\luria\PycharmProjects\QAStudiov3\.venv\Lib\site-packages\pandas\io\excel\_base.py", line 1616, in parse
    return self._reader.parse(
           ^^^^^^^^^^^^^^^^^^^
  File "C:\Users\luria\PycharmProjects\QAStudiov3\.venv\Lib\site-packages\pandas\io\excel\_base.py", line 773, in parse
    sheet = self.get_sheet_by_name(asheetname)
            ^^^^^^^^^^^^^^^^^^^^^^^^^^^^^^^^^^
  File "C:\Users\luria\PycharmProjects\QAStudiov3\.venv\Lib\site-packages\pandas\io\excel\_openpyxl.py", line 582, in get_sheet_by_name
    self.raise_if_bad_sheet_by_name(name)
  File "C:\Users\luria\PycharmProjects\QAStudiov3\.venv\Lib\site-packages\pandas\io\excel\_base.py", line 624, in raise_if_bad_sheet_by_name
    raise ValueError(f"Worksheet named '{name}' not found")
ValueError: Worksheet named 'Loading...' not found

During handling of the above exception, another exception occurred:

Traceback (most recent call last):
  File "C:\Users\luria\PycharmProjects\QAStudiov3\data_integration\connectors\excel_connector.py", line 195, in get_data
    df = retry_operation(
         ^^^^^^^^^^^^^^^^
  File "C:\Users\luria\PycharmProjects\QAStudiov3\data_integration\errors\error_handler.py", line 379, in retry_operation
    return func(*args, **kwargs)
           ^^^^^^^^^^^^^^^^^^^^^
  File "C:\Users\luria\PycharmProjects\QAStudiov3\data_integration\connectors\excel_connector.py", line 183, in load_excel
    return safe_dataframe_operation(
           ^^^^^^^^^^^^^^^^^^^^^^^^^
  File "C:\Users\luria\PycharmProjects\QAStudiov3\data_integration\errors\error_handler.py", line 344, in safe_dataframe_operation
    raise DataIntegrationError(error_msg, details)
data_integration.errors.error_handler.DataIntegrationError: Error executing read_excel: Worksheet named 'Loading...' not found - Details: {"function": "read_excel", "args": "('C:/Users/luria/PycharmProjects/AuditQAStudio2/test_data/audit_workpapers_2025Q2.xlsx',)", "kwargs": {"sheet_name": "Loading...", "header": 0, "nrows": 50, "na_values": ["#N/A", "#N/A N/A", "#NA", "-NA", "#NULL!", "#NUM!", "#DIV/0!", "#VALUE!", "#REF!", "#NAME?", "#DIV/0", "#NUM", "#REF", "#VALUE"], "engine": "openpyxl", "parse_dates": true}}
2025-05-23 10:33:42,107 - data_integration.io.importer - ERROR - Error previewing file C:/Users/luria/PycharmProjects/AuditQAStudio2/test_data/audit_workpapers_2025Q2.xlsx: Failed to load data from ExcelConnector: Error executing read_excel: Worksheet named 'Loading...' not found - Details: {"function": "read_excel", "args": "('C:/Users/luria/PycharmProjects/AuditQAStudio2/test_data/audit_workpapers_2025Q2.xlsx',)", "kwargs": {"sheet_name": "Loading...", "header": 0, "nrows": 50, "na_values": ["#N/A", "#N/A N/A", "#NA", "-NA", "#NULL!", "#NUM!", "#DIV/0!", "#VALUE!", "#REF!", "#NAME?", "#DIV/0", "#NUM", "#REF", "#VALUE"], "engine": "openpyxl", "parse_dates": true}} - Details: {"source_name": "ExcelConnector", "params": {"sheet_name": "Loading...", "header": 0, "nrows": 50, "na_values": ["#N/A", "#N/A N/A", "#NA", "-NA", "#NULL!", "#NUM!", "#DIV/0!", "#VALUE!", "#REF!", "#NAME?", "#DIV/0", "#NUM", "#REF", "#VALUE"], "engine": "openpyxl", "parse_dates": true}}
2025-05-23 10:33:42,107 - data_source_panel - ERROR - Error loading file preview: Failed to load data from ExcelConnector: Error executing read_excel: Worksheet named 'Loading...' not found - Details: {"function": "read_excel", "args": "('C:/Users/luria/PycharmProjects/AuditQAStudio2/test_data/audit_workpapers_2025Q2.xlsx',)", "kwargs": {"sheet_name": "Loading...", "header": 0, "nrows": 50, "na_values": ["#N/A", "#N/A N/A", "#NA", "-NA", "#NULL!", "#NUM!", "#DIV/0!", "#VALUE!", "#REF!", "#NAME?", "#DIV/0", "#NUM", "#REF", "#VALUE"], "engine": "openpyxl", "parse_dates": true}} - Details: {"source_name": "ExcelConnector", "params": {"sheet_name": "Loading...", "header": 0, "nrows": 50, "na_values": ["#N/A", "#N/A N/A", "#NA", "-NA", "#NULL!", "#NUM!", "#DIV/0!", "#VALUE!", "#REF!", "#NAME?", "#DIV/0", "#NUM", "#REF", "#VALUE"], "engine": "openpyxl", "parse_dates": true}}
2025-05-23 10:33:42,116 - data_source_panel - ERROR - Preview error: Error loading file preview: Failed to load data from ExcelConnector: Error executing read_excel: Worksheet named 'Loading...' not found - Details: {"function": "read_excel", "args": "('C:/Users/luria/PycharmProjects/AuditQAStudio2/test_data/audit_workpapers_2025Q2.xlsx',)", "kwargs": {"sheet_name": "Loading...", "header": 0, "nrows": 50, "na_values": ["#N/A", "#N/A N/A", "#NA", "-NA", "#NULL!", "#NUM!", "#DIV/0!", "#VALUE!", "#REF!", "#NAME?", "#DIV/0", "#NUM", "#REF", "#VALUE"], "engine": "openpyxl", "parse_dates": true}} - Details: {"source_name": "ExcelConnector", "params": {"sheet_name": "Loading...", "header": 0, "nrows": 50, "na_values": ["#N/A", "#N/A N/A", "#NA", "-NA", "#NULL!", "#NUM!", "#DIV/0!", "#VALUE!", "#REF!", "#NAME?", "#DIV/0", "#NUM", "#REF", "#VALUE"], "engine": "openpyxl", "parse_dates": true}}
2025-05-23 10:33:58,512 - error_handler - CRITICAL - TypeError: Object of type QByteArray is not JSON serializable
2025-05-23 10:34:00,222 - __main__ - ERROR - ERROR: Object of type QByteArray is not JSON serializable
2025-05-23 13:04:30,666 - data_integration.connectors.excel_connector - ERROR - Error loading Excel file C:/Users/luria/PycharmProjects/AuditQAStudio2/test_data/audit_workpapers_2025Q2.xlsx: Error executing read_excel: Worksheet named 'Loading...' not found - Details: {"function": "read_excel", "args": "('C:/Users/luria/PycharmProjects/AuditQAStudio2/test_data/audit_workpapers_2025Q2.xlsx',)", "kwargs": {"sheet_name": "Loading...", "header": 0, "nrows": 50, "na_values": ["#N/A", "#N/A N/A", "#NA", "-NA", "#NULL!", "#NUM!", "#DIV/0!", "#VALUE!", "#REF!", "#NAME?", "#DIV/0", "#NUM", "#REF", "#VALUE"], "engine": "openpyxl", "parse_dates": true}}
2025-05-23 13:04:30,666 - data_integration.errors.error_handler - ERROR - Failed to load data from ExcelConnector: Error executing read_excel: Worksheet named 'Loading...' not found - Details: {"function": "read_excel", "args": "('C:/Users/luria/PycharmProjects/AuditQAStudio2/test_data/audit_workpapers_2025Q2.xlsx',)", "kwargs": {"sheet_name": "Loading...", "header": 0, "nrows": 50, "na_values": ["#N/A", "#N/A N/A", "#NA", "-NA", "#NULL!", "#NUM!", "#DIV/0!", "#VALUE!", "#REF!", "#NAME?", "#DIV/0", "#NUM", "#REF", "#VALUE"], "engine": "openpyxl", "parse_dates": true}} - Details: {"source_name": "ExcelConnector", "params": {"sheet_name": "Loading...", "header": 0, "nrows": 50, "na_values": ["#N/A", "#N/A N/A", "#NA", "-NA", "#NULL!", "#NUM!", "#DIV/0!", "#VALUE!", "#REF!", "#NAME?", "#DIV/0", "#NUM", "#REF", "#VALUE"], "engine": "openpyxl", "parse_dates": true}}
Traceback (most recent call last):
  File "C:\Users\luria\PycharmProjects\QAStudiov3\data_integration\errors\error_handler.py", line 328, in safe_dataframe_operation
    return func(*args, **kwargs)
           ^^^^^^^^^^^^^^^^^^^^^
  File "C:\Users\luria\PycharmProjects\QAStudiov3\.venv\Lib\site-packages\pandas\io\excel\_base.py", line 508, in read_excel
    data = io.parse(
           ^^^^^^^^^
  File "C:\Users\luria\PycharmProjects\QAStudiov3\.venv\Lib\site-packages\pandas\io\excel\_base.py", line 1616, in parse
    return self._reader.parse(
           ^^^^^^^^^^^^^^^^^^^
  File "C:\Users\luria\PycharmProjects\QAStudiov3\.venv\Lib\site-packages\pandas\io\excel\_base.py", line 773, in parse
    sheet = self.get_sheet_by_name(asheetname)
            ^^^^^^^^^^^^^^^^^^^^^^^^^^^^^^^^^^
  File "C:\Users\luria\PycharmProjects\QAStudiov3\.venv\Lib\site-packages\pandas\io\excel\_openpyxl.py", line 582, in get_sheet_by_name
    self.raise_if_bad_sheet_by_name(name)
  File "C:\Users\luria\PycharmProjects\QAStudiov3\.venv\Lib\site-packages\pandas\io\excel\_base.py", line 624, in raise_if_bad_sheet_by_name
    raise ValueError(f"Worksheet named '{name}' not found")
ValueError: Worksheet named 'Loading...' not found

During handling of the above exception, another exception occurred:

Traceback (most recent call last):
  File "C:\Users\luria\PycharmProjects\QAStudiov3\data_integration\connectors\excel_connector.py", line 195, in get_data
    df = retry_operation(
         ^^^^^^^^^^^^^^^^
  File "C:\Users\luria\PycharmProjects\QAStudiov3\data_integration\errors\error_handler.py", line 379, in retry_operation
    return func(*args, **kwargs)
           ^^^^^^^^^^^^^^^^^^^^^
  File "C:\Users\luria\PycharmProjects\QAStudiov3\data_integration\connectors\excel_connector.py", line 183, in load_excel
    return safe_dataframe_operation(
           ^^^^^^^^^^^^^^^^^^^^^^^^^
  File "C:\Users\luria\PycharmProjects\QAStudiov3\data_integration\errors\error_handler.py", line 344, in safe_dataframe_operation
    raise DataIntegrationError(error_msg, details)
data_integration.errors.error_handler.DataIntegrationError: Error executing read_excel: Worksheet named 'Loading...' not found - Details: {"function": "read_excel", "args": "('C:/Users/luria/PycharmProjects/AuditQAStudio2/test_data/audit_workpapers_2025Q2.xlsx',)", "kwargs": {"sheet_name": "Loading...", "header": 0, "nrows": 50, "na_values": ["#N/A", "#N/A N/A", "#NA", "-NA", "#NULL!", "#NUM!", "#DIV/0!", "#VALUE!", "#REF!", "#NAME?", "#DIV/0", "#NUM", "#REF", "#VALUE"], "engine": "openpyxl", "parse_dates": true}}
2025-05-23 13:04:30,695 - data_integration.io.importer - ERROR - Error previewing file C:/Users/luria/PycharmProjects/AuditQAStudio2/test_data/audit_workpapers_2025Q2.xlsx: Failed to load data from ExcelConnector: Error executing read_excel: Worksheet named 'Loading...' not found - Details: {"function": "read_excel", "args": "('C:/Users/luria/PycharmProjects/AuditQAStudio2/test_data/audit_workpapers_2025Q2.xlsx',)", "kwargs": {"sheet_name": "Loading...", "header": 0, "nrows": 50, "na_values": ["#N/A", "#N/A N/A", "#NA", "-NA", "#NULL!", "#NUM!", "#DIV/0!", "#VALUE!", "#REF!", "#NAME?", "#DIV/0", "#NUM", "#REF", "#VALUE"], "engine": "openpyxl", "parse_dates": true}} - Details: {"source_name": "ExcelConnector", "params": {"sheet_name": "Loading...", "header": 0, "nrows": 50, "na_values": ["#N/A", "#N/A N/A", "#NA", "-NA", "#NULL!", "#NUM!", "#DIV/0!", "#VALUE!", "#REF!", "#NAME?", "#DIV/0", "#NUM", "#REF", "#VALUE"], "engine": "openpyxl", "parse_dates": true}}
2025-05-23 13:04:30,695 - data_source_panel - ERROR - Error loading file preview: Failed to load data from ExcelConnector: Error executing read_excel: Worksheet named 'Loading...' not found - Details: {"function": "read_excel", "args": "('C:/Users/luria/PycharmProjects/AuditQAStudio2/test_data/audit_workpapers_2025Q2.xlsx',)", "kwargs": {"sheet_name": "Loading...", "header": 0, "nrows": 50, "na_values": ["#N/A", "#N/A N/A", "#NA", "-NA", "#NULL!", "#NUM!", "#DIV/0!", "#VALUE!", "#REF!", "#NAME?", "#DIV/0", "#NUM", "#REF", "#VALUE"], "engine": "openpyxl", "parse_dates": true}} - Details: {"source_name": "ExcelConnector", "params": {"sheet_name": "Loading...", "header": 0, "nrows": 50, "na_values": ["#N/A", "#N/A N/A", "#NA", "-NA", "#NULL!", "#NUM!", "#DIV/0!", "#VALUE!", "#REF!", "#NAME?", "#DIV/0", "#NUM", "#REF", "#VALUE"], "engine": "openpyxl", "parse_dates": true}}
2025-05-23 13:04:30,698 - data_source_panel - ERROR - Preview error: Error loading file preview: Failed to load data from ExcelConnector: Error executing read_excel: Worksheet named 'Loading...' not found - Details: {"function": "read_excel", "args": "('C:/Users/luria/PycharmProjects/AuditQAStudio2/test_data/audit_workpapers_2025Q2.xlsx',)", "kwargs": {"sheet_name": "Loading...", "header": 0, "nrows": 50, "na_values": ["#N/A", "#N/A N/A", "#NA", "-NA", "#NULL!", "#NUM!", "#DIV/0!", "#VALUE!", "#REF!", "#NAME?", "#DIV/0", "#NUM", "#REF", "#VALUE"], "engine": "openpyxl", "parse_dates": true}} - Details: {"source_name": "ExcelConnector", "params": {"sheet_name": "Loading...", "header": 0, "nrows": 50, "na_values": ["#N/A", "#N/A N/A", "#NA", "-NA", "#NULL!", "#NUM!", "#DIV/0!", "#VALUE!", "#REF!", "#NAME?", "#DIV/0", "#NUM", "#REF", "#VALUE"], "engine": "openpyxl", "parse_dates": true}}
2025-05-23 13:40:42,879 - ui.common.error_handler - ERROR - AttributeError: type object 'PySide6.QtCore.Qt' has no attribute 'ScrollBarNever'
2025-05-23 13:41:21,962 - ui.common.error_handler - CRITICAL - AttributeError: 'AnalyticsRunnerApp' object has no attribute 'log_view'
2025-05-23 13:41:42,352 - ui.common.error_handler - ERROR - TypeError: 'PySide6.QtGui.QTextFormat.setForeground' called with wrong argument types:
  PySide6.QtGui.QTextFormat.setForeground(str)
Supported signatures:
  PySide6.QtGui.QTextFormat.setForeground(brush: PySide6.QtGui.QBrush | PySide6.QtCore.Qt.BrushStyle | PySide6.QtCore.Qt.GlobalColor | PySide6.QtGui.QColor | PySide6.QtGui.QGradient | PySide6.QtGui.QImage | PySide6.QtGui.QPixmap, /)
2025-05-23 13:41:58,635 - ui.common.error_handler - CRITICAL - AttributeError: 'AnalyticsRunnerApp' object has no attribute 'log_view'
2025-05-23 13:46:53,678 - ui.common.error_handler - ERROR - AttributeError: type object 'PySide6.QtCore.Qt' has no attribute 'ScrollBarNever'
2025-05-23 13:46:56,975 - ui.common.error_handler - CRITICAL - AttributeError: 'AnalyticsRunnerApp' object has no attribute 'log_view'
2025-05-23 13:47:07,793 - ui.common.error_handler - ERROR - AttributeError: type object 'PySide6.QtCore.Qt' has no attribute 'ScrollBarNever'
2025-05-23 13:47:39,732 - ui.common.error_handler - CRITICAL - AttributeError: 'AnalyticsRunnerApp' object has no attribute 'log_view'
2025-05-23 13:47:49,528 - ui.common.error_handler - CRITICAL - AttributeError: 'RuleEditorPanel' object has no attribute 'validation_timer'
2025-05-23 13:48:13,031 - ui.common.error_handler - CRITICAL - TypeError: Object of type bytes is not JSON serializable
2025-05-23 13:48:13,965 - __main__ - ERROR - ERROR: Object of type bytes is not JSON serializable
2025-05-23 13:48:26,644 - ui.common.error_handler - ERROR - TypeError: 'PySide6.QtWidgets.QWidget.restoreGeometry' called with wrong argument types:
  PySide6.QtWidgets.QWidget.restoreGeometry(dict)
Supported signatures:
  PySide6.QtWidgets.QWidget.restoreGeometry(geometry: PySide6.QtCore.QByteArray | bytes | bytearray | memoryview, /)
2025-05-23 13:49:30,401 - ui.common.error_handler - CRITICAL - TypeError: Object of type bytes is not JSON serializable
2025-05-23 13:51:11,433 - ui.common.error_handler - ERROR - TypeError: 'PySide6.QtWidgets.QWidget.restoreGeometry' called with wrong argument types:
  PySide6.QtWidgets.QWidget.restoreGeometry(dict)
Supported signatures:
  PySide6.QtWidgets.QWidget.restoreGeometry(geometry: PySide6.QtCore.QByteArray | bytes | bytearray | memoryview, /)
2025-05-23 13:51:14,842 - ui.common.error_handler - CRITICAL - TypeError: Object of type bytes is not JSON serializable
2025-05-23 13:51:22,962 - ui.common.error_handler - ERROR - TypeError: 'PySide6.QtWidgets.QWidget.restoreGeometry' called with wrong argument types:
  PySide6.QtWidgets.QWidget.restoreGeometry(dict)
Supported signatures:
  PySide6.QtWidgets.QWidget.restoreGeometry(geometry: PySide6.QtCore.QByteArray | bytes | bytearray | memoryview, /)
2025-05-23 13:51:53,163 - ui.common.error_handler - CRITICAL - TypeError: Object of type bytes is not JSON serializable
2025-05-23 13:53:23,453 - ui.common.error_handler - CRITICAL - TypeError: Object of type bytes is not JSON serializable
2025-05-23 13:53:24,920 - __main__ - ERROR - ERROR: Object of type bytes is not JSON serializable
2025-05-23 13:58:24,526 - ui.common.error_handler - CRITICAL - TypeError: Object of type bytes is not JSON serializable
2025-05-23 13:58:25,532 - __main__ - ERROR - ERROR: Object of type bytes is not JSON serializable
2025-05-23 14:00:50,301 - ui.common.error_handler - CRITICAL - TypeError: Object of type bytes is not JSON serializable
2025-05-23 14:00:51,371 - __main__ - ERROR - ERROR: Object of type bytes is not JSON serializable
2025-05-23 14:04:04,712 - data_integration.connectors.excel_connector - ERROR - Error loading Excel file C:/Users/luria/PycharmProjects/AuditQAStudio2/test_data/audit_workpapers_2025Q2.xlsx: Error executing read_excel: Worksheet named 'Loading...' not found - Details: {"function": "read_excel", "args": "('C:/Users/luria/PycharmProjects/AuditQAStudio2/test_data/audit_workpapers_2025Q2.xlsx',)", "kwargs": {"sheet_name": "Loading...", "header": 0, "nrows": 50, "na_values": ["#N/A", "#N/A N/A", "#NA", "-NA", "#NULL!", "#NUM!", "#DIV/0!", "#VALUE!", "#REF!", "#NAME?", "#DIV/0", "#NUM", "#REF", "#VALUE"], "engine": "openpyxl", "parse_dates": true}}
2025-05-23 14:04:04,712 - data_integration.errors.error_handler - ERROR - Failed to load data from ExcelConnector: Error executing read_excel: Worksheet named 'Loading...' not found - Details: {"function": "read_excel", "args": "('C:/Users/luria/PycharmProjects/AuditQAStudio2/test_data/audit_workpapers_2025Q2.xlsx',)", "kwargs": {"sheet_name": "Loading...", "header": 0, "nrows": 50, "na_values": ["#N/A", "#N/A N/A", "#NA", "-NA", "#NULL!", "#NUM!", "#DIV/0!", "#VALUE!", "#REF!", "#NAME?", "#DIV/0", "#NUM", "#REF", "#VALUE"], "engine": "openpyxl", "parse_dates": true}} - Details: {"source_name": "ExcelConnector", "params": {"sheet_name": "Loading...", "header": 0, "nrows": 50, "na_values": ["#N/A", "#N/A N/A", "#NA", "-NA", "#NULL!", "#NUM!", "#DIV/0!", "#VALUE!", "#REF!", "#NAME?", "#DIV/0", "#NUM", "#REF", "#VALUE"], "engine": "openpyxl", "parse_dates": true}}
Traceback (most recent call last):
  File "C:\Users\luria\PycharmProjects\QAStudiov3\data_integration\errors\error_handler.py", line 328, in safe_dataframe_operation
    return func(*args, **kwargs)
           ^^^^^^^^^^^^^^^^^^^^^
  File "C:\Users\luria\PycharmProjects\QAStudiov3\.venv\Lib\site-packages\pandas\io\excel\_base.py", line 508, in read_excel
    data = io.parse(
           ^^^^^^^^^
  File "C:\Users\luria\PycharmProjects\QAStudiov3\.venv\Lib\site-packages\pandas\io\excel\_base.py", line 1616, in parse
    return self._reader.parse(
           ^^^^^^^^^^^^^^^^^^^
  File "C:\Users\luria\PycharmProjects\QAStudiov3\.venv\Lib\site-packages\pandas\io\excel\_base.py", line 773, in parse
    sheet = self.get_sheet_by_name(asheetname)
            ^^^^^^^^^^^^^^^^^^^^^^^^^^^^^^^^^^
  File "C:\Users\luria\PycharmProjects\QAStudiov3\.venv\Lib\site-packages\pandas\io\excel\_openpyxl.py", line 582, in get_sheet_by_name
    self.raise_if_bad_sheet_by_name(name)
  File "C:\Users\luria\PycharmProjects\QAStudiov3\.venv\Lib\site-packages\pandas\io\excel\_base.py", line 624, in raise_if_bad_sheet_by_name
    raise ValueError(f"Worksheet named '{name}' not found")
ValueError: Worksheet named 'Loading...' not found

During handling of the above exception, another exception occurred:

Traceback (most recent call last):
  File "C:\Users\luria\PycharmProjects\QAStudiov3\data_integration\connectors\excel_connector.py", line 195, in get_data
    df = retry_operation(
         ^^^^^^^^^^^^^^^^
  File "C:\Users\luria\PycharmProjects\QAStudiov3\data_integration\errors\error_handler.py", line 379, in retry_operation
    return func(*args, **kwargs)
           ^^^^^^^^^^^^^^^^^^^^^
  File "C:\Users\luria\PycharmProjects\QAStudiov3\data_integration\connectors\excel_connector.py", line 183, in load_excel
    return safe_dataframe_operation(
           ^^^^^^^^^^^^^^^^^^^^^^^^^
  File "C:\Users\luria\PycharmProjects\QAStudiov3\data_integration\errors\error_handler.py", line 344, in safe_dataframe_operation
    raise DataIntegrationError(error_msg, details)
data_integration.errors.error_handler.DataIntegrationError: Error executing read_excel: Worksheet named 'Loading...' not found - Details: {"function": "read_excel", "args": "('C:/Users/luria/PycharmProjects/AuditQAStudio2/test_data/audit_workpapers_2025Q2.xlsx',)", "kwargs": {"sheet_name": "Loading...", "header": 0, "nrows": 50, "na_values": ["#N/A", "#N/A N/A", "#NA", "-NA", "#NULL!", "#NUM!", "#DIV/0!", "#VALUE!", "#REF!", "#NAME?", "#DIV/0", "#NUM", "#REF", "#VALUE"], "engine": "openpyxl", "parse_dates": true}}
2025-05-23 14:04:04,733 - data_integration.io.importer - ERROR - Error previewing file C:/Users/luria/PycharmProjects/AuditQAStudio2/test_data/audit_workpapers_2025Q2.xlsx: Failed to load data from ExcelConnector: Error executing read_excel: Worksheet named 'Loading...' not found - Details: {"function": "read_excel", "args": "('C:/Users/luria/PycharmProjects/AuditQAStudio2/test_data/audit_workpapers_2025Q2.xlsx',)", "kwargs": {"sheet_name": "Loading...", "header": 0, "nrows": 50, "na_values": ["#N/A", "#N/A N/A", "#NA", "-NA", "#NULL!", "#NUM!", "#DIV/0!", "#VALUE!", "#REF!", "#NAME?", "#DIV/0", "#NUM", "#REF", "#VALUE"], "engine": "openpyxl", "parse_dates": true}} - Details: {"source_name": "ExcelConnector", "params": {"sheet_name": "Loading...", "header": 0, "nrows": 50, "na_values": ["#N/A", "#N/A N/A", "#NA", "-NA", "#NULL!", "#NUM!", "#DIV/0!", "#VALUE!", "#REF!", "#NAME?", "#DIV/0", "#NUM", "#REF", "#VALUE"], "engine": "openpyxl", "parse_dates": true}}
2025-05-23 14:04:04,733 - data_source_panel - ERROR - Error loading file preview: Failed to load data from ExcelConnector: Error executing read_excel: Worksheet named 'Loading...' not found - Details: {"function": "read_excel", "args": "('C:/Users/luria/PycharmProjects/AuditQAStudio2/test_data/audit_workpapers_2025Q2.xlsx',)", "kwargs": {"sheet_name": "Loading...", "header": 0, "nrows": 50, "na_values": ["#N/A", "#N/A N/A", "#NA", "-NA", "#NULL!", "#NUM!", "#DIV/0!", "#VALUE!", "#REF!", "#NAME?", "#DIV/0", "#NUM", "#REF", "#VALUE"], "engine": "openpyxl", "parse_dates": true}} - Details: {"source_name": "ExcelConnector", "params": {"sheet_name": "Loading...", "header": 0, "nrows": 50, "na_values": ["#N/A", "#N/A N/A", "#NA", "-NA", "#NULL!", "#NUM!", "#DIV/0!", "#VALUE!", "#REF!", "#NAME?", "#DIV/0", "#NUM", "#REF", "#VALUE"], "engine": "openpyxl", "parse_dates": true}}
2025-05-23 14:04:04,736 - data_source_panel - ERROR - Preview error: Error loading file preview: Failed to load data from ExcelConnector: Error executing read_excel: Worksheet named 'Loading...' not found - Details: {"function": "read_excel", "args": "('C:/Users/luria/PycharmProjects/AuditQAStudio2/test_data/audit_workpapers_2025Q2.xlsx',)", "kwargs": {"sheet_name": "Loading...", "header": 0, "nrows": 50, "na_values": ["#N/A", "#N/A N/A", "#NA", "-NA", "#NULL!", "#NUM!", "#DIV/0!", "#VALUE!", "#REF!", "#NAME?", "#DIV/0", "#NUM", "#REF", "#VALUE"], "engine": "openpyxl", "parse_dates": true}} - Details: {"source_name": "ExcelConnector", "params": {"sheet_name": "Loading...", "header": 0, "nrows": 50, "na_values": ["#N/A", "#N/A N/A", "#NA", "-NA", "#NULL!", "#NUM!", "#DIV/0!", "#VALUE!", "#REF!", "#NAME?", "#DIV/0", "#NUM", "#REF", "#VALUE"], "engine": "openpyxl", "parse_dates": true}}
2025-05-23 14:09:53,337 - ui.common.error_handler - CRITICAL - TypeError: Object of type bytes is not JSON serializable
2025-05-23 14:09:54,308 - __main__ - ERROR - ERROR: Object of type bytes is not JSON serializable
2025-05-23 14:22:08,815 - data_integration.connectors.excel_connector - ERROR - Error loading Excel file C:\Users\luria\PycharmProjects\AuditQAStudio2\test_data\audit_workpapers_2025Q2.xlsx: Error executing read_excel: Worksheet named 'Loading...' not found - Details: {"function": "read_excel", "args": "('C:\\\\Users\\\\luria\\\\PycharmProjects\\\\AuditQAStudio2\\\\test_data\\\\audit_workpapers_2025Q2.xlsx',)", "kwargs": {"sheet_name": "Loading...", "header": 0, "nrows": 50, "na_values": ["#N/A", "#N/A N/A", "#NA", "-NA", "#NULL!", "#NUM!", "#DIV/0!", "#VALUE!", "#REF!", "#NAME?", "#DIV/0", "#NUM", "#REF", "#VALUE"], "engine": "openpyxl", "parse_dates": true}}
2025-05-23 14:22:08,815 - data_integration.errors.error_handler - ERROR - Failed to load data from ExcelConnector: Error executing read_excel: Worksheet named 'Loading...' not found - Details: {"function": "read_excel", "args": "('C:\\\\Users\\\\luria\\\\PycharmProjects\\\\AuditQAStudio2\\\\test_data\\\\audit_workpapers_2025Q2.xlsx',)", "kwargs": {"sheet_name": "Loading...", "header": 0, "nrows": 50, "na_values": ["#N/A", "#N/A N/A", "#NA", "-NA", "#NULL!", "#NUM!", "#DIV/0!", "#VALUE!", "#REF!", "#NAME?", "#DIV/0", "#NUM", "#REF", "#VALUE"], "engine": "openpyxl", "parse_dates": true}} - Details: {"source_name": "ExcelConnector", "params": {"sheet_name": "Loading...", "header": 0, "nrows": 50, "na_values": ["#N/A", "#N/A N/A", "#NA", "-NA", "#NULL!", "#NUM!", "#DIV/0!", "#VALUE!", "#REF!", "#NAME?", "#DIV/0", "#NUM", "#REF", "#VALUE"], "engine": "openpyxl", "parse_dates": true}}
Traceback (most recent call last):
  File "C:\Users\luria\PycharmProjects\QAStudiov3\data_integration\errors\error_handler.py", line 328, in safe_dataframe_operation
    return func(*args, **kwargs)
           ^^^^^^^^^^^^^^^^^^^^^
  File "C:\Users\luria\PycharmProjects\QAStudiov3\.venv\Lib\site-packages\pandas\io\excel\_base.py", line 508, in read_excel
    data = io.parse(
           ^^^^^^^^^
  File "C:\Users\luria\PycharmProjects\QAStudiov3\.venv\Lib\site-packages\pandas\io\excel\_base.py", line 1616, in parse
    return self._reader.parse(
           ^^^^^^^^^^^^^^^^^^^
  File "C:\Users\luria\PycharmProjects\QAStudiov3\.venv\Lib\site-packages\pandas\io\excel\_base.py", line 773, in parse
    sheet = self.get_sheet_by_name(asheetname)
            ^^^^^^^^^^^^^^^^^^^^^^^^^^^^^^^^^^
  File "C:\Users\luria\PycharmProjects\QAStudiov3\.venv\Lib\site-packages\pandas\io\excel\_openpyxl.py", line 582, in get_sheet_by_name
    self.raise_if_bad_sheet_by_name(name)
  File "C:\Users\luria\PycharmProjects\QAStudiov3\.venv\Lib\site-packages\pandas\io\excel\_base.py", line 624, in raise_if_bad_sheet_by_name
    raise ValueError(f"Worksheet named '{name}' not found")
ValueError: Worksheet named 'Loading...' not found

During handling of the above exception, another exception occurred:

Traceback (most recent call last):
  File "C:\Users\luria\PycharmProjects\QAStudiov3\data_integration\connectors\excel_connector.py", line 195, in get_data
    df = retry_operation(
         ^^^^^^^^^^^^^^^^
  File "C:\Users\luria\PycharmProjects\QAStudiov3\data_integration\errors\error_handler.py", line 379, in retry_operation
    return func(*args, **kwargs)
           ^^^^^^^^^^^^^^^^^^^^^
  File "C:\Users\luria\PycharmProjects\QAStudiov3\data_integration\connectors\excel_connector.py", line 183, in load_excel
    return safe_dataframe_operation(
           ^^^^^^^^^^^^^^^^^^^^^^^^^
  File "C:\Users\luria\PycharmProjects\QAStudiov3\data_integration\errors\error_handler.py", line 344, in safe_dataframe_operation
    raise DataIntegrationError(error_msg, details)
data_integration.errors.error_handler.DataIntegrationError: Error executing read_excel: Worksheet named 'Loading...' not found - Details: {"function": "read_excel", "args": "('C:\\\\Users\\\\luria\\\\PycharmProjects\\\\AuditQAStudio2\\\\test_data\\\\audit_workpapers_2025Q2.xlsx',)", "kwargs": {"sheet_name": "Loading...", "header": 0, "nrows": 50, "na_values": ["#N/A", "#N/A N/A", "#NA", "-NA", "#NULL!", "#NUM!", "#DIV/0!", "#VALUE!", "#REF!", "#NAME?", "#DIV/0", "#NUM", "#REF", "#VALUE"], "engine": "openpyxl", "parse_dates": true}}
2025-05-23 14:22:08,817 - data_integration.io.importer - ERROR - Error previewing file C:\Users\luria\PycharmProjects\AuditQAStudio2\test_data\audit_workpapers_2025Q2.xlsx: Failed to load data from ExcelConnector: Error executing read_excel: Worksheet named 'Loading...' not found - Details: {"function": "read_excel", "args": "('C:\\\\Users\\\\luria\\\\PycharmProjects\\\\AuditQAStudio2\\\\test_data\\\\audit_workpapers_2025Q2.xlsx',)", "kwargs": {"sheet_name": "Loading...", "header": 0, "nrows": 50, "na_values": ["#N/A", "#N/A N/A", "#NA", "-NA", "#NULL!", "#NUM!", "#DIV/0!", "#VALUE!", "#REF!", "#NAME?", "#DIV/0", "#NUM", "#REF", "#VALUE"], "engine": "openpyxl", "parse_dates": true}} - Details: {"source_name": "ExcelConnector", "params": {"sheet_name": "Loading...", "header": 0, "nrows": 50, "na_values": ["#N/A", "#N/A N/A", "#NA", "-NA", "#NULL!", "#NUM!", "#DIV/0!", "#VALUE!", "#REF!", "#NAME?", "#DIV/0", "#NUM", "#REF", "#VALUE"], "engine": "openpyxl", "parse_dates": true}}
2025-05-23 14:22:08,817 - data_source_panel - ERROR - Error loading file preview: Failed to load data from ExcelConnector: Error executing read_excel: Worksheet named 'Loading...' not found - Details: {"function": "read_excel", "args": "('C:\\\\Users\\\\luria\\\\PycharmProjects\\\\AuditQAStudio2\\\\test_data\\\\audit_workpapers_2025Q2.xlsx',)", "kwargs": {"sheet_name": "Loading...", "header": 0, "nrows": 50, "na_values": ["#N/A", "#N/A N/A", "#NA", "-NA", "#NULL!", "#NUM!", "#DIV/0!", "#VALUE!", "#REF!", "#NAME?", "#DIV/0", "#NUM", "#REF", "#VALUE"], "engine": "openpyxl", "parse_dates": true}} - Details: {"source_name": "ExcelConnector", "params": {"sheet_name": "Loading...", "header": 0, "nrows": 50, "na_values": ["#N/A", "#N/A N/A", "#NA", "-NA", "#NULL!", "#NUM!", "#DIV/0!", "#VALUE!", "#REF!", "#NAME?", "#DIV/0", "#NUM", "#REF", "#VALUE"], "engine": "openpyxl", "parse_dates": true}}
2025-05-23 14:22:08,818 - data_source_panel - ERROR - Preview error: Error loading file preview: Failed to load data from ExcelConnector: Error executing read_excel: Worksheet named 'Loading...' not found - Details: {"function": "read_excel", "args": "('C:\\\\Users\\\\luria\\\\PycharmProjects\\\\AuditQAStudio2\\\\test_data\\\\audit_workpapers_2025Q2.xlsx',)", "kwargs": {"sheet_name": "Loading...", "header": 0, "nrows": 50, "na_values": ["#N/A", "#N/A N/A", "#NA", "-NA", "#NULL!", "#NUM!", "#DIV/0!", "#VALUE!", "#REF!", "#NAME?", "#DIV/0", "#NUM", "#REF", "#VALUE"], "engine": "openpyxl", "parse_dates": true}} - Details: {"source_name": "ExcelConnector", "params": {"sheet_name": "Loading...", "header": 0, "nrows": 50, "na_values": ["#N/A", "#N/A N/A", "#NA", "-NA", "#NULL!", "#NUM!", "#DIV/0!", "#VALUE!", "#REF!", "#NAME?", "#DIV/0", "#NUM", "#REF", "#VALUE"], "engine": "openpyxl", "parse_dates": true}}
2025-05-23 14:25:50,342 - data_integration.connectors.excel_connector - ERROR - Error loading Excel file C:\Users\luria\PycharmProjects\AuditQAStudio2\test_data\audit_workpapers_2025Q2.xlsx: Error executing read_excel: Worksheet named 'Loading...' not found - Details: {"function": "read_excel", "args": "('C:\\\\Users\\\\luria\\\\PycharmProjects\\\\AuditQAStudio2\\\\test_data\\\\audit_workpapers_2025Q2.xlsx',)", "kwargs": {"sheet_name": "Loading...", "header": 0, "nrows": 50, "na_values": ["#N/A", "#N/A N/A", "#NA", "-NA", "#NULL!", "#NUM!", "#DIV/0!", "#VALUE!", "#REF!", "#NAME?", "#DIV/0", "#NUM", "#REF", "#VALUE"], "engine": "openpyxl", "parse_dates": true}}
2025-05-23 14:25:50,342 - data_integration.errors.error_handler - ERROR - Failed to load data from ExcelConnector: Error executing read_excel: Worksheet named 'Loading...' not found - Details: {"function": "read_excel", "args": "('C:\\\\Users\\\\luria\\\\PycharmProjects\\\\AuditQAStudio2\\\\test_data\\\\audit_workpapers_2025Q2.xlsx',)", "kwargs": {"sheet_name": "Loading...", "header": 0, "nrows": 50, "na_values": ["#N/A", "#N/A N/A", "#NA", "-NA", "#NULL!", "#NUM!", "#DIV/0!", "#VALUE!", "#REF!", "#NAME?", "#DIV/0", "#NUM", "#REF", "#VALUE"], "engine": "openpyxl", "parse_dates": true}} - Details: {"source_name": "ExcelConnector", "params": {"sheet_name": "Loading...", "header": 0, "nrows": 50, "na_values": ["#N/A", "#N/A N/A", "#NA", "-NA", "#NULL!", "#NUM!", "#DIV/0!", "#VALUE!", "#REF!", "#NAME?", "#DIV/0", "#NUM", "#REF", "#VALUE"], "engine": "openpyxl", "parse_dates": true}}
Traceback (most recent call last):
  File "C:\Users\luria\PycharmProjects\QAStudiov3\data_integration\errors\error_handler.py", line 328, in safe_dataframe_operation
    return func(*args, **kwargs)
           ^^^^^^^^^^^^^^^^^^^^^
  File "C:\Users\luria\PycharmProjects\QAStudiov3\.venv\Lib\site-packages\pandas\io\excel\_base.py", line 508, in read_excel
    data = io.parse(
           ^^^^^^^^^
  File "C:\Users\luria\PycharmProjects\QAStudiov3\.venv\Lib\site-packages\pandas\io\excel\_base.py", line 1616, in parse
    return self._reader.parse(
           ^^^^^^^^^^^^^^^^^^^
  File "C:\Users\luria\PycharmProjects\QAStudiov3\.venv\Lib\site-packages\pandas\io\excel\_base.py", line 773, in parse
    sheet = self.get_sheet_by_name(asheetname)
            ^^^^^^^^^^^^^^^^^^^^^^^^^^^^^^^^^^
  File "C:\Users\luria\PycharmProjects\QAStudiov3\.venv\Lib\site-packages\pandas\io\excel\_openpyxl.py", line 582, in get_sheet_by_name
    self.raise_if_bad_sheet_by_name(name)
  File "C:\Users\luria\PycharmProjects\QAStudiov3\.venv\Lib\site-packages\pandas\io\excel\_base.py", line 624, in raise_if_bad_sheet_by_name
    raise ValueError(f"Worksheet named '{name}' not found")
ValueError: Worksheet named 'Loading...' not found

During handling of the above exception, another exception occurred:

Traceback (most recent call last):
  File "C:\Users\luria\PycharmProjects\QAStudiov3\data_integration\connectors\excel_connector.py", line 195, in get_data
    df = retry_operation(
         ^^^^^^^^^^^^^^^^
  File "C:\Users\luria\PycharmProjects\QAStudiov3\data_integration\errors\error_handler.py", line 379, in retry_operation
    return func(*args, **kwargs)
           ^^^^^^^^^^^^^^^^^^^^^
  File "C:\Users\luria\PycharmProjects\QAStudiov3\data_integration\connectors\excel_connector.py", line 183, in load_excel
    return safe_dataframe_operation(
           ^^^^^^^^^^^^^^^^^^^^^^^^^
  File "C:\Users\luria\PycharmProjects\QAStudiov3\data_integration\errors\error_handler.py", line 344, in safe_dataframe_operation
    raise DataIntegrationError(error_msg, details)
data_integration.errors.error_handler.DataIntegrationError: Error executing read_excel: Worksheet named 'Loading...' not found - Details: {"function": "read_excel", "args": "('C:\\\\Users\\\\luria\\\\PycharmProjects\\\\AuditQAStudio2\\\\test_data\\\\audit_workpapers_2025Q2.xlsx',)", "kwargs": {"sheet_name": "Loading...", "header": 0, "nrows": 50, "na_values": ["#N/A", "#N/A N/A", "#NA", "-NA", "#NULL!", "#NUM!", "#DIV/0!", "#VALUE!", "#REF!", "#NAME?", "#DIV/0", "#NUM", "#REF", "#VALUE"], "engine": "openpyxl", "parse_dates": true}}
2025-05-23 14:25:50,343 - data_integration.io.importer - ERROR - Error previewing file C:\Users\luria\PycharmProjects\AuditQAStudio2\test_data\audit_workpapers_2025Q2.xlsx: Failed to load data from ExcelConnector: Error executing read_excel: Worksheet named 'Loading...' not found - Details: {"function": "read_excel", "args": "('C:\\\\Users\\\\luria\\\\PycharmProjects\\\\AuditQAStudio2\\\\test_data\\\\audit_workpapers_2025Q2.xlsx',)", "kwargs": {"sheet_name": "Loading...", "header": 0, "nrows": 50, "na_values": ["#N/A", "#N/A N/A", "#NA", "-NA", "#NULL!", "#NUM!", "#DIV/0!", "#VALUE!", "#REF!", "#NAME?", "#DIV/0", "#NUM", "#REF", "#VALUE"], "engine": "openpyxl", "parse_dates": true}} - Details: {"source_name": "ExcelConnector", "params": {"sheet_name": "Loading...", "header": 0, "nrows": 50, "na_values": ["#N/A", "#N/A N/A", "#NA", "-NA", "#NULL!", "#NUM!", "#DIV/0!", "#VALUE!", "#REF!", "#NAME?", "#DIV/0", "#NUM", "#REF", "#VALUE"], "engine": "openpyxl", "parse_dates": true}}
2025-05-23 14:25:50,343 - data_source_panel - ERROR - Error loading file preview: Failed to load data from ExcelConnector: Error executing read_excel: Worksheet named 'Loading...' not found - Details: {"function": "read_excel", "args": "('C:\\\\Users\\\\luria\\\\PycharmProjects\\\\AuditQAStudio2\\\\test_data\\\\audit_workpapers_2025Q2.xlsx',)", "kwargs": {"sheet_name": "Loading...", "header": 0, "nrows": 50, "na_values": ["#N/A", "#N/A N/A", "#NA", "-NA", "#NULL!", "#NUM!", "#DIV/0!", "#VALUE!", "#REF!", "#NAME?", "#DIV/0", "#NUM", "#REF", "#VALUE"], "engine": "openpyxl", "parse_dates": true}} - Details: {"source_name": "ExcelConnector", "params": {"sheet_name": "Loading...", "header": 0, "nrows": 50, "na_values": ["#N/A", "#N/A N/A", "#NA", "-NA", "#NULL!", "#NUM!", "#DIV/0!", "#VALUE!", "#REF!", "#NAME?", "#DIV/0", "#NUM", "#REF", "#VALUE"], "engine": "openpyxl", "parse_dates": true}}
2025-05-23 14:25:50,345 - data_source_panel - ERROR - Preview error: Error loading file preview: Failed to load data from ExcelConnector: Error executing read_excel: Worksheet named 'Loading...' not found - Details: {"function": "read_excel", "args": "('C:\\\\Users\\\\luria\\\\PycharmProjects\\\\AuditQAStudio2\\\\test_data\\\\audit_workpapers_2025Q2.xlsx',)", "kwargs": {"sheet_name": "Loading...", "header": 0, "nrows": 50, "na_values": ["#N/A", "#N/A N/A", "#NA", "-NA", "#NULL!", "#NUM!", "#DIV/0!", "#VALUE!", "#REF!", "#NAME?", "#DIV/0", "#NUM", "#REF", "#VALUE"], "engine": "openpyxl", "parse_dates": true}} - Details: {"source_name": "ExcelConnector", "params": {"sheet_name": "Loading...", "header": 0, "nrows": 50, "na_values": ["#N/A", "#N/A N/A", "#NA", "-NA", "#NULL!", "#NUM!", "#DIV/0!", "#VALUE!", "#REF!", "#NAME?", "#DIV/0", "#NUM", "#REF", "#VALUE"], "engine": "openpyxl", "parse_dates": true}}
2025-05-23 14:27:43,672 - ui.common.error_handler - CRITICAL - TypeError: Object of type bytes is not JSON serializable
2025-05-23 14:27:44,512 - __main__ - ERROR - ERROR: Object of type bytes is not JSON serializable
2025-05-23 14:32:42,849 - data_integration.connectors.excel_connector - ERROR - Error loading Excel file C:\Users\luria\PycharmProjects\AuditQAStudio2\test_data\audit_workpapers_2025Q2.xlsx: Error executing read_excel: Worksheet named 'Loading...' not found - Details: {"function": "read_excel", "args": "('C:\\\\Users\\\\luria\\\\PycharmProjects\\\\AuditQAStudio2\\\\test_data\\\\audit_workpapers_2025Q2.xlsx',)", "kwargs": {"sheet_name": "Loading...", "header": 0, "nrows": 50, "na_values": ["#N/A", "#N/A N/A", "#NA", "-NA", "#NULL!", "#NUM!", "#DIV/0!", "#VALUE!", "#REF!", "#NAME?", "#DIV/0", "#NUM", "#REF", "#VALUE"], "engine": "openpyxl", "parse_dates": true}}
2025-05-23 14:32:42,849 - data_integration.errors.error_handler - ERROR - Failed to load data from ExcelConnector: Error executing read_excel: Worksheet named 'Loading...' not found - Details: {"function": "read_excel", "args": "('C:\\\\Users\\\\luria\\\\PycharmProjects\\\\AuditQAStudio2\\\\test_data\\\\audit_workpapers_2025Q2.xlsx',)", "kwargs": {"sheet_name": "Loading...", "header": 0, "nrows": 50, "na_values": ["#N/A", "#N/A N/A", "#NA", "-NA", "#NULL!", "#NUM!", "#DIV/0!", "#VALUE!", "#REF!", "#NAME?", "#DIV/0", "#NUM", "#REF", "#VALUE"], "engine": "openpyxl", "parse_dates": true}} - Details: {"source_name": "ExcelConnector", "params": {"sheet_name": "Loading...", "header": 0, "nrows": 50, "na_values": ["#N/A", "#N/A N/A", "#NA", "-NA", "#NULL!", "#NUM!", "#DIV/0!", "#VALUE!", "#REF!", "#NAME?", "#DIV/0", "#NUM", "#REF", "#VALUE"], "engine": "openpyxl", "parse_dates": true}}
Traceback (most recent call last):
  File "C:\Users\luria\PycharmProjects\QAStudiov3\data_integration\errors\error_handler.py", line 328, in safe_dataframe_operation
    return func(*args, **kwargs)
           ^^^^^^^^^^^^^^^^^^^^^
  File "C:\Users\luria\PycharmProjects\QAStudiov3\.venv\Lib\site-packages\pandas\io\excel\_base.py", line 508, in read_excel
    data = io.parse(
           ^^^^^^^^^
  File "C:\Users\luria\PycharmProjects\QAStudiov3\.venv\Lib\site-packages\pandas\io\excel\_base.py", line 1616, in parse
    return self._reader.parse(
           ^^^^^^^^^^^^^^^^^^^
  File "C:\Users\luria\PycharmProjects\QAStudiov3\.venv\Lib\site-packages\pandas\io\excel\_base.py", line 773, in parse
    sheet = self.get_sheet_by_name(asheetname)
            ^^^^^^^^^^^^^^^^^^^^^^^^^^^^^^^^^^
  File "C:\Users\luria\PycharmProjects\QAStudiov3\.venv\Lib\site-packages\pandas\io\excel\_openpyxl.py", line 582, in get_sheet_by_name
    self.raise_if_bad_sheet_by_name(name)
  File "C:\Users\luria\PycharmProjects\QAStudiov3\.venv\Lib\site-packages\pandas\io\excel\_base.py", line 624, in raise_if_bad_sheet_by_name
    raise ValueError(f"Worksheet named '{name}' not found")
ValueError: Worksheet named 'Loading...' not found

During handling of the above exception, another exception occurred:

Traceback (most recent call last):
  File "C:\Users\luria\PycharmProjects\QAStudiov3\data_integration\connectors\excel_connector.py", line 195, in get_data
    df = retry_operation(
         ^^^^^^^^^^^^^^^^
  File "C:\Users\luria\PycharmProjects\QAStudiov3\data_integration\errors\error_handler.py", line 379, in retry_operation
    return func(*args, **kwargs)
           ^^^^^^^^^^^^^^^^^^^^^
  File "C:\Users\luria\PycharmProjects\QAStudiov3\data_integration\connectors\excel_connector.py", line 183, in load_excel
    return safe_dataframe_operation(
           ^^^^^^^^^^^^^^^^^^^^^^^^^
  File "C:\Users\luria\PycharmProjects\QAStudiov3\data_integration\errors\error_handler.py", line 344, in safe_dataframe_operation
    raise DataIntegrationError(error_msg, details)
data_integration.errors.error_handler.DataIntegrationError: Error executing read_excel: Worksheet named 'Loading...' not found - Details: {"function": "read_excel", "args": "('C:\\\\Users\\\\luria\\\\PycharmProjects\\\\AuditQAStudio2\\\\test_data\\\\audit_workpapers_2025Q2.xlsx',)", "kwargs": {"sheet_name": "Loading...", "header": 0, "nrows": 50, "na_values": ["#N/A", "#N/A N/A", "#NA", "-NA", "#NULL!", "#NUM!", "#DIV/0!", "#VALUE!", "#REF!", "#NAME?", "#DIV/0", "#NUM", "#REF", "#VALUE"], "engine": "openpyxl", "parse_dates": true}}
2025-05-23 14:32:42,850 - data_integration.io.importer - ERROR - Error previewing file C:\Users\luria\PycharmProjects\AuditQAStudio2\test_data\audit_workpapers_2025Q2.xlsx: Failed to load data from ExcelConnector: Error executing read_excel: Worksheet named 'Loading...' not found - Details: {"function": "read_excel", "args": "('C:\\\\Users\\\\luria\\\\PycharmProjects\\\\AuditQAStudio2\\\\test_data\\\\audit_workpapers_2025Q2.xlsx',)", "kwargs": {"sheet_name": "Loading...", "header": 0, "nrows": 50, "na_values": ["#N/A", "#N/A N/A", "#NA", "-NA", "#NULL!", "#NUM!", "#DIV/0!", "#VALUE!", "#REF!", "#NAME?", "#DIV/0", "#NUM", "#REF", "#VALUE"], "engine": "openpyxl", "parse_dates": true}} - Details: {"source_name": "ExcelConnector", "params": {"sheet_name": "Loading...", "header": 0, "nrows": 50, "na_values": ["#N/A", "#N/A N/A", "#NA", "-NA", "#NULL!", "#NUM!", "#DIV/0!", "#VALUE!", "#REF!", "#NAME?", "#DIV/0", "#NUM", "#REF", "#VALUE"], "engine": "openpyxl", "parse_dates": true}}
2025-05-23 14:32:42,850 - data_source_panel - ERROR - Error loading file preview: Failed to load data from ExcelConnector: Error executing read_excel: Worksheet named 'Loading...' not found - Details: {"function": "read_excel", "args": "('C:\\\\Users\\\\luria\\\\PycharmProjects\\\\AuditQAStudio2\\\\test_data\\\\audit_workpapers_2025Q2.xlsx',)", "kwargs": {"sheet_name": "Loading...", "header": 0, "nrows": 50, "na_values": ["#N/A", "#N/A N/A", "#NA", "-NA", "#NULL!", "#NUM!", "#DIV/0!", "#VALUE!", "#REF!", "#NAME?", "#DIV/0", "#NUM", "#REF", "#VALUE"], "engine": "openpyxl", "parse_dates": true}} - Details: {"source_name": "ExcelConnector", "params": {"sheet_name": "Loading...", "header": 0, "nrows": 50, "na_values": ["#N/A", "#N/A N/A", "#NA", "-NA", "#NULL!", "#NUM!", "#DIV/0!", "#VALUE!", "#REF!", "#NAME?", "#DIV/0", "#NUM", "#REF", "#VALUE"], "engine": "openpyxl", "parse_dates": true}}
2025-05-23 14:32:42,852 - data_source_panel - ERROR - Preview error: Error loading file preview: Failed to load data from ExcelConnector: Error executing read_excel: Worksheet named 'Loading...' not found - Details: {"function": "read_excel", "args": "('C:\\\\Users\\\\luria\\\\PycharmProjects\\\\AuditQAStudio2\\\\test_data\\\\audit_workpapers_2025Q2.xlsx',)", "kwargs": {"sheet_name": "Loading...", "header": 0, "nrows": 50, "na_values": ["#N/A", "#N/A N/A", "#NA", "-NA", "#NULL!", "#NUM!", "#DIV/0!", "#VALUE!", "#REF!", "#NAME?", "#DIV/0", "#NUM", "#REF", "#VALUE"], "engine": "openpyxl", "parse_dates": true}} - Details: {"source_name": "ExcelConnector", "params": {"sheet_name": "Loading...", "header": 0, "nrows": 50, "na_values": ["#N/A", "#N/A N/A", "#NA", "-NA", "#NULL!", "#NUM!", "#DIV/0!", "#VALUE!", "#REF!", "#NAME?", "#DIV/0", "#NUM", "#REF", "#VALUE"], "engine": "openpyxl", "parse_dates": true}}
2025-05-23 14:33:15,565 - data_integration.connectors.excel_connector - ERROR - Error loading Excel file C:\Users\luria\PycharmProjects\AuditQAStudio2\test_data\audit_workpapers_2025Q2.xlsx: Error executing read_excel: Worksheet named 'Loading...' not found - Details: {"function": "read_excel", "args": "('C:\\\\Users\\\\luria\\\\PycharmProjects\\\\AuditQAStudio2\\\\test_data\\\\audit_workpapers_2025Q2.xlsx',)", "kwargs": {"sheet_name": "Loading...", "header": 0, "nrows": 50, "na_values": ["#N/A", "#N/A N/A", "#NA", "-NA", "#NULL!", "#NUM!", "#DIV/0!", "#VALUE!", "#REF!", "#NAME?", "#DIV/0", "#NUM", "#REF", "#VALUE"], "engine": "openpyxl", "parse_dates": true}}
2025-05-23 14:33:15,565 - data_integration.errors.error_handler - ERROR - Failed to load data from ExcelConnector: Error executing read_excel: Worksheet named 'Loading...' not found - Details: {"function": "read_excel", "args": "('C:\\\\Users\\\\luria\\\\PycharmProjects\\\\AuditQAStudio2\\\\test_data\\\\audit_workpapers_2025Q2.xlsx',)", "kwargs": {"sheet_name": "Loading...", "header": 0, "nrows": 50, "na_values": ["#N/A", "#N/A N/A", "#NA", "-NA", "#NULL!", "#NUM!", "#DIV/0!", "#VALUE!", "#REF!", "#NAME?", "#DIV/0", "#NUM", "#REF", "#VALUE"], "engine": "openpyxl", "parse_dates": true}} - Details: {"source_name": "ExcelConnector", "params": {"sheet_name": "Loading...", "header": 0, "nrows": 50, "na_values": ["#N/A", "#N/A N/A", "#NA", "-NA", "#NULL!", "#NUM!", "#DIV/0!", "#VALUE!", "#REF!", "#NAME?", "#DIV/0", "#NUM", "#REF", "#VALUE"], "engine": "openpyxl", "parse_dates": true}}
Traceback (most recent call last):
  File "C:\Users\luria\PycharmProjects\QAStudiov3\data_integration\errors\error_handler.py", line 328, in safe_dataframe_operation
    return func(*args, **kwargs)
           ^^^^^^^^^^^^^^^^^^^^^
  File "C:\Users\luria\PycharmProjects\QAStudiov3\.venv\Lib\site-packages\pandas\io\excel\_base.py", line 508, in read_excel
    data = io.parse(
           ^^^^^^^^^
  File "C:\Users\luria\PycharmProjects\QAStudiov3\.venv\Lib\site-packages\pandas\io\excel\_base.py", line 1616, in parse
    return self._reader.parse(
           ^^^^^^^^^^^^^^^^^^^
  File "C:\Users\luria\PycharmProjects\QAStudiov3\.venv\Lib\site-packages\pandas\io\excel\_base.py", line 773, in parse
    sheet = self.get_sheet_by_name(asheetname)
            ^^^^^^^^^^^^^^^^^^^^^^^^^^^^^^^^^^
  File "C:\Users\luria\PycharmProjects\QAStudiov3\.venv\Lib\site-packages\pandas\io\excel\_openpyxl.py", line 582, in get_sheet_by_name
    self.raise_if_bad_sheet_by_name(name)
  File "C:\Users\luria\PycharmProjects\QAStudiov3\.venv\Lib\site-packages\pandas\io\excel\_base.py", line 624, in raise_if_bad_sheet_by_name
    raise ValueError(f"Worksheet named '{name}' not found")
ValueError: Worksheet named 'Loading...' not found

During handling of the above exception, another exception occurred:

Traceback (most recent call last):
  File "C:\Users\luria\PycharmProjects\QAStudiov3\data_integration\connectors\excel_connector.py", line 195, in get_data
    df = retry_operation(
         ^^^^^^^^^^^^^^^^
  File "C:\Users\luria\PycharmProjects\QAStudiov3\data_integration\errors\error_handler.py", line 379, in retry_operation
    return func(*args, **kwargs)
           ^^^^^^^^^^^^^^^^^^^^^
  File "C:\Users\luria\PycharmProjects\QAStudiov3\data_integration\connectors\excel_connector.py", line 183, in load_excel
    return safe_dataframe_operation(
           ^^^^^^^^^^^^^^^^^^^^^^^^^
  File "C:\Users\luria\PycharmProjects\QAStudiov3\data_integration\errors\error_handler.py", line 344, in safe_dataframe_operation
    raise DataIntegrationError(error_msg, details)
data_integration.errors.error_handler.DataIntegrationError: Error executing read_excel: Worksheet named 'Loading...' not found - Details: {"function": "read_excel", "args": "('C:\\\\Users\\\\luria\\\\PycharmProjects\\\\AuditQAStudio2\\\\test_data\\\\audit_workpapers_2025Q2.xlsx',)", "kwargs": {"sheet_name": "Loading...", "header": 0, "nrows": 50, "na_values": ["#N/A", "#N/A N/A", "#NA", "-NA", "#NULL!", "#NUM!", "#DIV/0!", "#VALUE!", "#REF!", "#NAME?", "#DIV/0", "#NUM", "#REF", "#VALUE"], "engine": "openpyxl", "parse_dates": true}}
2025-05-23 14:33:15,566 - data_integration.io.importer - ERROR - Error previewing file C:\Users\luria\PycharmProjects\AuditQAStudio2\test_data\audit_workpapers_2025Q2.xlsx: Failed to load data from ExcelConnector: Error executing read_excel: Worksheet named 'Loading...' not found - Details: {"function": "read_excel", "args": "('C:\\\\Users\\\\luria\\\\PycharmProjects\\\\AuditQAStudio2\\\\test_data\\\\audit_workpapers_2025Q2.xlsx',)", "kwargs": {"sheet_name": "Loading...", "header": 0, "nrows": 50, "na_values": ["#N/A", "#N/A N/A", "#NA", "-NA", "#NULL!", "#NUM!", "#DIV/0!", "#VALUE!", "#REF!", "#NAME?", "#DIV/0", "#NUM", "#REF", "#VALUE"], "engine": "openpyxl", "parse_dates": true}} - Details: {"source_name": "ExcelConnector", "params": {"sheet_name": "Loading...", "header": 0, "nrows": 50, "na_values": ["#N/A", "#N/A N/A", "#NA", "-NA", "#NULL!", "#NUM!", "#DIV/0!", "#VALUE!", "#REF!", "#NAME?", "#DIV/0", "#NUM", "#REF", "#VALUE"], "engine": "openpyxl", "parse_dates": true}}
2025-05-23 14:33:15,566 - data_source_panel - ERROR - Error loading file preview: Failed to load data from ExcelConnector: Error executing read_excel: Worksheet named 'Loading...' not found - Details: {"function": "read_excel", "args": "('C:\\\\Users\\\\luria\\\\PycharmProjects\\\\AuditQAStudio2\\\\test_data\\\\audit_workpapers_2025Q2.xlsx',)", "kwargs": {"sheet_name": "Loading...", "header": 0, "nrows": 50, "na_values": ["#N/A", "#N/A N/A", "#NA", "-NA", "#NULL!", "#NUM!", "#DIV/0!", "#VALUE!", "#REF!", "#NAME?", "#DIV/0", "#NUM", "#REF", "#VALUE"], "engine": "openpyxl", "parse_dates": true}} - Details: {"source_name": "ExcelConnector", "params": {"sheet_name": "Loading...", "header": 0, "nrows": 50, "na_values": ["#N/A", "#N/A N/A", "#NA", "-NA", "#NULL!", "#NUM!", "#DIV/0!", "#VALUE!", "#REF!", "#NAME?", "#DIV/0", "#NUM", "#REF", "#VALUE"], "engine": "openpyxl", "parse_dates": true}}
2025-05-23 14:33:15,567 - data_source_panel - ERROR - Preview error: Error loading file preview: Failed to load data from ExcelConnector: Error executing read_excel: Worksheet named 'Loading...' not found - Details: {"function": "read_excel", "args": "('C:\\\\Users\\\\luria\\\\PycharmProjects\\\\AuditQAStudio2\\\\test_data\\\\audit_workpapers_2025Q2.xlsx',)", "kwargs": {"sheet_name": "Loading...", "header": 0, "nrows": 50, "na_values": ["#N/A", "#N/A N/A", "#NA", "-NA", "#NULL!", "#NUM!", "#DIV/0!", "#VALUE!", "#REF!", "#NAME?", "#DIV/0", "#NUM", "#REF", "#VALUE"], "engine": "openpyxl", "parse_dates": true}} - Details: {"source_name": "ExcelConnector", "params": {"sheet_name": "Loading...", "header": 0, "nrows": 50, "na_values": ["#N/A", "#N/A N/A", "#NA", "-NA", "#NULL!", "#NUM!", "#DIV/0!", "#VALUE!", "#REF!", "#NAME?", "#DIV/0", "#NUM", "#REF", "#VALUE"], "engine": "openpyxl", "parse_dates": true}}
2025-05-23 14:33:39,975 - rule_editor_panel - ERROR - No current rule to save
2025-05-23 14:33:44,907 - rule_editor_panel - ERROR - No current rule to save
2025-05-23 14:34:07,473 - rule_editor_panel - ERROR - No current rule to save
2025-05-23 14:34:31,939 - ui.common.error_handler - CRITICAL - TypeError: Object of type bytes is not JSON serializable
2025-05-23 14:34:32,741 - __main__ - ERROR - ERROR: Object of type bytes is not JSON serializable
2025-05-23 14:36:21,045 - data_integration.connectors.excel_connector - ERROR - Error loading Excel file C:\Users\luria\PycharmProjects\AuditQAStudio2\test_data\audit_workpapers_2025Q2.xlsx: Error executing read_excel: Worksheet named 'Loading...' not found - Details: {"function": "read_excel", "args": "('C:\\\\Users\\\\luria\\\\PycharmProjects\\\\AuditQAStudio2\\\\test_data\\\\audit_workpapers_2025Q2.xlsx',)", "kwargs": {"sheet_name": "Loading...", "header": 0, "nrows": 50, "na_values": ["#N/A", "#N/A N/A", "#NA", "-NA", "#NULL!", "#NUM!", "#DIV/0!", "#VALUE!", "#REF!", "#NAME?", "#DIV/0", "#NUM", "#REF", "#VALUE"], "engine": "openpyxl", "parse_dates": true}}
2025-05-23 14:36:21,045 - data_integration.errors.error_handler - ERROR - Failed to load data from ExcelConnector: Error executing read_excel: Worksheet named 'Loading...' not found - Details: {"function": "read_excel", "args": "('C:\\\\Users\\\\luria\\\\PycharmProjects\\\\AuditQAStudio2\\\\test_data\\\\audit_workpapers_2025Q2.xlsx',)", "kwargs": {"sheet_name": "Loading...", "header": 0, "nrows": 50, "na_values": ["#N/A", "#N/A N/A", "#NA", "-NA", "#NULL!", "#NUM!", "#DIV/0!", "#VALUE!", "#REF!", "#NAME?", "#DIV/0", "#NUM", "#REF", "#VALUE"], "engine": "openpyxl", "parse_dates": true}} - Details: {"source_name": "ExcelConnector", "params": {"sheet_name": "Loading...", "header": 0, "nrows": 50, "na_values": ["#N/A", "#N/A N/A", "#NA", "-NA", "#NULL!", "#NUM!", "#DIV/0!", "#VALUE!", "#REF!", "#NAME?", "#DIV/0", "#NUM", "#REF", "#VALUE"], "engine": "openpyxl", "parse_dates": true}}
Traceback (most recent call last):
  File "C:\Users\luria\PycharmProjects\QAStudiov3\data_integration\errors\error_handler.py", line 328, in safe_dataframe_operation
    return func(*args, **kwargs)
           ^^^^^^^^^^^^^^^^^^^^^
  File "C:\Users\luria\PycharmProjects\QAStudiov3\.venv\Lib\site-packages\pandas\io\excel\_base.py", line 508, in read_excel
    data = io.parse(
           ^^^^^^^^^
  File "C:\Users\luria\PycharmProjects\QAStudiov3\.venv\Lib\site-packages\pandas\io\excel\_base.py", line 1616, in parse
    return self._reader.parse(
           ^^^^^^^^^^^^^^^^^^^
  File "C:\Users\luria\PycharmProjects\QAStudiov3\.venv\Lib\site-packages\pandas\io\excel\_base.py", line 773, in parse
    sheet = self.get_sheet_by_name(asheetname)
            ^^^^^^^^^^^^^^^^^^^^^^^^^^^^^^^^^^
  File "C:\Users\luria\PycharmProjects\QAStudiov3\.venv\Lib\site-packages\pandas\io\excel\_openpyxl.py", line 582, in get_sheet_by_name
    self.raise_if_bad_sheet_by_name(name)
  File "C:\Users\luria\PycharmProjects\QAStudiov3\.venv\Lib\site-packages\pandas\io\excel\_base.py", line 624, in raise_if_bad_sheet_by_name
    raise ValueError(f"Worksheet named '{name}' not found")
ValueError: Worksheet named 'Loading...' not found

During handling of the above exception, another exception occurred:

Traceback (most recent call last):
  File "C:\Users\luria\PycharmProjects\QAStudiov3\data_integration\connectors\excel_connector.py", line 195, in get_data
    df = retry_operation(
         ^^^^^^^^^^^^^^^^
  File "C:\Users\luria\PycharmProjects\QAStudiov3\data_integration\errors\error_handler.py", line 379, in retry_operation
    return func(*args, **kwargs)
           ^^^^^^^^^^^^^^^^^^^^^
  File "C:\Users\luria\PycharmProjects\QAStudiov3\data_integration\connectors\excel_connector.py", line 183, in load_excel
    return safe_dataframe_operation(
           ^^^^^^^^^^^^^^^^^^^^^^^^^
  File "C:\Users\luria\PycharmProjects\QAStudiov3\data_integration\errors\error_handler.py", line 344, in safe_dataframe_operation
    raise DataIntegrationError(error_msg, details)
data_integration.errors.error_handler.DataIntegrationError: Error executing read_excel: Worksheet named 'Loading...' not found - Details: {"function": "read_excel", "args": "('C:\\\\Users\\\\luria\\\\PycharmProjects\\\\AuditQAStudio2\\\\test_data\\\\audit_workpapers_2025Q2.xlsx',)", "kwargs": {"sheet_name": "Loading...", "header": 0, "nrows": 50, "na_values": ["#N/A", "#N/A N/A", "#NA", "-NA", "#NULL!", "#NUM!", "#DIV/0!", "#VALUE!", "#REF!", "#NAME?", "#DIV/0", "#NUM", "#REF", "#VALUE"], "engine": "openpyxl", "parse_dates": true}}
2025-05-23 14:36:21,046 - data_integration.io.importer - ERROR - Error previewing file C:\Users\luria\PycharmProjects\AuditQAStudio2\test_data\audit_workpapers_2025Q2.xlsx: Failed to load data from ExcelConnector: Error executing read_excel: Worksheet named 'Loading...' not found - Details: {"function": "read_excel", "args": "('C:\\\\Users\\\\luria\\\\PycharmProjects\\\\AuditQAStudio2\\\\test_data\\\\audit_workpapers_2025Q2.xlsx',)", "kwargs": {"sheet_name": "Loading...", "header": 0, "nrows": 50, "na_values": ["#N/A", "#N/A N/A", "#NA", "-NA", "#NULL!", "#NUM!", "#DIV/0!", "#VALUE!", "#REF!", "#NAME?", "#DIV/0", "#NUM", "#REF", "#VALUE"], "engine": "openpyxl", "parse_dates": true}} - Details: {"source_name": "ExcelConnector", "params": {"sheet_name": "Loading...", "header": 0, "nrows": 50, "na_values": ["#N/A", "#N/A N/A", "#NA", "-NA", "#NULL!", "#NUM!", "#DIV/0!", "#VALUE!", "#REF!", "#NAME?", "#DIV/0", "#NUM", "#REF", "#VALUE"], "engine": "openpyxl", "parse_dates": true}}
2025-05-23 14:36:21,047 - data_source_panel - ERROR - Error loading file preview: Failed to load data from ExcelConnector: Error executing read_excel: Worksheet named 'Loading...' not found - Details: {"function": "read_excel", "args": "('C:\\\\Users\\\\luria\\\\PycharmProjects\\\\AuditQAStudio2\\\\test_data\\\\audit_workpapers_2025Q2.xlsx',)", "kwargs": {"sheet_name": "Loading...", "header": 0, "nrows": 50, "na_values": ["#N/A", "#N/A N/A", "#NA", "-NA", "#NULL!", "#NUM!", "#DIV/0!", "#VALUE!", "#REF!", "#NAME?", "#DIV/0", "#NUM", "#REF", "#VALUE"], "engine": "openpyxl", "parse_dates": true}} - Details: {"source_name": "ExcelConnector", "params": {"sheet_name": "Loading...", "header": 0, "nrows": 50, "na_values": ["#N/A", "#N/A N/A", "#NA", "-NA", "#NULL!", "#NUM!", "#DIV/0!", "#VALUE!", "#REF!", "#NAME?", "#DIV/0", "#NUM", "#REF", "#VALUE"], "engine": "openpyxl", "parse_dates": true}}
2025-05-23 14:36:21,048 - data_source_panel - ERROR - Preview error: Error loading file preview: Failed to load data from ExcelConnector: Error executing read_excel: Worksheet named 'Loading...' not found - Details: {"function": "read_excel", "args": "('C:\\\\Users\\\\luria\\\\PycharmProjects\\\\AuditQAStudio2\\\\test_data\\\\audit_workpapers_2025Q2.xlsx',)", "kwargs": {"sheet_name": "Loading...", "header": 0, "nrows": 50, "na_values": ["#N/A", "#N/A N/A", "#NA", "-NA", "#NULL!", "#NUM!", "#DIV/0!", "#VALUE!", "#REF!", "#NAME?", "#DIV/0", "#NUM", "#REF", "#VALUE"], "engine": "openpyxl", "parse_dates": true}} - Details: {"source_name": "ExcelConnector", "params": {"sheet_name": "Loading...", "header": 0, "nrows": 50, "na_values": ["#N/A", "#N/A N/A", "#NA", "-NA", "#NULL!", "#NUM!", "#DIV/0!", "#VALUE!", "#REF!", "#NAME?", "#DIV/0", "#NUM", "#REF", "#VALUE"], "engine": "openpyxl", "parse_dates": true}}
2025-05-23 14:36:45,000 - rule_selector_panel - ERROR - Error loading rules: type object 'PySide6.QtCore.Qt' has no attribute 'ItemIsTristate'
2025-05-23 14:36:50,960 - ui.common.error_handler - CRITICAL - AttributeError: type object 'PySide6.QtCore.Qt' has no attribute 'ItemIsTristate'
2025-05-23 14:38:08,967 - __main__ - ERROR - ERROR: type object 'PySide6.QtCore.Qt' has no attribute 'ItemIsTristate'
2025-05-23 14:40:23,235 - ui.common.error_handler - CRITICAL - TypeError: Object of type bytes is not JSON serializable
2025-05-23 14:40:24,252 - __main__ - ERROR - ERROR: Object of type bytes is not JSON serializable
2025-05-23 14:40:28,153 - rule_selector_panel - ERROR - Error loading rules: type object 'PySide6.QtCore.Qt' has no attribute 'ItemIsTristate'
2025-05-23 14:40:55,339 - ui.common.error_handler - CRITICAL - TypeError: Object of type bytes is not JSON serializable
2025-05-23 14:40:56,935 - __main__ - ERROR - ERROR: Object of type bytes is not JSON serializable
2025-05-23 14:40:58,945 - rule_selector_panel - ERROR - Error loading rules: type object 'PySide6.QtCore.Qt' has no attribute 'Itemflag'
2025-05-23 14:41:09,344 - ui.common.error_handler - CRITICAL - TypeError: Object of type bytes is not JSON serializable
2025-05-23 14:41:10,472 - __main__ - ERROR - ERROR: Object of type bytes is not JSON serializable
2025-05-23 14:41:12,364 - rule_selector_panel - ERROR - Error loading rules: type object 'ItemFlag' has no attribute 'ItemIsTristate'
2025-05-23 14:42:14,980 - ui.common.error_handler - CRITICAL - TypeError: Object of type bytes is not JSON serializable
2025-05-23 14:42:16,093 - __main__ - ERROR - ERROR: Object of type bytes is not JSON serializable
2025-05-23 14:42:17,903 - ui.common.error_handler - CRITICAL - TypeError: Object of type bytes is not JSON serializable
2025-05-23 14:42:18,962 - ui.common.error_handler - CRITICAL - TypeError: Object of type bytes is not JSON serializable
2025-05-23 14:42:26,379 - ui.common.error_handler - CRITICAL - TypeError: Object of type bytes is not JSON serializable
2025-05-23 14:42:27,368 - ui.common.error_handler - CRITICAL - TypeError: Object of type bytes is not JSON serializable
2025-05-23 14:42:43,218 - ui.common.error_handler - CRITICAL - TypeError: Object of type bytes is not JSON serializable
2025-05-23 14:42:44,123 - __main__ - ERROR - ERROR: Object of type bytes is not JSON serializable
2025-05-23 14:42:50,514 - ui.common.error_handler - CRITICAL - TypeError: Object of type bytes is not JSON serializable
2025-05-23 14:42:51,899 - __main__ - ERROR - ERROR: Object of type bytes is not JSON serializable
2025-05-23 14:43:00,927 - ui.common.error_handler - CRITICAL - TypeError: Object of type bytes is not JSON serializable
2025-05-23 14:43:30,690 - __main__ - ERROR - ERROR: Object of type bytes is not JSON serializable
2025-05-23 14:43:32,573 - ui.common.error_handler - CRITICAL - TypeError: Object of type bytes is not JSON serializable
2025-05-23 14:43:33,615 - __main__ - ERROR - ERROR: Object of type bytes is not JSON serializable
2025-05-23 14:44:36,751 - data_integration.connectors.excel_connector - ERROR - Error loading Excel file C:/Users/luria/PycharmProjects/AuditQAStudio2/test_data/audit_workpapers_2025Q2.xlsx: Error executing read_excel: Worksheet named 'Loading...' not found - Details: {"function": "read_excel", "args": "('C:/Users/luria/PycharmProjects/AuditQAStudio2/test_data/audit_workpapers_2025Q2.xlsx',)", "kwargs": {"sheet_name": "Loading...", "header": 0, "nrows": 50, "na_values": ["#N/A", "#N/A N/A", "#NA", "-NA", "#NULL!", "#NUM!", "#DIV/0!", "#VALUE!", "#REF!", "#NAME?", "#DIV/0", "#NUM", "#REF", "#VALUE"], "engine": "openpyxl", "parse_dates": true}}
2025-05-23 14:44:36,752 - data_integration.errors.error_handler - ERROR - Failed to load data from ExcelConnector: Error executing read_excel: Worksheet named 'Loading...' not found - Details: {"function": "read_excel", "args": "('C:/Users/luria/PycharmProjects/AuditQAStudio2/test_data/audit_workpapers_2025Q2.xlsx',)", "kwargs": {"sheet_name": "Loading...", "header": 0, "nrows": 50, "na_values": ["#N/A", "#N/A N/A", "#NA", "-NA", "#NULL!", "#NUM!", "#DIV/0!", "#VALUE!", "#REF!", "#NAME?", "#DIV/0", "#NUM", "#REF", "#VALUE"], "engine": "openpyxl", "parse_dates": true}} - Details: {"source_name": "ExcelConnector", "params": {"sheet_name": "Loading...", "header": 0, "nrows": 50, "na_values": ["#N/A", "#N/A N/A", "#NA", "-NA", "#NULL!", "#NUM!", "#DIV/0!", "#VALUE!", "#REF!", "#NAME?", "#DIV/0", "#NUM", "#REF", "#VALUE"], "engine": "openpyxl", "parse_dates": true}}
Traceback (most recent call last):
  File "C:\Users\luria\PycharmProjects\QAStudiov3\data_integration\errors\error_handler.py", line 328, in safe_dataframe_operation
    return func(*args, **kwargs)
           ^^^^^^^^^^^^^^^^^^^^^
  File "C:\Users\luria\PycharmProjects\QAStudiov3\.venv\Lib\site-packages\pandas\io\excel\_base.py", line 508, in read_excel
    data = io.parse(
           ^^^^^^^^^
  File "C:\Users\luria\PycharmProjects\QAStudiov3\.venv\Lib\site-packages\pandas\io\excel\_base.py", line 1616, in parse
    return self._reader.parse(
           ^^^^^^^^^^^^^^^^^^^
  File "C:\Users\luria\PycharmProjects\QAStudiov3\.venv\Lib\site-packages\pandas\io\excel\_base.py", line 773, in parse
    sheet = self.get_sheet_by_name(asheetname)
            ^^^^^^^^^^^^^^^^^^^^^^^^^^^^^^^^^^
  File "C:\Users\luria\PycharmProjects\QAStudiov3\.venv\Lib\site-packages\pandas\io\excel\_openpyxl.py", line 582, in get_sheet_by_name
    self.raise_if_bad_sheet_by_name(name)
  File "C:\Users\luria\PycharmProjects\QAStudiov3\.venv\Lib\site-packages\pandas\io\excel\_base.py", line 624, in raise_if_bad_sheet_by_name
    raise ValueError(f"Worksheet named '{name}' not found")
ValueError: Worksheet named 'Loading...' not found

During handling of the above exception, another exception occurred:

Traceback (most recent call last):
  File "C:\Users\luria\PycharmProjects\QAStudiov3\data_integration\connectors\excel_connector.py", line 195, in get_data
    df = retry_operation(
         ^^^^^^^^^^^^^^^^
  File "C:\Users\luria\PycharmProjects\QAStudiov3\data_integration\errors\error_handler.py", line 379, in retry_operation
    return func(*args, **kwargs)
           ^^^^^^^^^^^^^^^^^^^^^
  File "C:\Users\luria\PycharmProjects\QAStudiov3\data_integration\connectors\excel_connector.py", line 183, in load_excel
    return safe_dataframe_operation(
           ^^^^^^^^^^^^^^^^^^^^^^^^^
  File "C:\Users\luria\PycharmProjects\QAStudiov3\data_integration\errors\error_handler.py", line 344, in safe_dataframe_operation
    raise DataIntegrationError(error_msg, details)
data_integration.errors.error_handler.DataIntegrationError: Error executing read_excel: Worksheet named 'Loading...' not found - Details: {"function": "read_excel", "args": "('C:/Users/luria/PycharmProjects/AuditQAStudio2/test_data/audit_workpapers_2025Q2.xlsx',)", "kwargs": {"sheet_name": "Loading...", "header": 0, "nrows": 50, "na_values": ["#N/A", "#N/A N/A", "#NA", "-NA", "#NULL!", "#NUM!", "#DIV/0!", "#VALUE!", "#REF!", "#NAME?", "#DIV/0", "#NUM", "#REF", "#VALUE"], "engine": "openpyxl", "parse_dates": true}}
2025-05-23 14:44:36,753 - data_integration.io.importer - ERROR - Error previewing file C:/Users/luria/PycharmProjects/AuditQAStudio2/test_data/audit_workpapers_2025Q2.xlsx: Failed to load data from ExcelConnector: Error executing read_excel: Worksheet named 'Loading...' not found - Details: {"function": "read_excel", "args": "('C:/Users/luria/PycharmProjects/AuditQAStudio2/test_data/audit_workpapers_2025Q2.xlsx',)", "kwargs": {"sheet_name": "Loading...", "header": 0, "nrows": 50, "na_values": ["#N/A", "#N/A N/A", "#NA", "-NA", "#NULL!", "#NUM!", "#DIV/0!", "#VALUE!", "#REF!", "#NAME?", "#DIV/0", "#NUM", "#REF", "#VALUE"], "engine": "openpyxl", "parse_dates": true}} - Details: {"source_name": "ExcelConnector", "params": {"sheet_name": "Loading...", "header": 0, "nrows": 50, "na_values": ["#N/A", "#N/A N/A", "#NA", "-NA", "#NULL!", "#NUM!", "#DIV/0!", "#VALUE!", "#REF!", "#NAME?", "#DIV/0", "#NUM", "#REF", "#VALUE"], "engine": "openpyxl", "parse_dates": true}}
2025-05-23 14:44:36,753 - data_source_panel - ERROR - Error loading file preview: Failed to load data from ExcelConnector: Error executing read_excel: Worksheet named 'Loading...' not found - Details: {"function": "read_excel", "args": "('C:/Users/luria/PycharmProjects/AuditQAStudio2/test_data/audit_workpapers_2025Q2.xlsx',)", "kwargs": {"sheet_name": "Loading...", "header": 0, "nrows": 50, "na_values": ["#N/A", "#N/A N/A", "#NA", "-NA", "#NULL!", "#NUM!", "#DIV/0!", "#VALUE!", "#REF!", "#NAME?", "#DIV/0", "#NUM", "#REF", "#VALUE"], "engine": "openpyxl", "parse_dates": true}} - Details: {"source_name": "ExcelConnector", "params": {"sheet_name": "Loading...", "header": 0, "nrows": 50, "na_values": ["#N/A", "#N/A N/A", "#NA", "-NA", "#NULL!", "#NUM!", "#DIV/0!", "#VALUE!", "#REF!", "#NAME?", "#DIV/0", "#NUM", "#REF", "#VALUE"], "engine": "openpyxl", "parse_dates": true}}
2025-05-23 14:44:36,755 - data_source_panel - ERROR - Preview error: Error loading file preview: Failed to load data from ExcelConnector: Error executing read_excel: Worksheet named 'Loading...' not found - Details: {"function": "read_excel", "args": "('C:/Users/luria/PycharmProjects/AuditQAStudio2/test_data/audit_workpapers_2025Q2.xlsx',)", "kwargs": {"sheet_name": "Loading...", "header": 0, "nrows": 50, "na_values": ["#N/A", "#N/A N/A", "#NA", "-NA", "#NULL!", "#NUM!", "#DIV/0!", "#VALUE!", "#REF!", "#NAME?", "#DIV/0", "#NUM", "#REF", "#VALUE"], "engine": "openpyxl", "parse_dates": true}} - Details: {"source_name": "ExcelConnector", "params": {"sheet_name": "Loading...", "header": 0, "nrows": 50, "na_values": ["#N/A", "#N/A N/A", "#NA", "-NA", "#NULL!", "#NUM!", "#DIV/0!", "#VALUE!", "#REF!", "#NAME?", "#DIV/0", "#NUM", "#REF", "#VALUE"], "engine": "openpyxl", "parse_dates": true}}
2025-05-23 14:49:27,448 - ui.common.error_handler - ERROR - AttributeError: type object 'AnalyticsRunnerStylesheet' has no attribute 'FONT_SIZE_REGULAR'
2025-05-23 14:49:31,674 - ui.common.error_handler - CRITICAL - AttributeError: 'AnalyticsRunnerApp' object has no attribute 'log_view'
2025-05-23 15:03:59,165 - data_integration.connectors.excel_connector - ERROR - Error loading Excel file C:/Users/luria/PycharmProjects/AuditQAStudio2/test_data/audit_workpapers_2025Q2.xlsx: Error executing read_excel: Worksheet named 'Loading...' not found - Details: {"function": "read_excel", "args": "('C:/Users/luria/PycharmProjects/AuditQAStudio2/test_data/audit_workpapers_2025Q2.xlsx',)", "kwargs": {"sheet_name": "Loading...", "header": 0, "nrows": 50, "na_values": ["#N/A", "#N/A N/A", "#NA", "-NA", "#NULL!", "#NUM!", "#DIV/0!", "#VALUE!", "#REF!", "#NAME?", "#DIV/0", "#NUM", "#REF", "#VALUE"], "engine": "openpyxl", "parse_dates": true}}
2025-05-23 15:03:59,165 - data_integration.errors.error_handler - ERROR - Failed to load data from ExcelConnector: Error executing read_excel: Worksheet named 'Loading...' not found - Details: {"function": "read_excel", "args": "('C:/Users/luria/PycharmProjects/AuditQAStudio2/test_data/audit_workpapers_2025Q2.xlsx',)", "kwargs": {"sheet_name": "Loading...", "header": 0, "nrows": 50, "na_values": ["#N/A", "#N/A N/A", "#NA", "-NA", "#NULL!", "#NUM!", "#DIV/0!", "#VALUE!", "#REF!", "#NAME?", "#DIV/0", "#NUM", "#REF", "#VALUE"], "engine": "openpyxl", "parse_dates": true}} - Details: {"source_name": "ExcelConnector", "params": {"sheet_name": "Loading...", "header": 0, "nrows": 50, "na_values": ["#N/A", "#N/A N/A", "#NA", "-NA", "#NULL!", "#NUM!", "#DIV/0!", "#VALUE!", "#REF!", "#NAME?", "#DIV/0", "#NUM", "#REF", "#VALUE"], "engine": "openpyxl", "parse_dates": true}}
Traceback (most recent call last):
  File "C:\Users\luria\PycharmProjects\QAStudiov3\data_integration\errors\error_handler.py", line 328, in safe_dataframe_operation
    return func(*args, **kwargs)
           ^^^^^^^^^^^^^^^^^^^^^
  File "C:\Users\luria\PycharmProjects\QAStudiov3\.venv\Lib\site-packages\pandas\io\excel\_base.py", line 508, in read_excel
    data = io.parse(
           ^^^^^^^^^
  File "C:\Users\luria\PycharmProjects\QAStudiov3\.venv\Lib\site-packages\pandas\io\excel\_base.py", line 1616, in parse
    return self._reader.parse(
           ^^^^^^^^^^^^^^^^^^^
  File "C:\Users\luria\PycharmProjects\QAStudiov3\.venv\Lib\site-packages\pandas\io\excel\_base.py", line 773, in parse
    sheet = self.get_sheet_by_name(asheetname)
            ^^^^^^^^^^^^^^^^^^^^^^^^^^^^^^^^^^
  File "C:\Users\luria\PycharmProjects\QAStudiov3\.venv\Lib\site-packages\pandas\io\excel\_openpyxl.py", line 582, in get_sheet_by_name
    self.raise_if_bad_sheet_by_name(name)
  File "C:\Users\luria\PycharmProjects\QAStudiov3\.venv\Lib\site-packages\pandas\io\excel\_base.py", line 624, in raise_if_bad_sheet_by_name
    raise ValueError(f"Worksheet named '{name}' not found")
ValueError: Worksheet named 'Loading...' not found

During handling of the above exception, another exception occurred:

Traceback (most recent call last):
  File "C:\Users\luria\PycharmProjects\QAStudiov3\data_integration\connectors\excel_connector.py", line 195, in get_data
    df = retry_operation(
         ^^^^^^^^^^^^^^^^
  File "C:\Users\luria\PycharmProjects\QAStudiov3\data_integration\errors\error_handler.py", line 379, in retry_operation
    return func(*args, **kwargs)
           ^^^^^^^^^^^^^^^^^^^^^
  File "C:\Users\luria\PycharmProjects\QAStudiov3\data_integration\connectors\excel_connector.py", line 183, in load_excel
    return safe_dataframe_operation(
           ^^^^^^^^^^^^^^^^^^^^^^^^^
  File "C:\Users\luria\PycharmProjects\QAStudiov3\data_integration\errors\error_handler.py", line 344, in safe_dataframe_operation
    raise DataIntegrationError(error_msg, details)
data_integration.errors.error_handler.DataIntegrationError: Error executing read_excel: Worksheet named 'Loading...' not found - Details: {"function": "read_excel", "args": "('C:/Users/luria/PycharmProjects/AuditQAStudio2/test_data/audit_workpapers_2025Q2.xlsx',)", "kwargs": {"sheet_name": "Loading...", "header": 0, "nrows": 50, "na_values": ["#N/A", "#N/A N/A", "#NA", "-NA", "#NULL!", "#NUM!", "#DIV/0!", "#VALUE!", "#REF!", "#NAME?", "#DIV/0", "#NUM", "#REF", "#VALUE"], "engine": "openpyxl", "parse_dates": true}}
2025-05-23 15:03:59,166 - data_integration.io.importer - ERROR - Error previewing file C:/Users/luria/PycharmProjects/AuditQAStudio2/test_data/audit_workpapers_2025Q2.xlsx: Failed to load data from ExcelConnector: Error executing read_excel: Worksheet named 'Loading...' not found - Details: {"function": "read_excel", "args": "('C:/Users/luria/PycharmProjects/AuditQAStudio2/test_data/audit_workpapers_2025Q2.xlsx',)", "kwargs": {"sheet_name": "Loading...", "header": 0, "nrows": 50, "na_values": ["#N/A", "#N/A N/A", "#NA", "-NA", "#NULL!", "#NUM!", "#DIV/0!", "#VALUE!", "#REF!", "#NAME?", "#DIV/0", "#NUM", "#REF", "#VALUE"], "engine": "openpyxl", "parse_dates": true}} - Details: {"source_name": "ExcelConnector", "params": {"sheet_name": "Loading...", "header": 0, "nrows": 50, "na_values": ["#N/A", "#N/A N/A", "#NA", "-NA", "#NULL!", "#NUM!", "#DIV/0!", "#VALUE!", "#REF!", "#NAME?", "#DIV/0", "#NUM", "#REF", "#VALUE"], "engine": "openpyxl", "parse_dates": true}}
2025-05-23 15:03:59,166 - data_source_panel - ERROR - Error loading file preview: Failed to load data from ExcelConnector: Error executing read_excel: Worksheet named 'Loading...' not found - Details: {"function": "read_excel", "args": "('C:/Users/luria/PycharmProjects/AuditQAStudio2/test_data/audit_workpapers_2025Q2.xlsx',)", "kwargs": {"sheet_name": "Loading...", "header": 0, "nrows": 50, "na_values": ["#N/A", "#N/A N/A", "#NA", "-NA", "#NULL!", "#NUM!", "#DIV/0!", "#VALUE!", "#REF!", "#NAME?", "#DIV/0", "#NUM", "#REF", "#VALUE"], "engine": "openpyxl", "parse_dates": true}} - Details: {"source_name": "ExcelConnector", "params": {"sheet_name": "Loading...", "header": 0, "nrows": 50, "na_values": ["#N/A", "#N/A N/A", "#NA", "-NA", "#NULL!", "#NUM!", "#DIV/0!", "#VALUE!", "#REF!", "#NAME?", "#DIV/0", "#NUM", "#REF", "#VALUE"], "engine": "openpyxl", "parse_dates": true}}
2025-05-23 15:03:59,168 - data_source_panel - ERROR - Preview error: Error loading file preview: Failed to load data from ExcelConnector: Error executing read_excel: Worksheet named 'Loading...' not found - Details: {"function": "read_excel", "args": "('C:/Users/luria/PycharmProjects/AuditQAStudio2/test_data/audit_workpapers_2025Q2.xlsx',)", "kwargs": {"sheet_name": "Loading...", "header": 0, "nrows": 50, "na_values": ["#N/A", "#N/A N/A", "#NA", "-NA", "#NULL!", "#NUM!", "#DIV/0!", "#VALUE!", "#REF!", "#NAME?", "#DIV/0", "#NUM", "#REF", "#VALUE"], "engine": "openpyxl", "parse_dates": true}} - Details: {"source_name": "ExcelConnector", "params": {"sheet_name": "Loading...", "header": 0, "nrows": 50, "na_values": ["#N/A", "#N/A N/A", "#NA", "-NA", "#NULL!", "#NUM!", "#DIV/0!", "#VALUE!", "#REF!", "#NAME?", "#DIV/0", "#NUM", "#REF", "#VALUE"], "engine": "openpyxl", "parse_dates": true}}
